5:return {{["x"] = 0, ["y"] = 0, ["param1"] = 30, ["z"] = 3, ["name"] = "default:silver_sandstone_block"}, {["x"] = 0, ["y"] = 0, ["param1"] = 30, ["z"] = 4, ["name"] = "default:silver_sandstone_block"}, {["x"] = 0, ["y"] = 0, ["param1"] = 30, ["z"] = 5, ["name"] = "default:silver_sandstone_block"}, {["x"] = 0, ["y"] = 0, ["param1"] = 30, ["z"] = 6, ["name"] = "default:silver_sandstone_block"}, {["x"] = 0, ["y"] = 0, ["param1"] = 30, ["z"] = 7, ["name"] = "default:silver_sandstone_block"}, {["x"] = 0, ["y"] = 0, ["param1"] = 30, ["z"] = 8, ["name"] = "default:silver_sandstone_block"}, {["x"] = 0, ["y"] = 0, ["param1"] = 30, ["z"] = 9, ["name"] = "default:silver_sandstone_block"}, {["x"] = 0, ["y"] = 0, ["param1"] = 30, ["z"] = 10, ["name"] = "default:silver_sandstone_block"}, {["x"] = 0, ["y"] = 0, ["param1"] = 30, ["z"] = 11, ["name"] = "default:silver_sandstone_block"}, {["x"] = 0, ["y"] = 0, ["param1"] = 30, ["z"] = 12, ["name"] = "default:silver_sandstone_block"}, {["x"] = 0, ["y"] = 1, ["param1"] = 30, ["z"] = 3, ["name"] = "default:silver_sandstone_block"}, {["x"] = 0, ["y"] = 1, ["param1"] = 30, ["z"] = 4, ["name"] = "default:silver_sandstone_block"}, {["x"] = 0, ["y"] = 1, ["param1"] = 30, ["z"] = 5, ["name"] = "default:silver_sandstone_block"}, {["x"] = 0, ["y"] = 1, ["param1"] = 30, ["z"] = 6, ["name"] = "default:silver_sandstone_block"}, {["x"] = 0, ["y"] = 1, ["param1"] = 30, ["z"] = 7, ["name"] = "default:silver_sandstone_block"}, {["x"] = 0, ["y"] = 1, ["param1"] = 30, ["z"] = 8, ["name"] = "default:silver_sandstone_block"}, {["x"] = 0, ["y"] = 1, ["param1"] = 30, ["z"] = 9, ["name"] = "default:silver_sandstone_block"}, {["x"] = 0, ["y"] = 1, ["param1"] = 30, ["z"] = 10, ["name"] = "default:silver_sandstone_block"}, {["x"] = 0, ["y"] = 1, ["param1"] = 30, ["z"] = 11, ["name"] = "default:silver_sandstone_block"}, {["x"] = 0, ["y"] = 1, ["param1"] = 30, ["z"] = 12, ["name"] = "default:silver_sandstone_block"}, {["x"] = 0, ["y"] = 1, ["param1"] = 30, ["z"] = 13, ["name"] = "default:silver_sandstone_block"}, {["x"] = 0, ["y"] = 2, ["param1"] = 30, ["z"] = 4, ["name"] = "default:silver_sandstone_block"}, {["x"] = 0, ["y"] = 2, ["param1"] = 30, ["z"] = 5, ["name"] = "default:silver_sandstone_block"}, {["x"] = 0, ["y"] = 2, ["param1"] = 30, ["z"] = 6, ["name"] = "default:silver_sandstone_block"}, {["x"] = 0, ["y"] = 2, ["param1"] = 30, ["z"] = 7, ["name"] = "default:silver_sandstone_block"}, {["x"] = 0, ["y"] = 2, ["param1"] = 30, ["z"] = 8, ["name"] = "default:silver_sandstone_block"}, {["x"] = 0, ["y"] = 2, ["param1"] = 30, ["z"] = 9, ["name"] = "default:silver_sandstone_block"}, {["x"] = 0, ["y"] = 2, ["param1"] = 30, ["z"] = 10, ["name"] = "default:silver_sandstone_block"}, {["x"] = 0, ["y"] = 2, ["param1"] = 30, ["z"] = 11, ["name"] = "default:silver_sandstone_block"}, {["x"] = 0, ["y"] = 2, ["param1"] = 30, ["z"] = 12, ["name"] = "default:silver_sandstone_block"}, {["x"] = 0, ["y"] = 2, ["param1"] = 30, ["z"] = 13, ["name"] = "default:silver_sandstone_block"}, {["x"] = 0, ["y"] = 3, ["param1"] = 90, ["z"] = 3, ["name"] = "default:goldblock"}, {["x"] = 0, ["y"] = 3, ["param1"] = 90, ["z"] = 4, ["name"] = "default:goldblock"}, {["x"] = 0, ["y"] = 3, ["param1"] = 30, ["z"] = 5, ["name"] = "default:silver_sandstone_block"}, {["x"] = 0, ["y"] = 3, ["param1"] = 14, ["z"] = 6, ["name"] = "default:glass"}, {["x"] = 0, ["y"] = 3, ["param1"] = 13, ["z"] = 7, ["name"] = "default:glass"}, {["x"] = 0, ["y"] = 3, ["param1"] = 13, ["z"] = 8, ["name"] = "default:glass"}, {["x"] = 0, ["y"] = 3, ["param1"] = 14, ["z"] = 9, ["name"] = "default:glass"}, {["x"] = 0, ["y"] = 3, ["param1"] = 30, ["z"] = 10, ["name"] = "default:silver_sandstone_block"}, {["x"] = 0, ["y"] = 3, ["param1"] = 14, ["z"] = 11, ["name"] = "default:glass"}, {["x"] = 0, ["y"] = 3, ["param1"] = 14, ["z"] = 12, ["name"] = "default:glass"}, {["x"] = 0, ["y"] = 3, ["param1"] = 30, ["z"] = 13, ["name"] = "default:silver_sandstone_block"}, {["x"] = 0, ["y"] = 3, ["param1"] = 30, ["z"] = 14, ["name"] = "default:silver_sandstone_block"}, {["x"] = 0, ["y"] = 4, ["param1"] = 90, ["z"] = 3, ["name"] = "default:goldblock"}, {["x"] = 0, ["y"] = 4, ["param1"] = 90, ["z"] = 4, ["name"] = "default:goldblock"}, {["x"] = 0, ["y"] = 4, ["param1"] = 30, ["z"] = 5, ["name"] = "default:silver_sandstone_block"}, {["x"] = 0, ["y"] = 4, ["param1"] = 14, ["z"] = 6, ["name"] = "default:glass"}, {["x"] = 0, ["y"] = 4, ["param1"] = 13, ["z"] = 7, ["name"] = "default:glass"}, {["x"] = 0, ["y"] = 4, ["param1"] = 13, ["z"] = 8, ["name"] = "default:glass"}, {["x"] = 0, ["y"] = 4, ["param1"] = 14, ["z"] = 9, ["name"] = "default:glass"}, {["x"] = 0, ["y"] = 4, ["param1"] = 30, ["z"] = 10, ["name"] = "default:silver_sandstone_block"}, {["x"] = 0, ["y"] = 4, ["param1"] = 14, ["z"] = 11, ["name"] = "default:glass"}, {["x"] = 0, ["y"] = 4, ["param1"] = 14, ["z"] = 12, ["name"] = "default:glass"}, {["x"] = 0, ["y"] = 4, ["param1"] = 14, ["z"] = 13, ["name"] = "default:glass"}, {["x"] = 0, ["y"] = 4, ["param1"] = 30, ["z"] = 14, ["name"] = "default:silver_sandstone_block"}, {["x"] = 0, ["y"] = 5, ["param1"] = 90, ["z"] = 3, ["name"] = "default:goldblock"}, {["x"] = 0, ["y"] = 5, ["param1"] = 90, ["z"] = 4, ["name"] = "default:goldblock"}, {["x"] = 0, ["y"] = 5, ["param1"] = 30, ["z"] = 5, ["name"] = "default:silver_sandstone_block"}, {["x"] = 0, ["y"] = 5, ["param1"] = 14, ["z"] = 6, ["name"] = "default:glass"}, {["x"] = 0, ["y"] = 5, ["param1"] = 13, ["z"] = 7, ["name"] = "default:glass"}, {["x"] = 0, ["y"] = 5, ["param1"] = 13, ["z"] = 8, ["name"] = "default:glass"}, {["x"] = 0, ["y"] = 5, ["param1"] = 14, ["z"] = 9, ["name"] = "default:glass"}, {["x"] = 0, ["y"] = 5, ["param1"] = 30, ["z"] = 10, ["name"] = "default:silver_sandstone_block"}, {["x"] = 0, ["y"] = 5, ["param1"] = 14, ["z"] = 11, ["name"] = "default:glass"}, {["x"] = 0, ["y"] = 5, ["param1"] = 14, ["z"] = 12, ["name"] = "default:glass"}, {["x"] = 0, ["y"] = 5, ["param1"] = 14, ["z"] = 13, ["name"] = "default:glass"}, {["x"] = 0, ["y"] = 5, ["param1"] = 13, ["z"] = 14, ["name"] = "default:glass"}, {["x"] = 0, ["y"] = 5, ["param1"] = 30, ["z"] = 15, ["name"] = "default:silver_sandstone_block"}, {["x"] = 0, ["y"] = 6, ["param1"] = 30, ["z"] = 5, ["name"] = "default:silver_sandstone_block"}, {["x"] = 0, ["y"] = 6, ["param1"] = 14, ["z"] = 6, ["name"] = "default:glass"}, {["x"] = 0, ["y"] = 6, ["param1"] = 13, ["z"] = 7, ["name"] = "default:glass"}, {["x"] = 0, ["y"] = 6, ["param1"] = 13, ["z"] = 8, ["name"] = "default:glass"}, {["x"] = 0, ["y"] = 6, ["param1"] = 14, ["z"] = 9, ["name"] = "default:glass"}, {["x"] = 0, ["y"] = 6, ["param1"] = 30, ["z"] = 10, ["name"] = "default:silver_sandstone_block"}, {["x"] = 0, ["y"] = 6, ["param1"] = 14, ["z"] = 11, ["name"] = "default:glass"}, {["x"] = 0, ["y"] = 6, ["param1"] = 14, ["z"] = 12, ["name"] = "default:glass"}, {["x"] = 0, ["y"] = 6, ["param1"] = 14, ["z"] = 13, ["name"] = "default:glass"}, {["x"] = 0, ["y"] = 6, ["param1"] = 13, ["z"] = 14, ["name"] = "default:glass"}, {["x"] = 0, ["y"] = 6, ["param1"] = 30, ["z"] = 15, ["name"] = "default:silver_sandstone_block"}, {["x"] = 0, ["y"] = 7, ["param1"] = 30, ["z"] = 5, ["name"] = "default:silver_sandstone_block"}, {["x"] = 0, ["y"] = 7, ["param1"] = 14, ["z"] = 6, ["name"] = "default:glass"}, {["x"] = 0, ["y"] = 7, ["param1"] = 13, ["z"] = 7, ["name"] = "default:glass"}, {["x"] = 0, ["y"] = 7, ["param1"] = 13, ["z"] = 8, ["name"] = "default:glass"}, {["x"] = 0, ["y"] = 7, ["param1"] = 14, ["z"] = 9, ["name"] = "default:glass"}, {["x"] = 0, ["y"] = 7, ["param1"] = 30, ["z"] = 10, ["name"] = "default:silver_sandstone_block"}, {["x"] = 0, ["y"] = 7, ["param1"] = 14, ["z"] = 11, ["name"] = "default:glass"}, {["x"] = 0, ["y"] = 7, ["param1"] = 14, ["z"] = 12, ["name"] = "default:glass"}, {["x"] = 0, ["y"] = 7, ["param1"] = 14, ["z"] = 13, ["name"] = "default:glass"}, {["x"] = 0, ["y"] = 7, ["param1"] = 13, ["z"] = 14, ["name"] = "default:glass"}, {["x"] = 0, ["y"] = 7, ["param1"] = 30, ["z"] = 15, ["name"] = "default:silver_sandstone_block"}, {["x"] = 0, ["y"] = 8, ["param1"] = 30, ["z"] = 5, ["name"] = "default:silver_sandstone_block"}, {["x"] = 0, ["y"] = 8, ["param1"] = 14, ["z"] = 6, ["name"] = "default:glass"}, {["x"] = 0, ["y"] = 8, ["param1"] = 13, ["z"] = 7, ["name"] = "default:glass"}, {["x"] = 0, ["y"] = 8, ["param1"] = 13, ["z"] = 8, ["name"] = "default:glass"}, {["x"] = 0, ["y"] = 8, ["param1"] = 14, ["z"] = 9, ["name"] = "default:glass"}, {["x"] = 0, ["y"] = 8, ["param1"] = 30, ["z"] = 10, ["name"] = "default:silver_sandstone_block"}, {["x"] = 0, ["y"] = 8, ["param1"] = 14, ["z"] = 11, ["name"] = "default:glass"}, {["x"] = 0, ["y"] = 8, ["param1"] = 14, ["z"] = 12, ["name"] = "default:glass"}, {["x"] = 0, ["y"] = 8, ["param1"] = 14, ["z"] = 13, ["name"] = "default:glass"}, {["x"] = 0, ["y"] = 8, ["param1"] = 13, ["z"] = 14, ["name"] = "default:glass"}, {["x"] = 0, ["y"] = 8, ["param1"] = 30, ["z"] = 15, ["name"] = "default:silver_sandstone_block"}, {["x"] = 0, ["y"] = 9, ["param1"] = 30, ["z"] = 5, ["name"] = "default:silver_sandstone_block"}, {["x"] = 0, ["y"] = 9, ["param1"] = 14, ["z"] = 6, ["name"] = "default:glass"}, {["x"] = 0, ["y"] = 9, ["param1"] = 14, ["z"] = 7, ["name"] = "default:glass"}, {["x"] = 0, ["y"] = 9, ["param1"] = 14, ["z"] = 8, ["name"] = "default:glass"}, {["x"] = 0, ["y"] = 9, ["param1"] = 14, ["z"] = 9, ["name"] = "default:glass"}, {["x"] = 0, ["y"] = 9, ["param1"] = 30, ["z"] = 10, ["name"] = "default:silver_sandstone_block"}, {["x"] = 0, ["y"] = 9, ["param1"] = 14, ["z"] = 11, ["name"] = "default:glass"}, {["x"] = 0, ["y"] = 9, ["param1"] = 14, ["z"] = 12, ["name"] = "default:glass"}, {["x"] = 0, ["y"] = 9, ["param1"] = 14, ["z"] = 13, ["name"] = "default:glass"}, {["x"] = 0, ["y"] = 9, ["param1"] = 13, ["z"] = 14, ["name"] = "default:glass"}, {["x"] = 0, ["y"] = 9, ["param1"] = 30, ["z"] = 15, ["name"] = "default:silver_sandstone_block"}, {["x"] = 0, ["y"] = 10, ["param1"] = 30, ["z"] = 5, ["name"] = "default:silver_sandstone_block"}, {["x"] = 0, ["y"] = 10, ["param1"] = 14, ["z"] = 6, ["name"] = "default:glass"}, {["x"] = 0, ["y"] = 10, ["param1"] = 14, ["z"] = 7, ["name"] = "default:glass"}, {["x"] = 0, ["y"] = 10, ["param1"] = 14, ["z"] = 8, ["name"] = "default:glass"}, {["x"] = 0, ["y"] = 10, ["param1"] = 14, ["z"] = 9, ["name"] = "default:glass"}, {["x"] = 0, ["y"] = 10, ["param1"] = 30, ["z"] = 10, ["name"] = "default:silver_sandstone_block"}, {["x"] = 0, ["y"] = 10, ["param1"] = 14, ["z"] = 11, ["name"] = "default:glass"}, {["x"] = 0, ["y"] = 10, ["param1"] = 14, ["z"] = 12, ["name"] = "default:glass"}, {["x"] = 0, ["y"] = 10, ["param1"] = 14, ["z"] = 13, ["name"] = "default:glass"}, {["x"] = 0, ["y"] = 10, ["param1"] = 13, ["z"] = 14, ["name"] = "default:glass"}, {["x"] = 0, ["y"] = 10, ["param1"] = 30, ["z"] = 15, ["name"] = "default:silver_sandstone_block"}, {["x"] = 0, ["y"] = 11, ["param1"] = 30, ["z"] = 5, ["name"] = "default:silver_sandstone_block"}, {["x"] = 0, ["y"] = 11, ["param1"] = 14, ["z"] = 6, ["name"] = "default:glass"}, {["x"] = 0, ["y"] = 11, ["param1"] = 14, ["z"] = 7, ["name"] = "default:glass"}, {["x"] = 0, ["y"] = 11, ["param1"] = 14, ["z"] = 8, ["name"] = "default:glass"}, {["x"] = 0, ["y"] = 11, ["param1"] = 14, ["z"] = 9, ["name"] = "default:glass"}, {["x"] = 0, ["y"] = 11, ["param1"] = 30, ["z"] = 10, ["name"] = "default:silver_sandstone_block"}, {["x"] = 0, ["y"] = 11, ["param1"] = 14, ["z"] = 11, ["name"] = "default:glass"}, {["x"] = 0, ["y"] = 11, ["param1"] = 14, ["z"] = 12, ["name"] = "default:glass"}, {["x"] = 0, ["y"] = 11, ["param1"] = 14, ["z"] = 13, ["name"] = "default:glass"}, {["x"] = 0, ["y"] = 11, ["param1"] = 13, ["z"] = 14, ["name"] = "default:glass"}, {["x"] = 0, ["y"] = 11, ["param1"] = 30, ["z"] = 15, ["name"] = "default:silver_sandstone_block"}, {["x"] = 0, ["y"] = 12, ["param1"] = 30, ["z"] = 5, ["name"] = "default:silver_sandstone_block"}, {["x"] = 0, ["y"] = 12, ["param1"] = 14, ["z"] = 6, ["name"] = "default:glass"}, {["x"] = 0, ["y"] = 12, ["param1"] = 14, ["z"] = 7, ["name"] = "default:glass"}, {["x"] = 0, ["y"] = 12, ["param1"] = 14, ["z"] = 8, ["name"] = "default:glass"}, {["x"] = 0, ["y"] = 12, ["param1"] = 14, ["z"] = 9, ["name"] = "default:glass"}, {["x"] = 0, ["y"] = 12, ["param1"] = 30, ["z"] = 10, ["name"] = "default:silver_sandstone_block"}, {["x"] = 0, ["y"] = 12, ["param1"] = 14, ["z"] = 11, ["name"] = "default:glass"}, {["x"] = 0, ["y"] = 12, ["param1"] = 14, ["z"] = 12, ["name"] = "default:glass"}, {["x"] = 0, ["y"] = 12, ["param1"] = 14, ["z"] = 13, ["name"] = "default:glass"}, {["x"] = 0, ["y"] = 12, ["param1"] = 13, ["z"] = 14, ["name"] = "default:glass"}, {["x"] = 0, ["y"] = 12, ["param1"] = 30, ["z"] = 15, ["name"] = "default:silver_sandstone_block"}, {["x"] = 0, ["y"] = 13, ["param1"] = 30, ["z"] = 5, ["name"] = "default:silver_sandstone_block"}, {["x"] = 0, ["y"] = 13, ["param1"] = 14, ["z"] = 6, ["name"] = "default:glass"}, {["x"] = 0, ["y"] = 13, ["param1"] = 14, ["z"] = 7, ["name"] = "default:glass"}, {["x"] = 0, ["y"] = 13, ["param1"] = 14, ["z"] = 8, ["name"] = "default:glass"}, {["x"] = 0, ["y"] = 13, ["param1"] = 14, ["z"] = 9, ["name"] = "default:glass"}, {["x"] = 0, ["y"] = 13, ["param1"] = 30, ["z"] = 10, ["name"] = "default:silver_sandstone_block"}, {["x"] = 0, ["y"] = 13, ["param1"] = 14, ["z"] = 11, ["name"] = "default:glass"}, {["x"] = 0, ["y"] = 13, ["param1"] = 14, ["z"] = 12, ["name"] = "default:glass"}, {["x"] = 0, ["y"] = 13, ["param1"] = 14, ["z"] = 13, ["name"] = "default:glass"}, {["x"] = 0, ["y"] = 13, ["param1"] = 13, ["z"] = 14, ["name"] = "default:glass"}, {["x"] = 0, ["y"] = 13, ["param1"] = 30, ["z"] = 15, ["name"] = "default:silver_sandstone_block"}, {["x"] = 0, ["y"] = 14, ["param1"] = 30, ["z"] = 5, ["name"] = "default:silver_sandstone_block"}, {["x"] = 0, ["y"] = 14, ["param1"] = 14, ["z"] = 6, ["name"] = "default:glass"}, {["x"] = 0, ["y"] = 14, ["param1"] = 14, ["z"] = 7, ["name"] = "default:glass"}, {["x"] = 0, ["y"] = 14, ["param1"] = 14, ["z"] = 8, ["name"] = "default:glass"}, {["x"] = 0, ["y"] = 14, ["param1"] = 14, ["z"] = 9, ["name"] = "default:glass"}, {["x"] = 0, ["y"] = 14, ["param1"] = 30, ["z"] = 10, ["name"] = "default:silver_sandstone_block"}, {["x"] = 0, ["y"] = 14, ["param1"] = 14, ["z"] = 11, ["name"] = "default:glass"}, {["x"] = 0, ["y"] = 14, ["param1"] = 14, ["z"] = 12, ["name"] = "default:glass"}, {["x"] = 0, ["y"] = 14, ["param1"] = 14, ["z"] = 13, ["name"] = "default:glass"}, {["x"] = 0, ["y"] = 14, ["param1"] = 13, ["z"] = 14, ["name"] = "default:glass"}, {["x"] = 0, ["y"] = 14, ["param1"] = 30, ["z"] = 15, ["name"] = "default:silver_sandstone_block"}, {["x"] = 0, ["y"] = 15, ["param1"] = 30, ["z"] = 5, ["name"] = "default:silver_sandstone_block"}, {["x"] = 0, ["y"] = 15, ["param1"] = 14, ["z"] = 6, ["name"] = "default:glass"}, {["x"] = 0, ["y"] = 15, ["param1"] = 14, ["z"] = 7, ["name"] = "default:glass"}, {["x"] = 0, ["y"] = 15, ["param1"] = 14, ["z"] = 8, ["name"] = "default:glass"}, {["x"] = 0, ["y"] = 15, ["param1"] = 14, ["z"] = 9, ["name"] = "default:glass"}, {["x"] = 0, ["y"] = 15, ["param1"] = 30, ["z"] = 10, ["name"] = "default:silver_sandstone_block"}, {["x"] = 0, ["y"] = 15, ["param1"] = 14, ["z"] = 11, ["name"] = "default:glass"}, {["x"] = 0, ["y"] = 15, ["param1"] = 14, ["z"] = 12, ["name"] = "default:glass"}, {["x"] = 0, ["y"] = 15, ["param1"] = 14, ["z"] = 13, ["name"] = "default:glass"}, {["x"] = 0, ["y"] = 15, ["param1"] = 13, ["z"] = 14, ["name"] = "default:glass"}, {["x"] = 0, ["y"] = 15, ["param1"] = 30, ["z"] = 15, ["name"] = "default:silver_sandstone_block"}, {["x"] = 0, ["y"] = 16, ["param1"] = 30, ["z"] = 5, ["name"] = "default:silver_sandstone_block"}, {["x"] = 0, ["y"] = 16, ["param1"] = 14, ["z"] = 6, ["name"] = "default:glass"}, {["x"] = 0, ["y"] = 16, ["param1"] = 14, ["z"] = 7, ["name"] = "default:glass"}, {["x"] = 0, ["y"] = 16, ["param1"] = 14, ["z"] = 8, ["name"] = "default:glass"}, {["x"] = 0, ["y"] = 16, ["param1"] = 14, ["z"] = 9, ["name"] = "default:glass"}, {["x"] = 0, ["y"] = 16, ["param1"] = 30, ["z"] = 10, ["name"] = "default:silver_sandstone_block"}, {["x"] = 0, ["y"] = 16, ["param1"] = 14, ["z"] = 11, ["name"] = "default:glass"}, {["x"] = 0, ["y"] = 16, ["param1"] = 14, ["z"] = 12, ["name"] = "default:glass"}, {["x"] = 0, ["y"] = 16, ["param1"] = 14, ["z"] = 13, ["name"] = "default:glass"}, {["x"] = 0, ["y"] = 16, ["param1"] = 14, ["z"] = 14, ["name"] = "default:glass"}, {["x"] = 0, ["y"] = 16, ["param1"] = 30, ["z"] = 15, ["name"] = "default:silver_sandstone_block"}, {["x"] = 0, ["y"] = 17, ["param1"] = 30, ["z"] = 5, ["name"] = "default:silver_sandstone_block"}, {["x"] = 0, ["y"] = 17, ["param1"] = 14, ["z"] = 6, ["name"] = "default:glass"}, {["x"] = 0, ["y"] = 17, ["param1"] = 14, ["z"] = 7, ["name"] = "default:glass"}, {["x"] = 0, ["y"] = 17, ["param1"] = 14, ["z"] = 8, ["name"] = "default:glass"}, {["x"] = 0, ["y"] = 17, ["param1"] = 14, ["z"] = 9, ["name"] = "default:glass"}, {["x"] = 0, ["y"] = 17, ["param1"] = 30, ["z"] = 10, ["name"] = "default:silver_sandstone_block"}, {["x"] = 0, ["y"] = 17, ["param1"] = 14, ["z"] = 11, ["name"] = "default:glass"}, {["x"] = 0, ["y"] = 17, ["param1"] = 14, ["z"] = 12, ["name"] = "default:glass"}, {["x"] = 0, ["y"] = 17, ["param1"] = 14, ["z"] = 13, ["name"] = "default:glass"}, {["x"] = 0, ["y"] = 17, ["param1"] = 14, ["z"] = 14, ["name"] = "default:glass"}, {["x"] = 0, ["y"] = 17, ["param1"] = 30, ["z"] = 15, ["name"] = "default:silver_sandstone_block"}, {["x"] = 0, ["y"] = 18, ["param1"] = 30, ["z"] = 5, ["name"] = "default:silver_sandstone_block"}, {["x"] = 0, ["y"] = 18, ["param1"] = 14, ["z"] = 6, ["name"] = "default:glass"}, {["x"] = 0, ["y"] = 18, ["param1"] = 14, ["z"] = 7, ["name"] = "default:glass"}, {["x"] = 0, ["y"] = 18, ["param1"] = 14, ["z"] = 8, ["name"] = "default:glass"}, {["x"] = 0, ["y"] = 18, ["param1"] = 14, ["z"] = 9, ["name"] = "default:glass"}, {["x"] = 0, ["y"] = 18, ["param1"] = 30, ["z"] = 10, ["name"] = "default:silver_sandstone_block"}, {["x"] = 0, ["y"] = 18, ["param1"] = 14, ["z"] = 11, ["name"] = "default:glass"}, {["x"] = 0, ["y"] = 18, ["param1"] = 14, ["z"] = 12, ["name"] = "default:glass"}, {["x"] = 0, ["y"] = 18, ["param1"] = 14, ["z"] = 13, ["name"] = "default:glass"}, {["x"] = 0, ["y"] = 18, ["param1"] = 14, ["z"] = 14, ["name"] = "default:glass"}, {["x"] = 0, ["y"] = 18, ["param1"] = 30, ["z"] = 15, ["name"] = "default:silver_sandstone_block"}, {["x"] = 0, ["y"] = 19, ["param1"] = 30, ["z"] = 5, ["name"] = "default:silver_sandstone_block"}, {["x"] = 0, ["y"] = 19, ["param1"] = 14, ["z"] = 6, ["name"] = "default:glass"}, {["x"] = 0, ["y"] = 19, ["param1"] = 14, ["z"] = 7, ["name"] = "default:glass"}, {["x"] = 0, ["y"] = 19, ["param1"] = 14, ["z"] = 8, ["name"] = "default:glass"}, {["x"] = 0, ["y"] = 19, ["param1"] = 14, ["z"] = 9, ["name"] = "default:glass"}, {["x"] = 0, ["y"] = 19, ["param1"] = 30, ["z"] = 10, ["name"] = "default:silver_sandstone_block"}, {["x"] = 0, ["y"] = 19, ["param1"] = 14, ["z"] = 11, ["name"] = "default:glass"}, {["x"] = 0, ["y"] = 19, ["param1"] = 14, ["z"] = 12, ["name"] = "default:glass"}, {["x"] = 0, ["y"] = 19, ["param1"] = 14, ["z"] = 13, ["name"] = "default:glass"}, {["x"] = 0, ["y"] = 19, ["param1"] = 14, ["z"] = 14, ["name"] = "default:glass"}, {["x"] = 0, ["y"] = 19, ["param1"] = 30, ["z"] = 15, ["name"] = "default:silver_sandstone_block"}, {["x"] = 0, ["y"] = 20, ["param1"] = 30, ["z"] = 5, ["name"] = "default:silver_sandstone_block"}, {["x"] = 0, ["y"] = 20, ["param1"] = 14, ["z"] = 6, ["name"] = "default:glass"}, {["x"] = 0, ["y"] = 20, ["param1"] = 14, ["z"] = 7, ["name"] = "default:glass"}, {["x"] = 0, ["y"] = 20, ["param1"] = 14, ["z"] = 8, ["name"] = "default:glass"}, {["x"] = 0, ["y"] = 20, ["param1"] = 14, ["z"] = 9, ["name"] = "default:glass"}, {["x"] = 0, ["y"] = 20, ["param1"] = 30, ["z"] = 10, ["name"] = "default:silver_sandstone_block"}, {["x"] = 0, ["y"] = 20, ["param1"] = 14, ["z"] = 11, ["name"] = "default:glass"}, {["x"] = 0, ["y"] = 20, ["param1"] = 14, ["z"] = 12, ["name"] = "default:glass"}, {["x"] = 0, ["y"] = 20, ["param1"] = 14, ["z"] = 13, ["name"] = "default:glass"}, {["x"] = 0, ["y"] = 20, ["param1"] = 14, ["z"] = 14, ["name"] = "default:glass"}, {["x"] = 0, ["y"] = 20, ["param1"] = 30, ["z"] = 15, ["name"] = "default:silver_sandstone_block"}, {["x"] = 0, ["y"] = 21, ["param1"] = 30, ["z"] = 5, ["name"] = "default:silver_sandstone_block"}, {["x"] = 0, ["y"] = 21, ["param1"] = 14, ["z"] = 6, ["name"] = "default:glass"}, {["x"] = 0, ["y"] = 21, ["param1"] = 14, ["z"] = 7, ["name"] = "default:glass"}, {["x"] = 0, ["y"] = 21, ["param1"] = 14, ["z"] = 8, ["name"] = "default:glass"}, {["x"] = 0, ["y"] = 21, ["param1"] = 14, ["z"] = 9, ["name"] = "default:glass"}, {["x"] = 0, ["y"] = 21, ["param1"] = 30, ["z"] = 10, ["name"] = "default:silver_sandstone_block"}, {["x"] = 0, ["y"] = 21, ["param1"] = 14, ["z"] = 11, ["name"] = "default:glass"}, {["x"] = 0, ["y"] = 21, ["param1"] = 14, ["z"] = 12, ["name"] = "default:glass"}, {["x"] = 0, ["y"] = 21, ["param1"] = 14, ["z"] = 13, ["name"] = "default:glass"}, {["x"] = 0, ["y"] = 21, ["param1"] = 14, ["z"] = 14, ["name"] = "default:glass"}, {["x"] = 0, ["y"] = 21, ["param1"] = 30, ["z"] = 15, ["name"] = "default:silver_sandstone_block"}, {["x"] = 0, ["y"] = 22, ["param1"] = 30, ["z"] = 5, ["name"] = "default:silver_sandstone_block"}, {["x"] = 0, ["y"] = 22, ["param1"] = 14, ["z"] = 6, ["name"] = "default:glass"}, {["x"] = 0, ["y"] = 22, ["param1"] = 14, ["z"] = 7, ["name"] = "default:glass"}, {["x"] = 0, ["y"] = 22, ["param1"] = 14, ["z"] = 8, ["name"] = "default:glass"}, {["x"] = 0, ["y"] = 22, ["param1"] = 14, ["z"] = 9, ["name"] = "default:glass"}, {["x"] = 0, ["y"] = 22, ["param1"] = 30, ["z"] = 10, ["name"] = "default:silver_sandstone_block"}, {["x"] = 0, ["y"] = 22, ["param1"] = 14, ["z"] = 11, ["name"] = "default:glass"}, {["x"] = 0, ["y"] = 22, ["param1"] = 14, ["z"] = 12, ["name"] = "default:glass"}, {["x"] = 0, ["y"] = 22, ["param1"] = 14, ["z"] = 13, ["name"] = "default:glass"}, {["x"] = 0, ["y"] = 22, ["param1"] = 14, ["z"] = 14, ["name"] = "default:glass"}, {["x"] = 0, ["y"] = 22, ["param1"] = 30, ["z"] = 15, ["name"] = "default:silver_sandstone_block"}, {["x"] = 0, ["y"] = 23, ["param1"] = 30, ["z"] = 5, ["name"] = "default:silver_sandstone_block"}, {["x"] = 0, ["y"] = 23, ["param1"] = 14, ["z"] = 6, ["name"] = "default:glass"}, {["x"] = 0, ["y"] = 23, ["param1"] = 14, ["z"] = 7, ["name"] = "default:glass"}, {["x"] = 0, ["y"] = 23, ["param1"] = 14, ["z"] = 8, ["name"] = "default:glass"}, {["x"] = 0, ["y"] = 23, ["param1"] = 14, ["z"] = 9, ["name"] = "default:glass"}, {["x"] = 0, ["y"] = 23, ["param1"] = 30, ["z"] = 10, ["name"] = "default:silver_sandstone_block"}, {["x"] = 0, ["y"] = 23, ["param1"] = 14, ["z"] = 11, ["name"] = "default:glass"}, {["x"] = 0, ["y"] = 23, ["param1"] = 14, ["z"] = 12, ["name"] = "default:glass"}, {["x"] = 0, ["y"] = 23, ["param1"] = 14, ["z"] = 13, ["name"] = "default:glass"}, {["x"] = 0, ["y"] = 23, ["param1"] = 14, ["z"] = 14, ["name"] = "default:glass"}, {["x"] = 0, ["y"] = 23, ["param1"] = 30, ["z"] = 15, ["name"] = "default:silver_sandstone_block"}, {["x"] = 0, ["y"] = 24, ["param1"] = 30, ["z"] = 3, ["name"] = "default:silver_sandstone_block"}, {["x"] = 0, ["y"] = 24, ["param1"] = 30, ["z"] = 4, ["name"] = "default:silver_sandstone_block"}, {["x"] = 0, ["y"] = 24, ["param1"] = 30, ["z"] = 5, ["name"] = "default:silver_sandstone_block"}, {["x"] = 0, ["y"] = 24, ["param1"] = 14, ["z"] = 6, ["name"] = "default:glass"}, {["x"] = 0, ["y"] = 24, ["param1"] = 14, ["z"] = 7, ["name"] = "default:glass"}, {["x"] = 0, ["y"] = 24, ["param1"] = 14, ["z"] = 8, ["name"] = "default:glass"}, {["x"] = 0, ["y"] = 24, ["param1"] = 14, ["z"] = 9, ["name"] = "default:glass"}, {["x"] = 0, ["y"] = 24, ["param1"] = 30, ["z"] = 10, ["name"] = "default:silver_sandstone_block"}, {["x"] = 0, ["y"] = 24, ["param1"] = 14, ["z"] = 11, ["name"] = "default:glass"}, {["x"] = 0, ["y"] = 24, ["param1"] = 14, ["z"] = 12, ["name"] = "default:glass"}, {["x"] = 0, ["y"] = 24, ["param1"] = 14, ["z"] = 13, ["name"] = "default:glass"}, {["x"] = 0, ["y"] = 24, ["param1"] = 30, ["z"] = 14, ["name"] = "default:silver_sandstone_block"}, {["x"] = 0, ["y"] = 25, ["param1"] = 30, ["z"] = 4, ["name"] = "default:silver_sandstone_block"}, {["x"] = 0, ["y"] = 25, ["param1"] = 30, ["z"] = 5, ["name"] = "default:silver_sandstone_block"}, {["x"] = 0, ["y"] = 25, ["param1"] = 30, ["z"] = 6, ["name"] = "default:silver_sandstone_block"}, {["x"] = 0, ["y"] = 25, ["param1"] = 14, ["z"] = 7, ["name"] = "default:glass"}, {["x"] = 0, ["y"] = 25, ["param1"] = 14, ["z"] = 8, ["name"] = "default:glass"}, {["x"] = 0, ["y"] = 25, ["param1"] = 14, ["z"] = 9, ["name"] = "default:glass"}, {["x"] = 0, ["y"] = 25, ["param1"] = 30, ["z"] = 10, ["name"] = "default:silver_sandstone_block"}, {["x"] = 0, ["y"] = 25, ["param1"] = 14, ["z"] = 11, ["name"] = "default:glass"}, {["x"] = 0, ["y"] = 25, ["param1"] = 14, ["z"] = 12, ["name"] = "default:glass"}, {["x"] = 0, ["y"] = 25, ["param1"] = 30, ["z"] = 13, ["name"] = "default:silver_sandstone_block"}, {["x"] = 0, ["y"] = 26, ["param1"] = 30, ["z"] = 5, ["name"] = "default:silver_sandstone_block"}, {["x"] = 0, ["y"] = 26, ["param1"] = 30, ["z"] = 6, ["name"] = "default:silver_sandstone_block"}, {["x"] = 0, ["y"] = 26, ["param1"] = 30, ["z"] = 7, ["name"] = "default:silver_sandstone_block"}, {["x"] = 0, ["y"] = 26, ["param1"] = 30, ["z"] = 8, ["name"] = "default:silver_sandstone_block"}, {["x"] = 0, ["y"] = 26, ["param1"] = 30, ["z"] = 9, ["name"] = "default:silver_sandstone_block"}, {["x"] = 0, ["y"] = 26, ["param1"] = 30, ["z"] = 10, ["name"] = "default:silver_sandstone_block"}, {["x"] = 0, ["y"] = 26, ["param1"] = 30, ["z"] = 11, ["name"] = "default:silver_sandstone_block"}, {["x"] = 0, ["y"] = 26, ["param1"] = 30, ["z"] = 12, ["name"] = "default:silver_sandstone_block"}, {["x"] = 0, ["y"] = 27, ["param1"] = 30, ["z"] = 6, ["name"] = "default:silver_sandstone_block"}, {["x"] = 0, ["y"] = 27, ["param1"] = 30, ["z"] = 7, ["name"] = "default:silver_sandstone_block"}, {["x"] = 0, ["y"] = 27, ["param1"] = 30, ["z"] = 8, ["name"] = "default:silver_sandstone_block"}, {["x"] = 0, ["y"] = 27, ["param1"] = 30, ["z"] = 9, ["name"] = "default:silver_sandstone_block"}, {["x"] = 0, ["y"] = 27, ["param1"] = 30, ["z"] = 10, ["name"] = "default:silver_sandstone_block"}, {["x"] = 0, ["y"] = 27, ["param1"] = 30, ["z"] = 11, ["name"] = "default:silver_sandstone_block"}, {["x"] = 1, ["y"] = 0, ["param1"] = 30, ["z"] = 3, ["name"] = "default:silver_sandstone_block"}, {["x"] = 1, ["y"] = 0, ["param1"] = 30, ["z"] = 4, ["name"] = "default:silver_sandstone_block"}, {["x"] = 1, ["y"] = 0, ["param1"] = 30, ["z"] = 5, ["name"] = "default:silver_sandstone_block"}, {["x"] = 1, ["y"] = 0, ["param1"] = 30, ["z"] = 6, ["name"] = "default:silver_sandstone_block"}, {["x"] = 1, ["y"] = 0, ["param1"] = 30, ["z"] = 7, ["name"] = "default:silver_sandstone_block"}, {["x"] = 1, ["y"] = 0, ["param1"] = 30, ["z"] = 8, ["name"] = "default:silver_sandstone_block"}, {["x"] = 1, ["y"] = 0, ["param1"] = 30, ["z"] = 9, ["name"] = "default:silver_sandstone_block"}, {["x"] = 1, ["y"] = 0, ["param1"] = 30, ["z"] = 10, ["name"] = "default:silver_sandstone_block"}, {["x"] = 1, ["y"] = 0, ["param1"] = 30, ["z"] = 11, ["name"] = "default:silver_sandstone_block"}, {["x"] = 1, ["y"] = 0, ["param1"] = 30, ["z"] = 12, ["name"] = "default:silver_sandstone_block"}, {["x"] = 1, ["y"] = 1, ["param1"] = 30, ["z"] = 13, ["name"] = "default:silver_sandstone_block"}, {["x"] = 1, ["y"] = 2, ["param1"] = 30, ["z"] = 13, ["name"] = "default:silver_sandstone_block"}, {["x"] = 1, ["y"] = 3, ["param1"] = 90, ["z"] = 3, ["name"] = "default:goldblock"}, {["x"] = 1, ["y"] = 3, ["param1"] = 30, ["z"] = 14, ["name"] = "default:silver_sandstone_block"}, {["x"] = 1, ["y"] = 4, ["param1"] = 90, ["z"] = 3, ["name"] = "default:goldblock"}, {["x"] = 1, ["y"] = 4, ["param1"] = 30, ["z"] = 14, ["name"] = "default:silver_sandstone_block"}, {["x"] = 1, ["y"] = 5, ["param1"] = 90, ["z"] = 3, ["name"] = "default:goldblock"}, {["x"] = 1, ["y"] = 5, ["param1"] = 30, ["z"] = 15, ["name"] = "default:silver_sandstone_block"}, {["x"] = 1, ["y"] = 6, ["param1"] = 30, ["z"] = 15, ["name"] = "default:silver_sandstone_block"}, {["x"] = 1, ["y"] = 7, ["param1"] = 30, ["z"] = 15, ["name"] = "default:silver_sandstone_block"}, {["x"] = 1, ["y"] = 8, ["param1"] = 30, ["z"] = 15, ["name"] = "default:silver_sandstone_block"}, {["x"] = 1, ["y"] = 9, ["param1"] = 30, ["z"] = 15, ["name"] = "default:silver_sandstone_block"}, {["x"] = 1, ["y"] = 10, ["param1"] = 30, ["z"] = 15, ["name"] = "default:silver_sandstone_block"}, {["x"] = 1, ["y"] = 11, ["param1"] = 30, ["z"] = 15, ["name"] = "default:silver_sandstone_block"}, {["x"] = 1, ["y"] = 12, ["param1"] = 30, ["z"] = 15, ["name"] = "default:silver_sandstone_block"}, {["x"] = 1, ["y"] = 13, ["param1"] = 30, ["z"] = 15, ["name"] = "default:silver_sandstone_block"}, {["x"] = 1, ["y"] = 14, ["param1"] = 30, ["z"] = 15, ["name"] = "default:silver_sandstone_block"}, {["x"] = 1, ["y"] = 15, ["param1"] = 30, ["z"] = 15, ["name"] = "default:silver_sandstone_block"}, {["x"] = 1, ["y"] = 16, ["param1"] = 30, ["z"] = 15, ["name"] = "default:silver_sandstone_block"}, {["x"] = 1, ["y"] = 17, ["param1"] = 30, ["z"] = 15, ["name"] = "default:silver_sandstone_block"}, {["x"] = 1, ["y"] = 18, ["param1"] = 30, ["z"] = 15, ["name"] = "default:silver_sandstone_block"}, {["x"] = 1, ["y"] = 19, ["param1"] = 30, ["z"] = 15, ["name"] = "default:silver_sandstone_block"}, {["x"] = 1, ["y"] = 20, ["param1"] = 30, ["z"] = 15, ["name"] = "default:silver_sandstone_block"}, {["x"] = 1, ["y"] = 21, ["param1"] = 30, ["z"] = 15, ["name"] = "default:silver_sandstone_block"}, {["x"] = 1, ["y"] = 22, ["param1"] = 30, ["z"] = 15, ["name"] = "default:silver_sandstone_block"}, {["x"] = 1, ["y"] = 23, ["param1"] = 30, ["z"] = 15, ["name"] = "default:silver_sandstone_block"}, {["x"] = 1, ["y"] = 24, ["param1"] = 30, ["z"] = 3, ["name"] = "default:silver_sandstone_block"}, {["x"] = 1, ["y"] = 24, ["param1"] = 30, ["z"] = 14, ["name"] = "default:silver_sandstone_block"}, {["x"] = 1, ["y"] = 25, ["param1"] = 30, ["z"] = 4, ["name"] = "default:silver_sandstone_block"}, {["x"] = 1, ["y"] = 25, ["param1"] = 30, ["z"] = 13, ["name"] = "default:silver_sandstone_block"}, {["x"] = 1, ["y"] = 26, ["param1"] = 30, ["z"] = 5, ["name"] = "default:silver_sandstone_block"}, {["x"] = 1, ["y"] = 26, ["param1"] = 30, ["z"] = 12, ["name"] = "default:silver_sandstone_block"}, {["x"] = 1, ["y"] = 27, ["param1"] = 30, ["z"] = 6, ["name"] = "default:silver_sandstone_block"}, {["x"] = 1, ["y"] = 27, ["param1"] = 30, ["z"] = 7, ["name"] = "default:silver_sandstone_block"}, {["x"] = 1, ["y"] = 27, ["param1"] = 30, ["z"] = 8, ["name"] = "default:silver_sandstone_block"}, {["x"] = 1, ["y"] = 27, ["param1"] = 30, ["z"] = 9, ["name"] = "default:silver_sandstone_block"}, {["x"] = 1, ["y"] = 27, ["param1"] = 30, ["z"] = 10, ["name"] = "default:silver_sandstone_block"}, {["x"] = 1, ["y"] = 27, ["param1"] = 30, ["z"] = 11, ["name"] = "default:silver_sandstone_block"}, {["x"] = 2, ["y"] = 0, ["param1"] = 30, ["z"] = 3, ["name"] = "default:silver_sandstone_block"}, {["x"] = 2, ["y"] = 0, ["param1"] = 30, ["z"] = 4, ["name"] = "default:silver_sandstone_block"}, {["x"] = 2, ["y"] = 0, ["param1"] = 30, ["z"] = 5, ["name"] = "default:silver_sandstone_block"}, {["x"] = 2, ["y"] = 0, ["param1"] = 30, ["z"] = 6, ["name"] = "default:silver_sandstone_block"}, {["x"] = 2, ["y"] = 0, ["param1"] = 30, ["z"] = 7, ["name"] = "default:silver_sandstone_block"}, {["x"] = 2, ["y"] = 0, ["param1"] = 30, ["z"] = 8, ["name"] = "default:silver_sandstone_block"}, {["x"] = 2, ["y"] = 0, ["param1"] = 30, ["z"] = 9, ["name"] = "default:silver_sandstone_block"}, {["x"] = 2, ["y"] = 0, ["param1"] = 30, ["z"] = 10, ["name"] = "default:silver_sandstone_block"}, {["x"] = 2, ["y"] = 0, ["param1"] = 30, ["z"] = 11, ["name"] = "default:silver_sandstone_block"}, {["x"] = 2, ["y"] = 0, ["param1"] = 30, ["z"] = 12, ["name"] = "default:silver_sandstone_block"}, {["x"] = 2, ["y"] = 1, ["param1"] = 30, ["z"] = 13, ["name"] = "default:silver_sandstone_block"}, {["x"] = 2, ["y"] = 2, ["param1"] = 30, ["z"] = 13, ["name"] = "default:silver_sandstone_block"}, {["x"] = 2, ["y"] = 3, ["param1"] = 90, ["z"] = 3, ["name"] = "default:goldblock"}, {["x"] = 2, ["y"] = 3, ["param1"] = 30, ["z"] = 14, ["name"] = "default:silver_sandstone_block"}, {["x"] = 2, ["y"] = 4, ["param1"] = 90, ["z"] = 3, ["name"] = "default:goldblock"}, {["x"] = 2, ["y"] = 4, ["param1"] = 30, ["z"] = 14, ["name"] = "default:silver_sandstone_block"}, {["x"] = 2, ["y"] = 5, ["param1"] = 90, ["z"] = 3, ["name"] = "default:goldblock"}, {["x"] = 2, ["y"] = 5, ["param1"] = 30, ["z"] = 15, ["name"] = "default:silver_sandstone_block"}, {["x"] = 2, ["y"] = 6, ["param1"] = 30, ["z"] = 15, ["name"] = "default:silver_sandstone_block"}, {["x"] = 2, ["y"] = 7, ["param1"] = 30, ["z"] = 15, ["name"] = "default:silver_sandstone_block"}, {["x"] = 2, ["y"] = 8, ["param1"] = 30, ["z"] = 15, ["name"] = "default:silver_sandstone_block"}, {["x"] = 2, ["y"] = 9, ["param1"] = 30, ["z"] = 15, ["name"] = "default:silver_sandstone_block"}, {["x"] = 2, ["y"] = 10, ["param1"] = 30, ["z"] = 15, ["name"] = "default:silver_sandstone_block"}, {["x"] = 2, ["y"] = 11, ["param1"] = 30, ["z"] = 15, ["name"] = "default:silver_sandstone_block"}, {["x"] = 2, ["y"] = 12, ["param1"] = 30, ["z"] = 15, ["name"] = "default:silver_sandstone_block"}, {["x"] = 2, ["y"] = 13, ["param1"] = 30, ["z"] = 15, ["name"] = "default:silver_sandstone_block"}, {["x"] = 2, ["y"] = 14, ["param1"] = 30, ["z"] = 15, ["name"] = "default:silver_sandstone_block"}, {["x"] = 2, ["y"] = 15, ["param1"] = 30, ["z"] = 15, ["name"] = "default:silver_sandstone_block"}, {["x"] = 2, ["y"] = 16, ["param1"] = 30, ["z"] = 15, ["name"] = "default:silver_sandstone_block"}, {["x"] = 2, ["y"] = 17, ["param1"] = 30, ["z"] = 15, ["name"] = "default:silver_sandstone_block"}, {["x"] = 2, ["y"] = 18, ["param1"] = 30, ["z"] = 15, ["name"] = "default:silver_sandstone_block"}, {["x"] = 2, ["y"] = 19, ["param1"] = 30, ["z"] = 15, ["name"] = "default:silver_sandstone_block"}, {["x"] = 2, ["y"] = 20, ["param1"] = 30, ["z"] = 15, ["name"] = "default:silver_sandstone_block"}, {["x"] = 2, ["y"] = 21, ["param1"] = 30, ["z"] = 15, ["name"] = "default:silver_sandstone_block"}, {["x"] = 2, ["y"] = 22, ["param1"] = 30, ["z"] = 15, ["name"] = "default:silver_sandstone_block"}, {["x"] = 2, ["y"] = 23, ["param1"] = 30, ["z"] = 15, ["name"] = "default:silver_sandstone_block"}, {["x"] = 2, ["y"] = 24, ["param1"] = 30, ["z"] = 3, ["name"] = "default:silver_sandstone_block"}, {["x"] = 2, ["y"] = 24, ["param1"] = 30, ["z"] = 14, ["name"] = "default:silver_sandstone_block"}, {["x"] = 2, ["y"] = 25, ["param1"] = 30, ["z"] = 4, ["name"] = "default:silver_sandstone_block"}, {["x"] = 2, ["y"] = 25, ["param1"] = 30, ["z"] = 13, ["name"] = "default:silver_sandstone_block"}, {["x"] = 2, ["y"] = 26, ["param1"] = 30, ["z"] = 5, ["name"] = "default:silver_sandstone_block"}, {["x"] = 2, ["y"] = 26, ["param1"] = 30, ["z"] = 12, ["name"] = "default:silver_sandstone_block"}, {["x"] = 2, ["y"] = 27, ["param1"] = 30, ["z"] = 6, ["name"] = "default:silver_sandstone_block"}, {["x"] = 2, ["y"] = 27, ["param1"] = 30, ["z"] = 7, ["name"] = "default:silver_sandstone_block"}, {["x"] = 2, ["y"] = 27, ["param1"] = 30, ["z"] = 8, ["name"] = "default:silver_sandstone_block"}, {["x"] = 2, ["y"] = 27, ["param1"] = 30, ["z"] = 9, ["name"] = "default:silver_sandstone_block"}, {["x"] = 2, ["y"] = 27, ["param1"] = 30, ["z"] = 10, ["name"] = "default:silver_sandstone_block"}, {["x"] = 2, ["y"] = 27, ["param1"] = 30, ["z"] = 11, ["name"] = "default:silver_sandstone_block"}, {["x"] = 3, ["y"] = 0, ["param1"] = 30, ["z"] = 3, ["name"] = "default:silver_sandstone_block"}, {["x"] = 3, ["y"] = 0, ["param1"] = 30, ["z"] = 4, ["name"] = "default:silver_sandstone_block"}, {["x"] = 3, ["y"] = 0, ["param1"] = 30, ["z"] = 5, ["name"] = "default:silver_sandstone_block"}, {["x"] = 3, ["y"] = 0, ["param1"] = 30, ["z"] = 6, ["name"] = "default:silver_sandstone_block"}, {["x"] = 3, ["y"] = 0, ["param1"] = 30, ["z"] = 7, ["name"] = "default:silver_sandstone_block"}, {["x"] = 3, ["y"] = 0, ["param1"] = 30, ["z"] = 8, ["name"] = "default:silver_sandstone_block"}, {["x"] = 3, ["y"] = 0, ["param1"] = 30, ["z"] = 9, ["name"] = "default:silver_sandstone_block"}, {["x"] = 3, ["y"] = 0, ["param1"] = 30, ["z"] = 10, ["name"] = "default:silver_sandstone_block"}, {["x"] = 3, ["y"] = 0, ["param1"] = 30, ["z"] = 11, ["name"] = "default:silver_sandstone_block"}, {["x"] = 3, ["y"] = 0, ["param1"] = 30, ["z"] = 12, ["name"] = "default:silver_sandstone_block"}, {["x"] = 3, ["y"] = 1, ["param1"] = 30, ["z"] = 13, ["name"] = "default:silver_sandstone_block"}, {["x"] = 3, ["y"] = 2, ["param1"] = 30, ["z"] = 13, ["name"] = "default:silver_sandstone_block"}, {["x"] = 3, ["y"] = 3, ["param1"] = 90, ["z"] = 3, ["name"] = "default:goldblock"}, {["x"] = 3, ["y"] = 3, ["param1"] = 30, ["z"] = 14, ["name"] = "default:silver_sandstone_block"}, {["x"] = 3, ["y"] = 4, ["param1"] = 90, ["z"] = 3, ["name"] = "default:goldblock"}, {["x"] = 3, ["y"] = 4, ["param1"] = 30, ["z"] = 14, ["name"] = "default:silver_sandstone_block"}, {["x"] = 3, ["y"] = 5, ["param1"] = 90, ["z"] = 3, ["name"] = "default:goldblock"}, {["x"] = 3, ["y"] = 5, ["param1"] = 30, ["z"] = 15, ["name"] = "default:silver_sandstone_block"}, {["x"] = 3, ["y"] = 6, ["param1"] = 30, ["z"] = 15, ["name"] = "default:silver_sandstone_block"}, {["x"] = 3, ["y"] = 7, ["param1"] = 30, ["z"] = 15, ["name"] = "default:silver_sandstone_block"}, {["x"] = 3, ["y"] = 8, ["param1"] = 30, ["z"] = 15, ["name"] = "default:silver_sandstone_block"}, {["x"] = 3, ["y"] = 9, ["param1"] = 30, ["z"] = 15, ["name"] = "default:silver_sandstone_block"}, {["x"] = 3, ["y"] = 10, ["param1"] = 30, ["z"] = 15, ["name"] = "default:silver_sandstone_block"}, {["x"] = 3, ["y"] = 11, ["param1"] = 30, ["z"] = 15, ["name"] = "default:silver_sandstone_block"}, {["x"] = 3, ["y"] = 12, ["param1"] = 30, ["z"] = 15, ["name"] = "default:silver_sandstone_block"}, {["x"] = 3, ["y"] = 13, ["param1"] = 30, ["z"] = 15, ["name"] = "default:silver_sandstone_block"}, {["x"] = 3, ["y"] = 14, ["param1"] = 30, ["z"] = 15, ["name"] = "default:silver_sandstone_block"}, {["x"] = 3, ["y"] = 15, ["param1"] = 30, ["z"] = 15, ["name"] = "default:silver_sandstone_block"}, {["x"] = 3, ["y"] = 16, ["param1"] = 30, ["z"] = 15, ["name"] = "default:silver_sandstone_block"}, {["x"] = 3, ["y"] = 17, ["param1"] = 30, ["z"] = 15, ["name"] = "default:silver_sandstone_block"}, {["x"] = 3, ["y"] = 18, ["param1"] = 30, ["z"] = 15, ["name"] = "default:silver_sandstone_block"}, {["x"] = 3, ["y"] = 19, ["param1"] = 30, ["z"] = 15, ["name"] = "default:silver_sandstone_block"}, {["x"] = 3, ["y"] = 20, ["param1"] = 30, ["z"] = 15, ["name"] = "default:silver_sandstone_block"}, {["x"] = 3, ["y"] = 21, ["param1"] = 30, ["z"] = 15, ["name"] = "default:silver_sandstone_block"}, {["x"] = 3, ["y"] = 22, ["param1"] = 30, ["z"] = 15, ["name"] = "default:silver_sandstone_block"}, {["x"] = 3, ["y"] = 23, ["param1"] = 30, ["z"] = 15, ["name"] = "default:silver_sandstone_block"}, {["x"] = 3, ["y"] = 24, ["param1"] = 30, ["z"] = 3, ["name"] = "default:silver_sandstone_block"}, {["x"] = 3, ["y"] = 24, ["param1"] = 30, ["z"] = 14, ["name"] = "default:silver_sandstone_block"}, {["x"] = 3, ["y"] = 25, ["param1"] = 30, ["z"] = 4, ["name"] = "default:silver_sandstone_block"}, {["x"] = 3, ["y"] = 25, ["param1"] = 30, ["z"] = 13, ["name"] = "default:silver_sandstone_block"}, {["x"] = 3, ["y"] = 26, ["param1"] = 30, ["z"] = 5, ["name"] = "default:silver_sandstone_block"}, {["x"] = 3, ["y"] = 26, ["param1"] = 30, ["z"] = 12, ["name"] = "default:silver_sandstone_block"}, {["x"] = 3, ["y"] = 27, ["param1"] = 30, ["z"] = 6, ["name"] = "default:silver_sandstone_block"}, {["x"] = 3, ["y"] = 27, ["param1"] = 30, ["z"] = 7, ["name"] = "default:silver_sandstone_block"}, {["x"] = 3, ["y"] = 27, ["param1"] = 30, ["z"] = 8, ["name"] = "default:silver_sandstone_block"}, {["x"] = 3, ["y"] = 27, ["param1"] = 30, ["z"] = 9, ["name"] = "default:silver_sandstone_block"}, {["x"] = 3, ["y"] = 27, ["param1"] = 30, ["z"] = 10, ["name"] = "default:silver_sandstone_block"}, {["x"] = 3, ["y"] = 27, ["param1"] = 30, ["z"] = 11, ["name"] = "default:silver_sandstone_block"}, {["x"] = 4, ["y"] = 0, ["param1"] = 30, ["z"] = 3, ["name"] = "default:silver_sandstone_block"}, {["x"] = 4, ["y"] = 0, ["param1"] = 30, ["z"] = 4, ["name"] = "default:silver_sandstone_block"}, {["x"] = 4, ["y"] = 0, ["param1"] = 30, ["z"] = 5, ["name"] = "default:silver_sandstone_block"}, {["x"] = 4, ["y"] = 0, ["param1"] = 30, ["z"] = 6, ["name"] = "default:silver_sandstone_block"}, {["x"] = 4, ["y"] = 0, ["param1"] = 30, ["z"] = 7, ["name"] = "default:silver_sandstone_block"}, {["x"] = 4, ["y"] = 0, ["param1"] = 30, ["z"] = 8, ["name"] = "default:silver_sandstone_block"}, {["x"] = 4, ["y"] = 0, ["param1"] = 30, ["z"] = 9, ["name"] = "default:silver_sandstone_block"}, {["x"] = 4, ["y"] = 0, ["param1"] = 30, ["z"] = 10, ["name"] = "default:silver_sandstone_block"}, {["x"] = 4, ["y"] = 0, ["param1"] = 30, ["z"] = 11, ["name"] = "default:silver_sandstone_block"}, {["x"] = 4, ["y"] = 0, ["param1"] = 30, ["z"] = 12, ["name"] = "default:silver_sandstone_block"}, {["x"] = 4, ["y"] = 1, ["param1"] = 30, ["z"] = 13, ["name"] = "default:silver_sandstone_block"}, {["x"] = 4, ["y"] = 2, ["param1"] = 30, ["z"] = 13, ["name"] = "default:silver_sandstone_block"}, {["x"] = 4, ["y"] = 3, ["param1"] = 90, ["z"] = 3, ["name"] = "default:goldblock"}, {["x"] = 4, ["y"] = 3, ["param1"] = 30, ["z"] = 14, ["name"] = "default:silver_sandstone_block"}, {["x"] = 4, ["y"] = 4, ["param1"] = 90, ["z"] = 3, ["name"] = "default:goldblock"}, {["x"] = 4, ["y"] = 4, ["param1"] = 30, ["z"] = 14, ["name"] = "default:silver_sandstone_block"}, {["x"] = 4, ["y"] = 5, ["param1"] = 90, ["z"] = 3, ["name"] = "default:goldblock"}, {["x"] = 4, ["y"] = 5, ["param1"] = 30, ["z"] = 15, ["name"] = "default:silver_sandstone_block"}, {["x"] = 4, ["y"] = 6, ["param1"] = 30, ["z"] = 15, ["name"] = "default:silver_sandstone_block"}, {["x"] = 4, ["y"] = 7, ["param1"] = 30, ["z"] = 15, ["name"] = "default:silver_sandstone_block"}, {["x"] = 4, ["y"] = 8, ["param1"] = 30, ["z"] = 15, ["name"] = "default:silver_sandstone_block"}, {["x"] = 4, ["y"] = 9, ["param1"] = 30, ["z"] = 15, ["name"] = "default:silver_sandstone_block"}, {["x"] = 4, ["y"] = 10, ["param1"] = 30, ["z"] = 15, ["name"] = "default:silver_sandstone_block"}, {["x"] = 4, ["y"] = 11, ["param1"] = 30, ["z"] = 15, ["name"] = "default:silver_sandstone_block"}, {["x"] = 4, ["y"] = 12, ["param1"] = 30, ["z"] = 15, ["name"] = "default:silver_sandstone_block"}, {["x"] = 4, ["y"] = 13, ["param1"] = 30, ["z"] = 15, ["name"] = "default:silver_sandstone_block"}, {["x"] = 4, ["y"] = 14, ["param1"] = 30, ["z"] = 15, ["name"] = "default:silver_sandstone_block"}, {["x"] = 4, ["y"] = 15, ["param1"] = 30, ["z"] = 15, ["name"] = "default:silver_sandstone_block"}, {["x"] = 4, ["y"] = 16, ["param1"] = 30, ["z"] = 15, ["name"] = "default:silver_sandstone_block"}, {["x"] = 4, ["y"] = 17, ["param1"] = 30, ["z"] = 15, ["name"] = "default:silver_sandstone_block"}, {["x"] = 4, ["y"] = 18, ["param1"] = 30, ["z"] = 15, ["name"] = "default:silver_sandstone_block"}, {["x"] = 4, ["y"] = 19, ["param1"] = 30, ["z"] = 15, ["name"] = "default:silver_sandstone_block"}, {["x"] = 4, ["y"] = 20, ["param1"] = 30, ["z"] = 15, ["name"] = "default:silver_sandstone_block"}, {["x"] = 4, ["y"] = 21, ["param1"] = 30, ["z"] = 15, ["name"] = "default:silver_sandstone_block"}, {["x"] = 4, ["y"] = 22, ["param1"] = 30, ["z"] = 15, ["name"] = "default:silver_sandstone_block"}, {["x"] = 4, ["y"] = 23, ["param1"] = 30, ["z"] = 15, ["name"] = "default:silver_sandstone_block"}, {["x"] = 4, ["y"] = 24, ["param1"] = 30, ["z"] = 3, ["name"] = "default:silver_sandstone_block"}, {["x"] = 4, ["y"] = 24, ["param1"] = 30, ["z"] = 14, ["name"] = "default:silver_sandstone_block"}, {["x"] = 4, ["y"] = 25, ["param1"] = 30, ["z"] = 4, ["name"] = "default:silver_sandstone_block"}, {["x"] = 4, ["y"] = 25, ["param1"] = 30, ["z"] = 13, ["name"] = "default:silver_sandstone_block"}, {["x"] = 4, ["y"] = 26, ["param1"] = 30, ["z"] = 5, ["name"] = "default:silver_sandstone_block"}, {["x"] = 4, ["y"] = 26, ["param1"] = 30, ["z"] = 12, ["name"] = "default:silver_sandstone_block"}, {["x"] = 4, ["y"] = 27, ["param1"] = 30, ["z"] = 6, ["name"] = "default:silver_sandstone_block"}, {["x"] = 4, ["y"] = 27, ["param1"] = 30, ["z"] = 7, ["name"] = "default:silver_sandstone_block"}, {["x"] = 4, ["y"] = 27, ["param1"] = 30, ["z"] = 8, ["name"] = "default:silver_sandstone_block"}, {["x"] = 4, ["y"] = 27, ["param1"] = 30, ["z"] = 9, ["name"] = "default:silver_sandstone_block"}, {["x"] = 4, ["y"] = 27, ["param1"] = 30, ["z"] = 10, ["name"] = "default:silver_sandstone_block"}, {["x"] = 4, ["y"] = 27, ["param1"] = 30, ["z"] = 11, ["name"] = "default:silver_sandstone_block"}, {["x"] = 5, ["y"] = 0, ["param1"] = 30, ["z"] = 3, ["name"] = "default:silver_sandstone_block"}, {["x"] = 5, ["y"] = 0, ["param1"] = 30, ["z"] = 4, ["name"] = "default:silver_sandstone_block"}, {["x"] = 5, ["y"] = 0, ["param1"] = 30, ["z"] = 5, ["name"] = "default:silver_sandstone_block"}, {["x"] = 5, ["y"] = 0, ["param1"] = 30, ["z"] = 6, ["name"] = "default:silver_sandstone_block"}, {["x"] = 5, ["y"] = 0, ["param1"] = 30, ["z"] = 7, ["name"] = "default:silver_sandstone_block"}, {["x"] = 5, ["y"] = 0, ["param1"] = 30, ["z"] = 8, ["name"] = "default:silver_sandstone_block"}, {["x"] = 5, ["y"] = 0, ["param1"] = 30, ["z"] = 9, ["name"] = "default:silver_sandstone_block"}, {["x"] = 5, ["y"] = 0, ["param1"] = 30, ["z"] = 10, ["name"] = "default:silver_sandstone_block"}, {["x"] = 5, ["y"] = 0, ["param1"] = 30, ["z"] = 11, ["name"] = "default:silver_sandstone_block"}, {["x"] = 5, ["y"] = 0, ["param1"] = 30, ["z"] = 12, ["name"] = "default:silver_sandstone_block"}, {["x"] = 5, ["y"] = 1, ["param1"] = 30, ["z"] = 13, ["name"] = "default:silver_sandstone_block"}, {["x"] = 5, ["y"] = 2, ["param1"] = 30, ["z"] = 13, ["name"] = "default:silver_sandstone_block"}, {["x"] = 5, ["y"] = 3, ["param1"] = 90, ["z"] = 3, ["name"] = "default:goldblock"}, {["x"] = 5, ["y"] = 3, ["param1"] = 30, ["z"] = 14, ["name"] = "default:silver_sandstone_block"}, {["x"] = 5, ["y"] = 4, ["param1"] = 90, ["z"] = 3, ["name"] = "default:goldblock"}, {["x"] = 5, ["y"] = 4, ["param1"] = 30, ["z"] = 14, ["name"] = "default:silver_sandstone_block"}, {["x"] = 5, ["y"] = 5, ["param1"] = 90, ["z"] = 3, ["name"] = "default:goldblock"}, {["x"] = 5, ["y"] = 5, ["param1"] = 30, ["z"] = 15, ["name"] = "default:silver_sandstone_block"}, {["x"] = 5, ["y"] = 6, ["param1"] = 30, ["z"] = 15, ["name"] = "default:silver_sandstone_block"}, {["x"] = 5, ["y"] = 7, ["param1"] = 30, ["z"] = 15, ["name"] = "default:silver_sandstone_block"}, {["x"] = 5, ["y"] = 8, ["param1"] = 30, ["z"] = 15, ["name"] = "default:silver_sandstone_block"}, {["x"] = 5, ["y"] = 9, ["param1"] = 30, ["z"] = 15, ["name"] = "default:silver_sandstone_block"}, {["x"] = 5, ["y"] = 10, ["param1"] = 30, ["z"] = 15, ["name"] = "default:silver_sandstone_block"}, {["x"] = 5, ["y"] = 11, ["param1"] = 30, ["z"] = 15, ["name"] = "default:silver_sandstone_block"}, {["x"] = 5, ["y"] = 12, ["param1"] = 30, ["z"] = 15, ["name"] = "default:silver_sandstone_block"}, {["x"] = 5, ["y"] = 13, ["param1"] = 30, ["z"] = 15, ["name"] = "default:silver_sandstone_block"}, {["x"] = 5, ["y"] = 14, ["param1"] = 30, ["z"] = 15, ["name"] = "default:silver_sandstone_block"}, {["x"] = 5, ["y"] = 15, ["param1"] = 30, ["z"] = 15, ["name"] = "default:silver_sandstone_block"}, {["x"] = 5, ["y"] = 16, ["param1"] = 30, ["z"] = 15, ["name"] = "default:silver_sandstone_block"}, {["x"] = 5, ["y"] = 17, ["param1"] = 30, ["z"] = 15, ["name"] = "default:silver_sandstone_block"}, {["x"] = 5, ["y"] = 18, ["param1"] = 30, ["z"] = 15, ["name"] = "default:silver_sandstone_block"}, {["x"] = 5, ["y"] = 19, ["param1"] = 30, ["z"] = 15, ["name"] = "default:silver_sandstone_block"}, {["x"] = 5, ["y"] = 20, ["param1"] = 30, ["z"] = 15, ["name"] = "default:silver_sandstone_block"}, {["x"] = 5, ["y"] = 21, ["param1"] = 30, ["z"] = 15, ["name"] = "default:silver_sandstone_block"}, {["x"] = 5, ["y"] = 22, ["param1"] = 30, ["z"] = 15, ["name"] = "default:silver_sandstone_block"}, {["x"] = 5, ["y"] = 23, ["param1"] = 30, ["z"] = 15, ["name"] = "default:silver_sandstone_block"}, {["x"] = 5, ["y"] = 24, ["param1"] = 30, ["z"] = 3, ["name"] = "default:silver_sandstone_block"}, {["x"] = 5, ["y"] = 24, ["param1"] = 30, ["z"] = 14, ["name"] = "default:silver_sandstone_block"}, {["x"] = 5, ["y"] = 25, ["param1"] = 30, ["z"] = 4, ["name"] = "default:silver_sandstone_block"}, {["x"] = 5, ["y"] = 25, ["param1"] = 30, ["z"] = 13, ["name"] = "default:silver_sandstone_block"}, {["x"] = 5, ["y"] = 26, ["param1"] = 30, ["z"] = 5, ["name"] = "default:silver_sandstone_block"}, {["x"] = 5, ["y"] = 26, ["param1"] = 30, ["z"] = 12, ["name"] = "default:silver_sandstone_block"}, {["x"] = 5, ["y"] = 27, ["param1"] = 30, ["z"] = 6, ["name"] = "default:silver_sandstone_block"}, {["x"] = 5, ["y"] = 27, ["param1"] = 30, ["z"] = 7, ["name"] = "default:silver_sandstone_block"}, {["x"] = 5, ["y"] = 27, ["param1"] = 30, ["z"] = 8, ["name"] = "default:silver_sandstone_block"}, {["x"] = 5, ["y"] = 27, ["param1"] = 30, ["z"] = 9, ["name"] = "default:silver_sandstone_block"}, {["x"] = 5, ["y"] = 27, ["param1"] = 30, ["z"] = 10, ["name"] = "default:silver_sandstone_block"}, {["x"] = 5, ["y"] = 27, ["param1"] = 30, ["z"] = 11, ["name"] = "default:silver_sandstone_block"}, {["x"] = 6, ["y"] = 0, ["param1"] = 30, ["z"] = 3, ["name"] = "default:silver_sandstone_block"}, {["x"] = 6, ["y"] = 0, ["param1"] = 30, ["z"] = 4, ["name"] = "default:silver_sandstone_block"}, {["x"] = 6, ["y"] = 0, ["param1"] = 30, ["z"] = 5, ["name"] = "default:silver_sandstone_block"}, {["x"] = 6, ["y"] = 0, ["param1"] = 30, ["z"] = 6, ["name"] = "default:silver_sandstone_block"}, {["x"] = 6, ["y"] = 0, ["param1"] = 30, ["z"] = 7, ["name"] = "default:silver_sandstone_block"}, {["x"] = 6, ["y"] = 0, ["param1"] = 30, ["z"] = 8, ["name"] = "default:silver_sandstone_block"}, {["x"] = 6, ["y"] = 0, ["param1"] = 30, ["z"] = 9, ["name"] = "default:silver_sandstone_block"}, {["x"] = 6, ["y"] = 0, ["param1"] = 30, ["z"] = 10, ["name"] = "default:silver_sandstone_block"}, {["x"] = 6, ["y"] = 0, ["param1"] = 30, ["z"] = 11, ["name"] = "default:silver_sandstone_block"}, {["x"] = 6, ["y"] = 0, ["param1"] = 30, ["z"] = 12, ["name"] = "default:silver_sandstone_block"}, {["x"] = 6, ["y"] = 1, ["param1"] = 30, ["z"] = 13, ["name"] = "default:silver_sandstone_block"}, {["x"] = 6, ["y"] = 2, ["param1"] = 30, ["z"] = 13, ["name"] = "default:silver_sandstone_block"}, {["x"] = 6, ["y"] = 3, ["param1"] = 90, ["z"] = 3, ["name"] = "default:goldblock"}, {["x"] = 6, ["y"] = 3, ["param1"] = 30, ["z"] = 14, ["name"] = "default:silver_sandstone_block"}, {["x"] = 6, ["y"] = 4, ["param1"] = 90, ["z"] = 3, ["name"] = "default:goldblock"}, {["x"] = 6, ["y"] = 4, ["param1"] = 30, ["z"] = 14, ["name"] = "default:silver_sandstone_block"}, {["x"] = 6, ["y"] = 5, ["param1"] = 90, ["z"] = 3, ["name"] = "default:goldblock"}, {["x"] = 6, ["y"] = 5, ["param1"] = 30, ["z"] = 15, ["name"] = "default:silver_sandstone_block"}, {["x"] = 6, ["y"] = 6, ["param1"] = 30, ["z"] = 15, ["name"] = "default:silver_sandstone_block"}, {["x"] = 6, ["y"] = 7, ["param1"] = 30, ["z"] = 15, ["name"] = "default:silver_sandstone_block"}, {["x"] = 6, ["y"] = 8, ["param1"] = 30, ["z"] = 15, ["name"] = "default:silver_sandstone_block"}, {["x"] = 6, ["y"] = 9, ["param1"] = 30, ["z"] = 15, ["name"] = "default:silver_sandstone_block"}, {["x"] = 6, ["y"] = 10, ["param1"] = 30, ["z"] = 15, ["name"] = "default:silver_sandstone_block"}, {["x"] = 6, ["y"] = 11, ["param1"] = 30, ["z"] = 15, ["name"] = "default:silver_sandstone_block"}, {["x"] = 6, ["y"] = 12, ["param1"] = 30, ["z"] = 15, ["name"] = "default:silver_sandstone_block"}, {["x"] = 6, ["y"] = 13, ["param1"] = 30, ["z"] = 15, ["name"] = "default:silver_sandstone_block"}, {["x"] = 6, ["y"] = 14, ["param1"] = 30, ["z"] = 15, ["name"] = "default:silver_sandstone_block"}, {["x"] = 6, ["y"] = 15, ["param1"] = 30, ["z"] = 15, ["name"] = "default:silver_sandstone_block"}, {["x"] = 6, ["y"] = 16, ["param1"] = 30, ["z"] = 15, ["name"] = "default:silver_sandstone_block"}, {["x"] = 6, ["y"] = 17, ["param1"] = 30, ["z"] = 15, ["name"] = "default:silver_sandstone_block"}, {["x"] = 6, ["y"] = 18, ["param1"] = 30, ["z"] = 15, ["name"] = "default:silver_sandstone_block"}, {["x"] = 6, ["y"] = 19, ["param1"] = 30, ["z"] = 15, ["name"] = "default:silver_sandstone_block"}, {["x"] = 6, ["y"] = 20, ["param1"] = 30, ["z"] = 15, ["name"] = "default:silver_sandstone_block"}, {["x"] = 6, ["y"] = 21, ["param1"] = 30, ["z"] = 15, ["name"] = "default:silver_sandstone_block"}, {["x"] = 6, ["y"] = 22, ["param1"] = 30, ["z"] = 15, ["name"] = "default:silver_sandstone_block"}, {["x"] = 6, ["y"] = 23, ["param1"] = 30, ["z"] = 15, ["name"] = "default:silver_sandstone_block"}, {["x"] = 6, ["y"] = 24, ["param1"] = 30, ["z"] = 3, ["name"] = "default:silver_sandstone_block"}, {["x"] = 6, ["y"] = 24, ["param1"] = 30, ["z"] = 14, ["name"] = "default:silver_sandstone_block"}, {["x"] = 6, ["y"] = 25, ["param1"] = 30, ["z"] = 4, ["name"] = "default:silver_sandstone_block"}, {["x"] = 6, ["y"] = 25, ["param1"] = 30, ["z"] = 13, ["name"] = "default:silver_sandstone_block"}, {["x"] = 6, ["y"] = 26, ["param1"] = 30, ["z"] = 5, ["name"] = "default:silver_sandstone_block"}, {["x"] = 6, ["y"] = 26, ["param1"] = 30, ["z"] = 12, ["name"] = "default:silver_sandstone_block"}, {["x"] = 6, ["y"] = 27, ["param1"] = 30, ["z"] = 6, ["name"] = "default:silver_sandstone_block"}, {["x"] = 6, ["y"] = 27, ["param1"] = 30, ["z"] = 7, ["name"] = "default:silver_sandstone_block"}, {["x"] = 6, ["y"] = 27, ["param1"] = 30, ["z"] = 8, ["name"] = "default:silver_sandstone_block"}, {["x"] = 6, ["y"] = 27, ["param1"] = 30, ["z"] = 9, ["name"] = "default:silver_sandstone_block"}, {["x"] = 6, ["y"] = 27, ["param1"] = 30, ["z"] = 10, ["name"] = "default:silver_sandstone_block"}, {["x"] = 6, ["y"] = 27, ["param1"] = 30, ["z"] = 11, ["name"] = "default:silver_sandstone_block"}, {["x"] = 6, ["y"] = 28, ["param1"] = 30, ["z"] = 7, ["name"] = "default:silver_sandstone_block"}, {["x"] = 6, ["y"] = 28, ["param1"] = 30, ["z"] = 8, ["name"] = "default:silver_sandstone_block"}, {["x"] = 6, ["y"] = 28, ["param1"] = 30, ["z"] = 9, ["name"] = "default:silver_sandstone_block"}, {["x"] = 6, ["y"] = 28, ["param1"] = 30, ["z"] = 10, ["name"] = "default:silver_sandstone_block"}, {["x"] = 7, ["y"] = 0, ["param1"] = 30, ["z"] = 3, ["name"] = "default:silver_sandstone_block"}, {["x"] = 7, ["y"] = 0, ["param1"] = 30, ["z"] = 4, ["name"] = "default:silver_sandstone_block"}, {["x"] = 7, ["y"] = 0, ["param1"] = 30, ["z"] = 5, ["name"] = "default:silver_sandstone_block"}, {["x"] = 7, ["y"] = 0, ["param1"] = 30, ["z"] = 6, ["name"] = "default:silver_sandstone_block"}, {["x"] = 7, ["y"] = 0, ["param1"] = 30, ["z"] = 7, ["name"] = "default:silver_sandstone_block"}, {["x"] = 7, ["y"] = 0, ["param1"] = 30, ["z"] = 8, ["name"] = "default:silver_sandstone_block"}, {["x"] = 7, ["y"] = 0, ["param1"] = 30, ["z"] = 9, ["name"] = "default:silver_sandstone_block"}, {["x"] = 7, ["y"] = 0, ["param1"] = 30, ["z"] = 10, ["name"] = "default:silver_sandstone_block"}, {["x"] = 7, ["y"] = 0, ["param1"] = 30, ["z"] = 11, ["name"] = "default:silver_sandstone_block"}, {["x"] = 7, ["y"] = 0, ["param1"] = 30, ["z"] = 12, ["name"] = "default:silver_sandstone_block"}, {["x"] = 7, ["y"] = 1, ["param1"] = 30, ["z"] = 13, ["name"] = "default:silver_sandstone_block"}, {["x"] = 7, ["y"] = 2, ["param1"] = 30, ["z"] = 13, ["name"] = "default:silver_sandstone_block"}, {["x"] = 7, ["y"] = 3, ["param1"] = 90, ["z"] = 3, ["name"] = "default:goldblock"}, {["x"] = 7, ["y"] = 3, ["param1"] = 30, ["z"] = 14, ["name"] = "default:silver_sandstone_block"}, {["x"] = 7, ["y"] = 4, ["param1"] = 90, ["z"] = 3, ["name"] = "default:goldblock"}, {["x"] = 7, ["y"] = 4, ["param1"] = 30, ["z"] = 14, ["name"] = "default:silver_sandstone_block"}, {["x"] = 7, ["y"] = 5, ["param1"] = 90, ["z"] = 3, ["name"] = "default:goldblock"}, {["x"] = 7, ["y"] = 5, ["param1"] = 30, ["z"] = 15, ["name"] = "default:silver_sandstone_block"}, {["x"] = 7, ["y"] = 6, ["param1"] = 30, ["z"] = 15, ["name"] = "default:silver_sandstone_block"}, {["x"] = 7, ["y"] = 7, ["param1"] = 30, ["z"] = 15, ["name"] = "default:silver_sandstone_block"}, {["x"] = 7, ["y"] = 8, ["param1"] = 30, ["z"] = 15, ["name"] = "default:silver_sandstone_block"}, {["x"] = 7, ["y"] = 9, ["param1"] = 30, ["z"] = 15, ["name"] = "default:silver_sandstone_block"}, {["x"] = 7, ["y"] = 10, ["param1"] = 30, ["z"] = 15, ["name"] = "default:silver_sandstone_block"}, {["x"] = 7, ["y"] = 11, ["param1"] = 30, ["z"] = 15, ["name"] = "default:silver_sandstone_block"}, {["x"] = 7, ["y"] = 12, ["param1"] = 30, ["z"] = 15, ["name"] = "default:silver_sandstone_block"}, {["x"] = 7, ["y"] = 13, ["param1"] = 30, ["z"] = 15, ["name"] = "default:silver_sandstone_block"}, {["x"] = 7, ["y"] = 14, ["param1"] = 30, ["z"] = 15, ["name"] = "default:silver_sandstone_block"}, {["x"] = 7, ["y"] = 15, ["param1"] = 30, ["z"] = 15, ["name"] = "default:silver_sandstone_block"}, {["x"] = 7, ["y"] = 16, ["param1"] = 30, ["z"] = 15, ["name"] = "default:silver_sandstone_block"}, {["x"] = 7, ["y"] = 17, ["param1"] = 30, ["z"] = 15, ["name"] = "default:silver_sandstone_block"}, {["x"] = 7, ["y"] = 18, ["param1"] = 30, ["z"] = 15, ["name"] = "default:silver_sandstone_block"}, {["x"] = 7, ["y"] = 19, ["param1"] = 30, ["z"] = 15, ["name"] = "default:silver_sandstone_block"}, {["x"] = 7, ["y"] = 20, ["param1"] = 30, ["z"] = 15, ["name"] = "default:silver_sandstone_block"}, {["x"] = 7, ["y"] = 21, ["param1"] = 30, ["z"] = 15, ["name"] = "default:silver_sandstone_block"}, {["x"] = 7, ["y"] = 22, ["param1"] = 30, ["z"] = 15, ["name"] = "default:silver_sandstone_block"}, {["x"] = 7, ["y"] = 23, ["param1"] = 30, ["z"] = 15, ["name"] = "default:silver_sandstone_block"}, {["x"] = 7, ["y"] = 24, ["param1"] = 30, ["z"] = 3, ["name"] = "default:silver_sandstone_block"}, {["x"] = 7, ["y"] = 24, ["param1"] = 30, ["z"] = 14, ["name"] = "default:silver_sandstone_block"}, {["x"] = 7, ["y"] = 25, ["param1"] = 30, ["z"] = 4, ["name"] = "default:silver_sandstone_block"}, {["x"] = 7, ["y"] = 25, ["param1"] = 30, ["z"] = 13, ["name"] = "default:silver_sandstone_block"}, {["x"] = 7, ["y"] = 26, ["param1"] = 30, ["z"] = 5, ["name"] = "default:silver_sandstone_block"}, {["x"] = 7, ["y"] = 26, ["param1"] = 30, ["z"] = 12, ["name"] = "default:silver_sandstone_block"}, {["x"] = 7, ["y"] = 27, ["param1"] = 30, ["z"] = 6, ["name"] = "default:silver_sandstone_block"}, {["x"] = 7, ["y"] = 27, ["param1"] = 30, ["z"] = 7, ["name"] = "default:silver_sandstone_block"}, {["x"] = 7, ["y"] = 27, ["param1"] = 30, ["z"] = 8, ["name"] = "default:silver_sandstone_block"}, {["x"] = 7, ["y"] = 27, ["param1"] = 30, ["z"] = 9, ["name"] = "default:silver_sandstone_block"}, {["x"] = 7, ["y"] = 27, ["param1"] = 30, ["z"] = 10, ["name"] = "default:silver_sandstone_block"}, {["x"] = 7, ["y"] = 27, ["param1"] = 30, ["z"] = 11, ["name"] = "default:silver_sandstone_block"}, {["x"] = 7, ["y"] = 28, ["param1"] = 30, ["z"] = 7, ["name"] = "default:silver_sandstone_block"}, {["x"] = 7, ["y"] = 28, ["param1"] = 30, ["z"] = 8, ["name"] = "default:silver_sandstone_block"}, {["x"] = 7, ["y"] = 28, ["param1"] = 30, ["z"] = 9, ["name"] = "default:silver_sandstone_block"}, {["x"] = 7, ["y"] = 28, ["param1"] = 30, ["z"] = 10, ["name"] = "default:silver_sandstone_block"}, {["x"] = 7, ["y"] = 29, ["param1"] = 30, ["z"] = 8, ["name"] = "default:silver_sandstone_block"}, {["x"] = 7, ["y"] = 29, ["param1"] = 30, ["z"] = 9, ["name"] = "default:silver_sandstone_block"}, {["x"] = 7, ["y"] = 30, ["param1"] = 30, ["z"] = 8, ["name"] = "default:silver_sandstone_block"}, {["x"] = 7, ["y"] = 30, ["param1"] = 30, ["z"] = 9, ["name"] = "default:silver_sandstone_block"}, {["x"] = 7, ["y"] = 31, ["param1"] = 30, ["z"] = 8, ["name"] = "default:silver_sandstone_block"}, {["x"] = 7, ["y"] = 31, ["param1"] = 30, ["z"] = 9, ["name"] = "default:silver_sandstone_block"}, {["x"] = 7, ["y"] = 32, ["param1"] = 30, ["z"] = 8, ["name"] = "default:silver_sandstone_block"}, {["x"] = 7, ["y"] = 32, ["param1"] = 30, ["z"] = 9, ["name"] = "default:silver_sandstone_block"}, {["x"] = 7, ["y"] = 33, ["param1"] = 30, ["z"] = 8, ["name"] = "default:silver_sandstone_block"}, {["x"] = 7, ["y"] = 33, ["param1"] = 30, ["z"] = 9, ["name"] = "default:silver_sandstone_block"}, {["x"] = 7, ["y"] = 34, ["param1"] = 30, ["z"] = 8, ["name"] = "default:silver_sandstone_block"}, {["x"] = 7, ["y"] = 34, ["param1"] = 30, ["z"] = 9, ["name"] = "default:silver_sandstone_block"}, {["x"] = 7, ["y"] = 35, ["param1"] = 30, ["z"] = 8, ["name"] = "default:silver_sandstone_block"}, {["x"] = 7, ["y"] = 35, ["param1"] = 30, ["z"] = 9, ["name"] = "default:silver_sandstone_block"}, {["x"] = 7, ["y"] = 36, ["param1"] = 30, ["z"] = 8, ["name"] = "default:silver_sandstone_block"}, {["x"] = 7, ["y"] = 36, ["param1"] = 30, ["z"] = 9, ["name"] = "default:silver_sandstone_block"}, {["x"] = 7, ["y"] = 37, ["param1"] = 30, ["z"] = 8, ["name"] = "default:silver_sandstone_block"}, {["x"] = 7, ["y"] = 37, ["param1"] = 30, ["z"] = 9, ["name"] = "default:silver_sandstone_block"}, {["x"] = 7, ["y"] = 38, ["param1"] = 30, ["z"] = 8, ["name"] = "default:silver_sandstone_block"}, {["x"] = 7, ["y"] = 38, ["param1"] = 30, ["z"] = 9, ["name"] = "default:silver_sandstone_block"}, {["x"] = 7, ["y"] = 39, ["param1"] = 30, ["z"] = 8, ["name"] = "default:silver_sandstone_block"}, {["x"] = 7, ["y"] = 39, ["param1"] = 30, ["z"] = 9, ["name"] = "default:silver_sandstone_block"}, {["x"] = 7, ["y"] = 40, ["param1"] = 30, ["z"] = 8, ["name"] = "default:silver_sandstone_block"}, {["x"] = 7, ["y"] = 40, ["param1"] = 30, ["z"] = 9, ["name"] = "default:silver_sandstone_block"}, {["x"] = 7, ["y"] = 41, ["param1"] = 30, ["z"] = 8, ["name"] = "default:silver_sandstone_block"}, {["x"] = 7, ["y"] = 41, ["param1"] = 30, ["z"] = 9, ["name"] = "default:silver_sandstone_block"}, {["x"] = 7, ["y"] = 42, ["param1"] = 30, ["z"] = 8, ["name"] = "default:silver_sandstone_block"}, {["x"] = 7, ["y"] = 42, ["param1"] = 30, ["z"] = 9, ["name"] = "default:silver_sandstone_block"}, {["x"] = 7, ["y"] = 43, ["param1"] = 30, ["z"] = 8, ["name"] = "default:silver_sandstone_block"}, {["x"] = 7, ["y"] = 43, ["param1"] = 30, ["z"] = 9, ["name"] = "default:silver_sandstone_block"}, {["x"] = 7, ["y"] = 44, ["param1"] = 30, ["z"] = 8, ["name"] = "default:silver_sandstone_block"}, {["x"] = 7, ["y"] = 44, ["param1"] = 30, ["z"] = 9, ["name"] = "default:silver_sandstone_block"}, {["x"] = 7, ["y"] = 45, ["param1"] = 30, ["z"] = 8, ["name"] = "default:silver_sandstone_block"}, {["x"] = 7, ["y"] = 45, ["param1"] = 30, ["z"] = 9, ["name"] = "default:silver_sandstone_block"}, {["x"] = 8, ["y"] = 0, ["param1"] = 30, ["z"] = 3, ["name"] = "default:silver_sandstone_block"}, {["x"] = 8, ["y"] = 0, ["param1"] = 30, ["z"] = 4, ["name"] = "default:silver_sandstone_block"}, {["x"] = 8, ["y"] = 0, ["param1"] = 30, ["z"] = 5, ["name"] = "default:silver_sandstone_block"}, {["x"] = 8, ["y"] = 0, ["param1"] = 30, ["z"] = 6, ["name"] = "default:silver_sandstone_block"}, {["x"] = 8, ["y"] = 0, ["param1"] = 30, ["z"] = 7, ["name"] = "default:silver_sandstone_block"}, {["x"] = 8, ["y"] = 0, ["param1"] = 30, ["z"] = 8, ["name"] = "default:silver_sandstone_block"}, {["x"] = 8, ["y"] = 0, ["param1"] = 30, ["z"] = 9, ["name"] = "default:silver_sandstone_block"}, {["x"] = 8, ["y"] = 0, ["param1"] = 30, ["z"] = 10, ["name"] = "default:silver_sandstone_block"}, {["x"] = 8, ["y"] = 0, ["param1"] = 30, ["z"] = 11, ["name"] = "default:silver_sandstone_block"}, {["x"] = 8, ["y"] = 0, ["param1"] = 30, ["z"] = 12, ["name"] = "default:silver_sandstone_block"}, {["x"] = 8, ["y"] = 1, ["param1"] = 30, ["z"] = 13, ["name"] = "default:silver_sandstone_block"}, {["x"] = 8, ["y"] = 2, ["param1"] = 30, ["z"] = 13, ["name"] = "default:silver_sandstone_block"}, {["x"] = 8, ["y"] = 3, ["param1"] = 90, ["z"] = 3, ["name"] = "default:goldblock"}, {["x"] = 8, ["y"] = 3, ["param1"] = 30, ["z"] = 14, ["name"] = "default:silver_sandstone_block"}, {["x"] = 8, ["y"] = 4, ["param1"] = 90, ["z"] = 3, ["name"] = "default:goldblock"}, {["x"] = 8, ["y"] = 4, ["param1"] = 30, ["z"] = 14, ["name"] = "default:silver_sandstone_block"}, {["x"] = 8, ["y"] = 5, ["param1"] = 90, ["z"] = 3, ["name"] = "default:goldblock"}, {["x"] = 8, ["y"] = 5, ["param1"] = 30, ["z"] = 15, ["name"] = "default:silver_sandstone_block"}, {["x"] = 8, ["y"] = 6, ["param1"] = 30, ["z"] = 15, ["name"] = "default:silver_sandstone_block"}, {["x"] = 8, ["y"] = 7, ["param1"] = 30, ["z"] = 15, ["name"] = "default:silver_sandstone_block"}, {["x"] = 8, ["y"] = 8, ["param1"] = 30, ["z"] = 15, ["name"] = "default:silver_sandstone_block"}, {["x"] = 8, ["y"] = 9, ["param1"] = 30, ["z"] = 15, ["name"] = "default:silver_sandstone_block"}, {["x"] = 8, ["y"] = 10, ["param1"] = 30, ["z"] = 15, ["name"] = "default:silver_sandstone_block"}, {["x"] = 8, ["y"] = 11, ["param1"] = 30, ["z"] = 15, ["name"] = "default:silver_sandstone_block"}, {["x"] = 8, ["y"] = 12, ["param1"] = 30, ["z"] = 15, ["name"] = "default:silver_sandstone_block"}, {["x"] = 8, ["y"] = 13, ["param1"] = 30, ["z"] = 15, ["name"] = "default:silver_sandstone_block"}, {["x"] = 8, ["y"] = 14, ["param1"] = 30, ["z"] = 15, ["name"] = "default:silver_sandstone_block"}, {["x"] = 8, ["y"] = 15, ["param1"] = 30, ["z"] = 15, ["name"] = "default:silver_sandstone_block"}, {["x"] = 8, ["y"] = 16, ["param1"] = 30, ["z"] = 15, ["name"] = "default:silver_sandstone_block"}, {["x"] = 8, ["y"] = 17, ["param1"] = 30, ["z"] = 15, ["name"] = "default:silver_sandstone_block"}, {["x"] = 8, ["y"] = 18, ["param1"] = 30, ["z"] = 15, ["name"] = "default:silver_sandstone_block"}, {["x"] = 8, ["y"] = 19, ["param1"] = 30, ["z"] = 15, ["name"] = "default:silver_sandstone_block"}, {["x"] = 8, ["y"] = 20, ["param1"] = 30, ["z"] = 15, ["name"] = "default:silver_sandstone_block"}, {["x"] = 8, ["y"] = 21, ["param1"] = 30, ["z"] = 15, ["name"] = "default:silver_sandstone_block"}, {["x"] = 8, ["y"] = 22, ["param1"] = 30, ["z"] = 15, ["name"] = "default:silver_sandstone_block"}, {["x"] = 8, ["y"] = 23, ["param1"] = 30, ["z"] = 15, ["name"] = "default:silver_sandstone_block"}, {["x"] = 8, ["y"] = 24, ["param1"] = 30, ["z"] = 3, ["name"] = "default:silver_sandstone_block"}, {["x"] = 8, ["y"] = 24, ["param1"] = 30, ["z"] = 14, ["name"] = "default:silver_sandstone_block"}, {["x"] = 8, ["y"] = 25, ["param1"] = 30, ["z"] = 4, ["name"] = "default:silver_sandstone_block"}, {["x"] = 8, ["y"] = 25, ["param1"] = 30, ["z"] = 13, ["name"] = "default:silver_sandstone_block"}, {["x"] = 8, ["y"] = 26, ["param1"] = 30, ["z"] = 5, ["name"] = "default:silver_sandstone_block"}, {["x"] = 8, ["y"] = 26, ["param1"] = 30, ["z"] = 12, ["name"] = "default:silver_sandstone_block"}, {["x"] = 8, ["y"] = 27, ["param1"] = 30, ["z"] = 6, ["name"] = "default:silver_sandstone_block"}, {["x"] = 8, ["y"] = 27, ["param1"] = 30, ["z"] = 7, ["name"] = "default:silver_sandstone_block"}, {["x"] = 8, ["y"] = 27, ["param1"] = 30, ["z"] = 8, ["name"] = "default:silver_sandstone_block"}, {["x"] = 8, ["y"] = 27, ["param1"] = 30, ["z"] = 9, ["name"] = "default:silver_sandstone_block"}, {["x"] = 8, ["y"] = 27, ["param1"] = 30, ["z"] = 10, ["name"] = "default:silver_sandstone_block"}, {["x"] = 8, ["y"] = 27, ["param1"] = 30, ["z"] = 11, ["name"] = "default:silver_sandstone_block"}, {["x"] = 8, ["y"] = 28, ["param1"] = 30, ["z"] = 7, ["name"] = "default:silver_sandstone_block"}, {["x"] = 8, ["y"] = 28, ["param1"] = 30, ["z"] = 8, ["name"] = "default:silver_sandstone_block"}, {["x"] = 8, ["y"] = 28, ["param1"] = 30, ["z"] = 9, ["name"] = "default:silver_sandstone_block"}, {["x"] = 8, ["y"] = 28, ["param1"] = 30, ["z"] = 10, ["name"] = "default:silver_sandstone_block"}, {["x"] = 8, ["y"] = 29, ["param1"] = 30, ["z"] = 8, ["name"] = "default:silver_sandstone_block"}, {["x"] = 8, ["y"] = 29, ["param1"] = 30, ["z"] = 9, ["name"] = "default:silver_sandstone_block"}, {["x"] = 8, ["y"] = 30, ["param1"] = 30, ["z"] = 8, ["name"] = "default:silver_sandstone_block"}, {["x"] = 8, ["y"] = 30, ["param1"] = 30, ["z"] = 9, ["name"] = "default:silver_sandstone_block"}, {["x"] = 8, ["y"] = 31, ["param1"] = 30, ["z"] = 8, ["name"] = "default:silver_sandstone_block"}, {["x"] = 8, ["y"] = 31, ["param1"] = 30, ["z"] = 9, ["name"] = "default:silver_sandstone_block"}, {["x"] = 8, ["y"] = 32, ["param1"] = 30, ["z"] = 8, ["name"] = "default:silver_sandstone_block"}, {["x"] = 8, ["y"] = 32, ["param1"] = 30, ["z"] = 9, ["name"] = "default:silver_sandstone_block"}, {["x"] = 8, ["y"] = 33, ["param1"] = 30, ["z"] = 8, ["name"] = "default:silver_sandstone_block"}, {["x"] = 8, ["y"] = 33, ["param1"] = 30, ["z"] = 9, ["name"] = "default:silver_sandstone_block"}, {["x"] = 8, ["y"] = 34, ["param1"] = 30, ["z"] = 8, ["name"] = "default:silver_sandstone_block"}, {["x"] = 8, ["y"] = 34, ["param1"] = 30, ["z"] = 9, ["name"] = "default:silver_sandstone_block"}, {["x"] = 8, ["y"] = 35, ["param1"] = 30, ["z"] = 8, ["name"] = "default:silver_sandstone_block"}, {["x"] = 8, ["y"] = 35, ["param1"] = 30, ["z"] = 9, ["name"] = "default:silver_sandstone_block"}, {["x"] = 8, ["y"] = 36, ["param1"] = 30, ["z"] = 8, ["name"] = "default:silver_sandstone_block"}, {["x"] = 8, ["y"] = 36, ["param1"] = 30, ["z"] = 9, ["name"] = "default:silver_sandstone_block"}, {["x"] = 8, ["y"] = 37, ["param1"] = 30, ["z"] = 8, ["name"] = "default:silver_sandstone_block"}, {["x"] = 8, ["y"] = 37, ["param1"] = 30, ["z"] = 9, ["name"] = "default:silver_sandstone_block"}, {["x"] = 8, ["y"] = 38, ["param1"] = 30, ["z"] = 8, ["name"] = "default:silver_sandstone_block"}, {["x"] = 8, ["y"] = 38, ["param1"] = 30, ["z"] = 9, ["name"] = "default:silver_sandstone_block"}, {["x"] = 8, ["y"] = 39, ["param1"] = 30, ["z"] = 8, ["name"] = "default:silver_sandstone_block"}, {["x"] = 8, ["y"] = 39, ["param1"] = 30, ["z"] = 9, ["name"] = "default:silver_sandstone_block"}, {["x"] = 8, ["y"] = 40, ["param1"] = 30, ["z"] = 8, ["name"] = "default:silver_sandstone_block"}, {["x"] = 8, ["y"] = 40, ["param1"] = 30, ["z"] = 9, ["name"] = "default:silver_sandstone_block"}, {["x"] = 8, ["y"] = 41, ["param1"] = 30, ["z"] = 8, ["name"] = "default:silver_sandstone_block"}, {["x"] = 8, ["y"] = 41, ["param1"] = 30, ["z"] = 9, ["name"] = "default:silver_sandstone_block"}, {["x"] = 8, ["y"] = 42, ["param1"] = 30, ["z"] = 8, ["name"] = "default:silver_sandstone_block"}, {["x"] = 8, ["y"] = 42, ["param1"] = 30, ["z"] = 9, ["name"] = "default:silver_sandstone_block"}, {["x"] = 8, ["y"] = 43, ["param1"] = 87, ["z"] = 4, ["name"] = "wool:dark_grey"}, {["x"] = 8, ["y"] = 43, ["param1"] = 30, ["z"] = 8, ["name"] = "default:silver_sandstone_block"}, {["x"] = 8, ["y"] = 43, ["param1"] = 30, ["z"] = 9, ["name"] = "default:silver_sandstone_block"}, {["x"] = 8, ["y"] = 43, ["param1"] = 87, ["z"] = 13, ["name"] = "wool:dark_grey"}, {["x"] = 8, ["y"] = 44, ["param1"] = 87, ["z"] = 3, ["name"] = "wool:dark_grey"}, {["x"] = 8, ["y"] = 44, ["param1"] = 87, ["z"] = 4, ["name"] = "wool:dark_grey"}, {["x"] = 8, ["y"] = 44, ["param1"] = 87, ["z"] = 5, ["name"] = "wool:dark_grey"}, {["x"] = 8, ["y"] = 44, ["param1"] = 30, ["z"] = 8, ["name"] = "default:silver_sandstone_block"}, {["x"] = 8, ["y"] = 44, ["param1"] = 30, ["z"] = 9, ["name"] = "default:silver_sandstone_block"}, {["x"] = 8, ["y"] = 44, ["param1"] = 87, ["z"] = 12, ["name"] = "wool:dark_grey"}, {["x"] = 8, ["y"] = 44, ["param1"] = 87, ["z"] = 13, ["name"] = "wool:dark_grey"}, {["x"] = 8, ["y"] = 44, ["param1"] = 87, ["z"] = 14, ["name"] = "wool:dark_grey"}, {["x"] = 8, ["y"] = 45, ["param1"] = 87, ["z"] = 2, ["name"] = "wool:dark_grey"}, {["x"] = 8, ["y"] = 45, ["param1"] = 87, ["z"] = 3, ["name"] = "wool:dark_grey"}, {["x"] = 8, ["y"] = 45, ["param1"] = 90, ["z"] = 4, ["name"] = "default:goldblock"}, {["x"] = 8, ["y"] = 45, ["param1"] = 87, ["z"] = 5, ["name"] = "wool:dark_grey"}, {["x"] = 8, ["y"] = 45, ["param1"] = 87, ["z"] = 6, ["name"] = "wool:dark_grey"}, {["x"] = 8, ["y"] = 45, ["param1"] = 30, ["z"] = 8, ["name"] = "default:silver_sandstone_block"}, {["x"] = 8, ["y"] = 45, ["param1"] = 30, ["z"] = 9, ["name"] = "default:silver_sandstone_block"}, {["x"] = 8, ["y"] = 45, ["param1"] = 87, ["z"] = 11, ["name"] = "wool:dark_grey"}, {["x"] = 8, ["y"] = 45, ["param1"] = 87, ["z"] = 12, ["name"] = "wool:dark_grey"}, {["x"] = 8, ["y"] = 45, ["param1"] = 90, ["z"] = 13, ["name"] = "default:goldblock"}, {["x"] = 8, ["y"] = 45, ["param1"] = 87, ["z"] = 14, ["name"] = "wool:dark_grey"}, {["x"] = 8, ["y"] = 45, ["param1"] = 87, ["z"] = 15, ["name"] = "wool:dark_grey"}, {["x"] = 8, ["y"] = 46, ["param1"] = 87, ["z"] = 4, ["name"] = "wool:dark_grey"}, {["x"] = 8, ["y"] = 46, ["param1"] = 87, ["z"] = 5, ["name"] = "wool:dark_grey"}, {["x"] = 8, ["y"] = 46, ["param1"] = 87, ["z"] = 6, ["name"] = "wool:dark_grey"}, {["x"] = 8, ["y"] = 46, ["param1"] = 87, ["z"] = 13, ["name"] = "wool:dark_grey"}, {["x"] = 8, ["y"] = 46, ["param1"] = 87, ["z"] = 14, ["name"] = "wool:dark_grey"}, {["x"] = 8, ["y"] = 46, ["param1"] = 87, ["z"] = 15, ["name"] = "wool:dark_grey"}, {["x"] = 8, ["y"] = 47, ["param1"] = 87, ["z"] = 5, ["name"] = "wool:dark_grey"}, {["x"] = 8, ["y"] = 47, ["param1"] = 87, ["z"] = 14, ["name"] = "wool:dark_grey"}, {["x"] = 9, ["y"] = 0, ["param1"] = 30, ["z"] = 3, ["name"] = "default:silver_sandstone_block"}, {["x"] = 9, ["y"] = 0, ["param1"] = 30, ["z"] = 4, ["name"] = "default:silver_sandstone_block"}, {["x"] = 9, ["y"] = 0, ["param1"] = 30, ["z"] = 5, ["name"] = "default:silver_sandstone_block"}, {["x"] = 9, ["y"] = 0, ["param1"] = 30, ["z"] = 6, ["name"] = "default:silver_sandstone_block"}, {["x"] = 9, ["y"] = 0, ["param1"] = 30, ["z"] = 7, ["name"] = "default:silver_sandstone_block"}, {["x"] = 9, ["y"] = 0, ["param1"] = 30, ["z"] = 8, ["name"] = "default:silver_sandstone_block"}, {["x"] = 9, ["y"] = 0, ["param1"] = 30, ["z"] = 9, ["name"] = "default:silver_sandstone_block"}, {["x"] = 9, ["y"] = 0, ["param1"] = 30, ["z"] = 10, ["name"] = "default:silver_sandstone_block"}, {["x"] = 9, ["y"] = 0, ["param1"] = 30, ["z"] = 11, ["name"] = "default:silver_sandstone_block"}, {["x"] = 9, ["y"] = 0, ["param1"] = 30, ["z"] = 12, ["name"] = "default:silver_sandstone_block"}, {["x"] = 9, ["y"] = 1, ["param1"] = 30, ["z"] = 13, ["name"] = "default:silver_sandstone_block"}, {["x"] = 9, ["y"] = 2, ["param1"] = 30, ["z"] = 13, ["name"] = "default:silver_sandstone_block"}, {["x"] = 9, ["y"] = 3, ["param1"] = 90, ["z"] = 3, ["name"] = "default:goldblock"}, {["x"] = 9, ["y"] = 3, ["param1"] = 30, ["z"] = 14, ["name"] = "default:silver_sandstone_block"}, {["x"] = 9, ["y"] = 4, ["param1"] = 90, ["z"] = 3, ["name"] = "default:goldblock"}, {["x"] = 9, ["y"] = 4, ["param1"] = 30, ["z"] = 14, ["name"] = "default:silver_sandstone_block"}, {["x"] = 9, ["y"] = 5, ["param1"] = 90, ["z"] = 3, ["name"] = "default:goldblock"}, {["x"] = 9, ["y"] = 5, ["param1"] = 30, ["z"] = 15, ["name"] = "default:silver_sandstone_block"}, {["x"] = 9, ["y"] = 6, ["param1"] = 30, ["z"] = 15, ["name"] = "default:silver_sandstone_block"}, {["x"] = 9, ["y"] = 7, ["param1"] = 30, ["z"] = 15, ["name"] = "default:silver_sandstone_block"}, {["x"] = 9, ["y"] = 8, ["param1"] = 30, ["z"] = 15, ["name"] = "default:silver_sandstone_block"}, {["x"] = 9, ["y"] = 9, ["param1"] = 30, ["z"] = 15, ["name"] = "default:silver_sandstone_block"}, {["x"] = 9, ["y"] = 10, ["param1"] = 30, ["z"] = 15, ["name"] = "default:silver_sandstone_block"}, {["x"] = 9, ["y"] = 11, ["param1"] = 30, ["z"] = 15, ["name"] = "default:silver_sandstone_block"}, {["x"] = 9, ["y"] = 12, ["param1"] = 30, ["z"] = 15, ["name"] = "default:silver_sandstone_block"}, {["x"] = 9, ["y"] = 13, ["param1"] = 30, ["z"] = 15, ["name"] = "default:silver_sandstone_block"}, {["x"] = 9, ["y"] = 14, ["param1"] = 30, ["z"] = 15, ["name"] = "default:silver_sandstone_block"}, {["x"] = 9, ["y"] = 15, ["param1"] = 30, ["z"] = 15, ["name"] = "default:silver_sandstone_block"}, {["x"] = 9, ["y"] = 16, ["param1"] = 30, ["z"] = 15, ["name"] = "default:silver_sandstone_block"}, {["x"] = 9, ["y"] = 17, ["param1"] = 30, ["z"] = 15, ["name"] = "default:silver_sandstone_block"}, {["x"] = 9, ["y"] = 18, ["param1"] = 30, ["z"] = 15, ["name"] = "default:silver_sandstone_block"}, {["x"] = 9, ["y"] = 19, ["param1"] = 30, ["z"] = 15, ["name"] = "default:silver_sandstone_block"}, {["x"] = 9, ["y"] = 20, ["param1"] = 30, ["z"] = 15, ["name"] = "default:silver_sandstone_block"}, {["x"] = 9, ["y"] = 21, ["param1"] = 30, ["z"] = 15, ["name"] = "default:silver_sandstone_block"}, {["x"] = 9, ["y"] = 22, ["param1"] = 30, ["z"] = 15, ["name"] = "default:silver_sandstone_block"}, {["x"] = 9, ["y"] = 23, ["param1"] = 30, ["z"] = 15, ["name"] = "default:silver_sandstone_block"}, {["x"] = 9, ["y"] = 24, ["param1"] = 30, ["z"] = 3, ["name"] = "default:silver_sandstone_block"}, {["x"] = 9, ["y"] = 24, ["param1"] = 30, ["z"] = 14, ["name"] = "default:silver_sandstone_block"}, {["x"] = 9, ["y"] = 25, ["param1"] = 30, ["z"] = 4, ["name"] = "default:silver_sandstone_block"}, {["x"] = 9, ["y"] = 25, ["param1"] = 30, ["z"] = 13, ["name"] = "default:silver_sandstone_block"}, {["x"] = 9, ["y"] = 26, ["param1"] = 30, ["z"] = 5, ["name"] = "default:silver_sandstone_block"}, {["x"] = 9, ["y"] = 26, ["param1"] = 30, ["z"] = 12, ["name"] = "default:silver_sandstone_block"}, {["x"] = 9, ["y"] = 27, ["param1"] = 30, ["z"] = 6, ["name"] = "default:silver_sandstone_block"}, {["x"] = 9, ["y"] = 27, ["param1"] = 30, ["z"] = 7, ["name"] = "default:silver_sandstone_block"}, {["x"] = 9, ["y"] = 27, ["param1"] = 30, ["z"] = 8, ["name"] = "default:silver_sandstone_block"}, {["x"] = 9, ["y"] = 27, ["param1"] = 30, ["z"] = 9, ["name"] = "default:silver_sandstone_block"}, {["x"] = 9, ["y"] = 27, ["param1"] = 30, ["z"] = 10, ["name"] = "default:silver_sandstone_block"}, {["x"] = 9, ["y"] = 27, ["param1"] = 30, ["z"] = 11, ["name"] = "default:silver_sandstone_block"}, {["x"] = 9, ["y"] = 28, ["param1"] = 30, ["z"] = 7, ["name"] = "default:silver_sandstone_block"}, {["x"] = 9, ["y"] = 28, ["param1"] = 30, ["z"] = 8, ["name"] = "default:silver_sandstone_block"}, {["x"] = 9, ["y"] = 28, ["param1"] = 30, ["z"] = 9, ["name"] = "default:silver_sandstone_block"}, {["x"] = 9, ["y"] = 28, ["param1"] = 30, ["z"] = 10, ["name"] = "default:silver_sandstone_block"}, {["x"] = 9, ["y"] = 44, ["param1"] = 33, ["z"] = 3, ["name"] = "default:obsidian_block"}, {["x"] = 9, ["y"] = 44, ["param1"] = 33, ["z"] = 4, ["name"] = "default:obsidian_block"}, {["x"] = 9, ["y"] = 44, ["param1"] = 33, ["z"] = 5, ["name"] = "default:obsidian_block"}, {["x"] = 9, ["y"] = 44, ["param1"] = 33, ["z"] = 6, ["name"] = "default:obsidian_block"}, {["x"] = 9, ["y"] = 44, ["param1"] = 33, ["z"] = 7, ["name"] = "default:obsidian_block"}, {["x"] = 9, ["y"] = 44, ["param1"] = 33, ["z"] = 8, ["name"] = "default:obsidian_block"}, {["x"] = 9, ["y"] = 44, ["param1"] = 33, ["z"] = 9, ["name"] = "default:obsidian_block"}, {["x"] = 9, ["y"] = 44, ["param1"] = 33, ["z"] = 10, ["name"] = "default:obsidian_block"}, {["x"] = 9, ["y"] = 44, ["param1"] = 33, ["z"] = 11, ["name"] = "default:obsidian_block"}, {["x"] = 9, ["y"] = 44, ["param1"] = 33, ["z"] = 12, ["name"] = "default:obsidian_block"}, {["x"] = 9, ["y"] = 44, ["param1"] = 33, ["z"] = 13, ["name"] = "default:obsidian_block"}, {["x"] = 9, ["y"] = 44, ["param1"] = 33, ["z"] = 14, ["name"] = "default:obsidian_block"}, {["x"] = 9, ["y"] = 45, ["param1"] = 33, ["z"] = 3, ["name"] = "default:obsidian_block"}, {["x"] = 9, ["y"] = 45, ["param1"] = 33, ["z"] = 4, ["name"] = "default:obsidian_block"}, {["x"] = 9, ["y"] = 45, ["param1"] = 33, ["z"] = 5, ["name"] = "default:obsidian_block"}, {["x"] = 9, ["y"] = 45, ["param1"] = 33, ["z"] = 6, ["name"] = "default:obsidian_block"}, {["x"] = 9, ["y"] = 45, ["param1"] = 33, ["z"] = 7, ["name"] = "default:obsidian_block"}, {["x"] = 9, ["y"] = 45, ["param1"] = 33, ["z"] = 8, ["name"] = "default:obsidian_block"}, {["x"] = 9, ["y"] = 45, ["param1"] = 33, ["z"] = 9, ["name"] = "default:obsidian_block"}, {["x"] = 9, ["y"] = 45, ["param1"] = 33, ["z"] = 10, ["name"] = "default:obsidian_block"}, {["x"] = 9, ["y"] = 45, ["param1"] = 33, ["z"] = 11, ["name"] = "default:obsidian_block"}, {["x"] = 9, ["y"] = 45, ["param1"] = 33, ["z"] = 12, ["name"] = "default:obsidian_block"}, {["x"] = 9, ["y"] = 45, ["param1"] = 33, ["z"] = 13, ["name"] = "default:obsidian_block"}, {["x"] = 9, ["y"] = 45, ["param1"] = 33, ["z"] = 14, ["name"] = "default:obsidian_block"}, {["x"] = 9, ["y"] = 46, ["param1"] = 33, ["z"] = 4, ["name"] = "default:obsidian_block"}, {["x"] = 9, ["y"] = 46, ["param1"] = 33, ["z"] = 5, ["name"] = "default:obsidian_block"}, {["x"] = 9, ["y"] = 46, ["param1"] = 33, ["z"] = 6, ["name"] = "default:obsidian_block"}, {["x"] = 9, ["y"] = 46, ["param1"] = 33, ["z"] = 7, ["name"] = "default:obsidian_block"}, {["x"] = 9, ["y"] = 46, ["param1"] = 33, ["z"] = 8, ["name"] = "default:obsidian_block"}, {["x"] = 9, ["y"] = 46, ["param1"] = 33, ["z"] = 9, ["name"] = "default:obsidian_block"}, {["x"] = 9, ["y"] = 46, ["param1"] = 33, ["z"] = 10, ["name"] = "default:obsidian_block"}, {["x"] = 9, ["y"] = 46, ["param1"] = 33, ["z"] = 11, ["name"] = "default:obsidian_block"}, {["x"] = 9, ["y"] = 46, ["param1"] = 33, ["z"] = 12, ["name"] = "default:obsidian_block"}, {["x"] = 9, ["y"] = 46, ["param1"] = 33, ["z"] = 13, ["name"] = "default:obsidian_block"}, {["x"] = 9, ["y"] = 46, ["param1"] = 33, ["z"] = 14, ["name"] = "default:obsidian_block"}, {["x"] = 9, ["y"] = 46, ["param1"] = 33, ["z"] = 15, ["name"] = "default:obsidian_block"}, {["x"] = 10, ["y"] = 0, ["param1"] = 30, ["z"] = 3, ["name"] = "default:silver_sandstone_block"}, {["x"] = 10, ["y"] = 0, ["param1"] = 30, ["z"] = 4, ["name"] = "default:silver_sandstone_block"}, {["x"] = 10, ["y"] = 0, ["param1"] = 30, ["z"] = 5, ["name"] = "default:silver_sandstone_block"}, {["x"] = 10, ["y"] = 0, ["param1"] = 30, ["z"] = 6, ["name"] = "default:silver_sandstone_block"}, {["x"] = 10, ["y"] = 0, ["param1"] = 30, ["z"] = 7, ["name"] = "default:silver_sandstone_block"}, {["x"] = 10, ["y"] = 0, ["param1"] = 30, ["z"] = 8, ["name"] = "default:silver_sandstone_block"}, {["x"] = 10, ["y"] = 0, ["param1"] = 30, ["z"] = 9, ["name"] = "default:silver_sandstone_block"}, {["x"] = 10, ["y"] = 0, ["param1"] = 30, ["z"] = 10, ["name"] = "default:silver_sandstone_block"}, {["x"] = 10, ["y"] = 0, ["param1"] = 30, ["z"] = 11, ["name"] = "default:silver_sandstone_block"}, {["x"] = 10, ["y"] = 0, ["param1"] = 30, ["z"] = 12, ["name"] = "default:silver_sandstone_block"}, {["x"] = 10, ["y"] = 1, ["param1"] = 30, ["z"] = 13, ["name"] = "default:silver_sandstone_block"}, {["x"] = 10, ["y"] = 2, ["param1"] = 30, ["z"] = 13, ["name"] = "default:silver_sandstone_block"}, {["x"] = 10, ["y"] = 3, ["param1"] = 90, ["z"] = 3, ["name"] = "default:goldblock"}, {["x"] = 10, ["y"] = 3, ["param1"] = 30, ["z"] = 14, ["name"] = "default:silver_sandstone_block"}, {["x"] = 10, ["y"] = 4, ["param1"] = 90, ["z"] = 3, ["name"] = "default:goldblock"}, {["x"] = 10, ["y"] = 4, ["param1"] = 30, ["z"] = 14, ["name"] = "default:silver_sandstone_block"}, {["x"] = 10, ["y"] = 5, ["param1"] = 90, ["z"] = 3, ["name"] = "default:goldblock"}, {["x"] = 10, ["y"] = 5, ["param1"] = 30, ["z"] = 15, ["name"] = "default:silver_sandstone_block"}, {["x"] = 10, ["y"] = 6, ["param1"] = 30, ["z"] = 15, ["name"] = "default:silver_sandstone_block"}, {["x"] = 10, ["y"] = 7, ["param1"] = 30, ["z"] = 15, ["name"] = "default:silver_sandstone_block"}, {["x"] = 10, ["y"] = 8, ["param1"] = 30, ["z"] = 15, ["name"] = "default:silver_sandstone_block"}, {["x"] = 10, ["y"] = 9, ["param1"] = 30, ["z"] = 15, ["name"] = "default:silver_sandstone_block"}, {["x"] = 10, ["y"] = 10, ["param1"] = 30, ["z"] = 15, ["name"] = "default:silver_sandstone_block"}, {["x"] = 10, ["y"] = 11, ["param1"] = 30, ["z"] = 15, ["name"] = "default:silver_sandstone_block"}, {["x"] = 10, ["y"] = 12, ["param1"] = 30, ["z"] = 15, ["name"] = "default:silver_sandstone_block"}, {["x"] = 10, ["y"] = 13, ["param1"] = 30, ["z"] = 15, ["name"] = "default:silver_sandstone_block"}, {["x"] = 10, ["y"] = 14, ["param1"] = 30, ["z"] = 15, ["name"] = "default:silver_sandstone_block"}, {["x"] = 10, ["y"] = 15, ["param1"] = 30, ["z"] = 15, ["name"] = "default:silver_sandstone_block"}, {["x"] = 10, ["y"] = 16, ["param1"] = 30, ["z"] = 15, ["name"] = "default:silver_sandstone_block"}, {["x"] = 10, ["y"] = 17, ["param1"] = 30, ["z"] = 15, ["name"] = "default:silver_sandstone_block"}, {["x"] = 10, ["y"] = 18, ["param1"] = 30, ["z"] = 15, ["name"] = "default:silver_sandstone_block"}, {["x"] = 10, ["y"] = 19, ["param1"] = 30, ["z"] = 15, ["name"] = "default:silver_sandstone_block"}, {["x"] = 10, ["y"] = 20, ["param1"] = 30, ["z"] = 15, ["name"] = "default:silver_sandstone_block"}, {["x"] = 10, ["y"] = 21, ["param1"] = 30, ["z"] = 15, ["name"] = "default:silver_sandstone_block"}, {["x"] = 10, ["y"] = 22, ["param1"] = 30, ["z"] = 15, ["name"] = "default:silver_sandstone_block"}, {["x"] = 10, ["y"] = 23, ["param1"] = 30, ["z"] = 15, ["name"] = "default:silver_sandstone_block"}, {["x"] = 10, ["y"] = 24, ["param1"] = 30, ["z"] = 3, ["name"] = "default:silver_sandstone_block"}, {["x"] = 10, ["y"] = 24, ["param1"] = 30, ["z"] = 14, ["name"] = "default:silver_sandstone_block"}, {["x"] = 10, ["y"] = 25, ["param1"] = 30, ["z"] = 4, ["name"] = "default:silver_sandstone_block"}, {["x"] = 10, ["y"] = 25, ["param1"] = 30, ["z"] = 13, ["name"] = "default:silver_sandstone_block"}, {["x"] = 10, ["y"] = 26, ["param1"] = 30, ["z"] = 5, ["name"] = "default:silver_sandstone_block"}, {["x"] = 10, ["y"] = 26, ["param1"] = 30, ["z"] = 12, ["name"] = "default:silver_sandstone_block"}, {["x"] = 10, ["y"] = 27, ["param1"] = 30, ["z"] = 6, ["name"] = "default:silver_sandstone_block"}, {["x"] = 10, ["y"] = 27, ["param1"] = 30, ["z"] = 7, ["name"] = "default:silver_sandstone_block"}, {["x"] = 10, ["y"] = 27, ["param1"] = 30, ["z"] = 8, ["name"] = "default:silver_sandstone_block"}, {["x"] = 10, ["y"] = 27, ["param1"] = 30, ["z"] = 9, ["name"] = "default:silver_sandstone_block"}, {["x"] = 10, ["y"] = 27, ["param1"] = 30, ["z"] = 10, ["name"] = "default:silver_sandstone_block"}, {["x"] = 10, ["y"] = 27, ["param1"] = 30, ["z"] = 11, ["name"] = "default:silver_sandstone_block"}, {["x"] = 10, ["y"] = 46, ["param1"] = 33, ["z"] = 4, ["name"] = "default:obsidian_block"}, {["x"] = 10, ["y"] = 46, ["param1"] = 33, ["z"] = 5, ["name"] = "default:obsidian_block"}, {["x"] = 10, ["y"] = 46, ["param1"] = 33, ["z"] = 6, ["name"] = "default:obsidian_block"}, {["x"] = 10, ["y"] = 46, ["param1"] = 33, ["z"] = 7, ["name"] = "default:obsidian_block"}, {["x"] = 10, ["y"] = 46, ["param1"] = 33, ["z"] = 8, ["name"] = "default:obsidian_block"}, {["x"] = 10, ["y"] = 46, ["param1"] = 33, ["z"] = 9, ["name"] = "default:obsidian_block"}, {["x"] = 10, ["y"] = 46, ["param1"] = 33, ["z"] = 10, ["name"] = "default:obsidian_block"}, {["x"] = 10, ["y"] = 46, ["param1"] = 33, ["z"] = 11, ["name"] = "default:obsidian_block"}, {["x"] = 10, ["y"] = 46, ["param1"] = 33, ["z"] = 12, ["name"] = "default:obsidian_block"}, {["x"] = 10, ["y"] = 46, ["param1"] = 33, ["z"] = 13, ["name"] = "default:obsidian_block"}, {["x"] = 10, ["y"] = 46, ["param1"] = 33, ["z"] = 14, ["name"] = "default:obsidian_block"}, {["x"] = 10, ["y"] = 46, ["param1"] = 33, ["z"] = 15, ["name"] = "default:obsidian_block"}, {["x"] = 11, ["y"] = 0, ["param1"] = 30, ["z"] = 3, ["name"] = "default:silver_sandstone_block"}, {["x"] = 11, ["y"] = 0, ["param1"] = 30, ["z"] = 4, ["name"] = "default:silver_sandstone_block"}, {["x"] = 11, ["y"] = 0, ["param1"] = 30, ["z"] = 5, ["name"] = "default:silver_sandstone_block"}, {["x"] = 11, ["y"] = 0, ["param1"] = 30, ["z"] = 6, ["name"] = "default:silver_sandstone_block"}, {["x"] = 11, ["y"] = 0, ["param1"] = 30, ["z"] = 7, ["name"] = "default:silver_sandstone_block"}, {["x"] = 11, ["y"] = 0, ["param1"] = 30, ["z"] = 8, ["name"] = "default:silver_sandstone_block"}, {["x"] = 11, ["y"] = 0, ["param1"] = 30, ["z"] = 9, ["name"] = "default:silver_sandstone_block"}, {["x"] = 11, ["y"] = 0, ["param1"] = 30, ["z"] = 10, ["name"] = "default:silver_sandstone_block"}, {["x"] = 11, ["y"] = 0, ["param1"] = 30, ["z"] = 11, ["name"] = "default:silver_sandstone_block"}, {["x"] = 11, ["y"] = 0, ["param1"] = 30, ["z"] = 12, ["name"] = "default:silver_sandstone_block"}, {["x"] = 11, ["y"] = 1, ["param1"] = 30, ["z"] = 13, ["name"] = "default:silver_sandstone_block"}, {["x"] = 11, ["y"] = 2, ["param1"] = 30, ["z"] = 13, ["name"] = "default:silver_sandstone_block"}, {["x"] = 11, ["y"] = 3, ["param1"] = 90, ["z"] = 3, ["name"] = "default:goldblock"}, {["x"] = 11, ["y"] = 3, ["param1"] = 30, ["z"] = 14, ["name"] = "default:silver_sandstone_block"}, {["x"] = 11, ["y"] = 4, ["param1"] = 90, ["z"] = 3, ["name"] = "default:goldblock"}, {["x"] = 11, ["y"] = 4, ["param1"] = 30, ["z"] = 14, ["name"] = "default:silver_sandstone_block"}, {["x"] = 11, ["y"] = 5, ["param1"] = 90, ["z"] = 3, ["name"] = "default:goldblock"}, {["x"] = 11, ["y"] = 5, ["param1"] = 30, ["z"] = 15, ["name"] = "default:silver_sandstone_block"}, {["x"] = 11, ["y"] = 6, ["param1"] = 30, ["z"] = 15, ["name"] = "default:silver_sandstone_block"}, {["x"] = 11, ["y"] = 7, ["param1"] = 30, ["z"] = 15, ["name"] = "default:silver_sandstone_block"}, {["x"] = 11, ["y"] = 8, ["param1"] = 30, ["z"] = 15, ["name"] = "default:silver_sandstone_block"}, {["x"] = 11, ["y"] = 9, ["param1"] = 30, ["z"] = 15, ["name"] = "default:silver_sandstone_block"}, {["x"] = 11, ["y"] = 10, ["param1"] = 30, ["z"] = 15, ["name"] = "default:silver_sandstone_block"}, {["x"] = 11, ["y"] = 11, ["param1"] = 30, ["z"] = 15, ["name"] = "default:silver_sandstone_block"}, {["x"] = 11, ["y"] = 12, ["param1"] = 30, ["z"] = 15, ["name"] = "default:silver_sandstone_block"}, {["x"] = 11, ["y"] = 13, ["param1"] = 30, ["z"] = 15, ["name"] = "default:silver_sandstone_block"}, {["x"] = 11, ["y"] = 14, ["param1"] = 30, ["z"] = 15, ["name"] = "default:silver_sandstone_block"}, {["x"] = 11, ["y"] = 15, ["param1"] = 30, ["z"] = 15, ["name"] = "default:silver_sandstone_block"}, {["x"] = 11, ["y"] = 16, ["param1"] = 30, ["z"] = 15, ["name"] = "default:silver_sandstone_block"}, {["x"] = 11, ["y"] = 17, ["param1"] = 30, ["z"] = 15, ["name"] = "default:silver_sandstone_block"}, {["x"] = 11, ["y"] = 18, ["param1"] = 30, ["z"] = 15, ["name"] = "default:silver_sandstone_block"}, {["x"] = 11, ["y"] = 19, ["param1"] = 30, ["z"] = 15, ["name"] = "default:silver_sandstone_block"}, {["x"] = 11, ["y"] = 20, ["param1"] = 30, ["z"] = 15, ["name"] = "default:silver_sandstone_block"}, {["x"] = 11, ["y"] = 21, ["param1"] = 30, ["z"] = 15, ["name"] = "default:silver_sandstone_block"}, {["x"] = 11, ["y"] = 22, ["param1"] = 30, ["z"] = 15, ["name"] = "default:silver_sandstone_block"}, {["x"] = 11, ["y"] = 23, ["param1"] = 30, ["z"] = 15, ["name"] = "default:silver_sandstone_block"}, {["x"] = 11, ["y"] = 24, ["param1"] = 30, ["z"] = 3, ["name"] = "default:silver_sandstone_block"}, {["x"] = 11, ["y"] = 24, ["param1"] = 30, ["z"] = 14, ["name"] = "default:silver_sandstone_block"}, {["x"] = 11, ["y"] = 25, ["param1"] = 30, ["z"] = 4, ["name"] = "default:silver_sandstone_block"}, {["x"] = 11, ["y"] = 25, ["param1"] = 30, ["z"] = 13, ["name"] = "default:silver_sandstone_block"}, {["x"] = 11, ["y"] = 26, ["param1"] = 30, ["z"] = 5, ["name"] = "default:silver_sandstone_block"}, {["x"] = 11, ["y"] = 26, ["param1"] = 30, ["z"] = 12, ["name"] = "default:silver_sandstone_block"}, {["x"] = 11, ["y"] = 27, ["param1"] = 30, ["z"] = 6, ["name"] = "default:silver_sandstone_block"}, {["x"] = 11, ["y"] = 27, ["param1"] = 30, ["z"] = 7, ["name"] = "default:silver_sandstone_block"}, {["x"] = 11, ["y"] = 27, ["param1"] = 30, ["z"] = 8, ["name"] = "default:silver_sandstone_block"}, {["x"] = 11, ["y"] = 27, ["param1"] = 30, ["z"] = 9, ["name"] = "default:silver_sandstone_block"}, {["x"] = 11, ["y"] = 27, ["param1"] = 30, ["z"] = 10, ["name"] = "default:silver_sandstone_block"}, {["x"] = 11, ["y"] = 27, ["param1"] = 30, ["z"] = 11, ["name"] = "default:silver_sandstone_block"}, {["x"] = 11, ["y"] = 46, ["param1"] = 33, ["z"] = 4, ["name"] = "default:obsidian_block"}, {["x"] = 11, ["y"] = 46, ["param1"] = 33, ["z"] = 5, ["name"] = "default:obsidian_block"}, {["x"] = 11, ["y"] = 46, ["param1"] = 33, ["z"] = 6, ["name"] = "default:obsidian_block"}, {["x"] = 11, ["y"] = 46, ["param1"] = 33, ["z"] = 7, ["name"] = "default:obsidian_block"}, {["x"] = 11, ["y"] = 46, ["param1"] = 33, ["z"] = 8, ["name"] = "default:obsidian_block"}, {["x"] = 11, ["y"] = 46, ["param1"] = 33, ["z"] = 9, ["name"] = "default:obsidian_block"}, {["x"] = 11, ["y"] = 46, ["param1"] = 33, ["z"] = 10, ["name"] = "default:obsidian_block"}, {["x"] = 11, ["y"] = 46, ["param1"] = 33, ["z"] = 11, ["name"] = "default:obsidian_block"}, {["x"] = 11, ["y"] = 46, ["param1"] = 33, ["z"] = 12, ["name"] = "default:obsidian_block"}, {["x"] = 11, ["y"] = 46, ["param1"] = 33, ["z"] = 13, ["name"] = "default:obsidian_block"}, {["x"] = 11, ["y"] = 46, ["param1"] = 33, ["z"] = 14, ["name"] = "default:obsidian_block"}, {["x"] = 11, ["y"] = 46, ["param1"] = 33, ["z"] = 15, ["name"] = "default:obsidian_block"}, {["x"] = 12, ["y"] = 0, ["param1"] = 30, ["z"] = 3, ["name"] = "default:silver_sandstone_block"}, {["x"] = 12, ["y"] = 0, ["param1"] = 30, ["z"] = 4, ["name"] = "default:silver_sandstone_block"}, {["x"] = 12, ["y"] = 0, ["param1"] = 30, ["z"] = 5, ["name"] = "default:silver_sandstone_block"}, {["x"] = 12, ["y"] = 0, ["param1"] = 30, ["z"] = 6, ["name"] = "default:silver_sandstone_block"}, {["x"] = 12, ["y"] = 0, ["param1"] = 30, ["z"] = 7, ["name"] = "default:silver_sandstone_block"}, {["x"] = 12, ["y"] = 0, ["param1"] = 30, ["z"] = 8, ["name"] = "default:silver_sandstone_block"}, {["x"] = 12, ["y"] = 0, ["param1"] = 30, ["z"] = 9, ["name"] = "default:silver_sandstone_block"}, {["x"] = 12, ["y"] = 0, ["param1"] = 30, ["z"] = 10, ["name"] = "default:silver_sandstone_block"}, {["x"] = 12, ["y"] = 0, ["param1"] = 30, ["z"] = 11, ["name"] = "default:silver_sandstone_block"}, {["x"] = 12, ["y"] = 0, ["param1"] = 30, ["z"] = 12, ["name"] = "default:silver_sandstone_block"}, {["x"] = 12, ["y"] = 1, ["param1"] = 30, ["z"] = 13, ["name"] = "default:silver_sandstone_block"}, {["x"] = 12, ["y"] = 2, ["param1"] = 30, ["z"] = 13, ["name"] = "default:silver_sandstone_block"}, {["x"] = 12, ["y"] = 3, ["param1"] = 90, ["z"] = 3, ["name"] = "default:goldblock"}, {["x"] = 12, ["y"] = 3, ["param1"] = 30, ["z"] = 14, ["name"] = "default:silver_sandstone_block"}, {["x"] = 12, ["y"] = 4, ["param1"] = 90, ["z"] = 3, ["name"] = "default:goldblock"}, {["x"] = 12, ["y"] = 4, ["param1"] = 30, ["z"] = 14, ["name"] = "default:silver_sandstone_block"}, {["x"] = 12, ["y"] = 5, ["param1"] = 90, ["z"] = 3, ["name"] = "default:goldblock"}, {["x"] = 12, ["y"] = 5, ["param1"] = 30, ["z"] = 15, ["name"] = "default:silver_sandstone_block"}, {["x"] = 12, ["y"] = 6, ["param1"] = 30, ["z"] = 15, ["name"] = "default:silver_sandstone_block"}, {["x"] = 12, ["y"] = 7, ["param1"] = 30, ["z"] = 15, ["name"] = "default:silver_sandstone_block"}, {["x"] = 12, ["y"] = 8, ["param1"] = 30, ["z"] = 15, ["name"] = "default:silver_sandstone_block"}, {["x"] = 12, ["y"] = 9, ["param1"] = 30, ["z"] = 15, ["name"] = "default:silver_sandstone_block"}, {["x"] = 12, ["y"] = 10, ["param1"] = 30, ["z"] = 15, ["name"] = "default:silver_sandstone_block"}, {["x"] = 12, ["y"] = 11, ["param1"] = 30, ["z"] = 15, ["name"] = "default:silver_sandstone_block"}, {["x"] = 12, ["y"] = 12, ["param1"] = 30, ["z"] = 15, ["name"] = "default:silver_sandstone_block"}, {["x"] = 12, ["y"] = 13, ["param1"] = 30, ["z"] = 15, ["name"] = "default:silver_sandstone_block"}, {["x"] = 12, ["y"] = 14, ["param1"] = 30, ["z"] = 15, ["name"] = "default:silver_sandstone_block"}, {["x"] = 12, ["y"] = 15, ["param1"] = 30, ["z"] = 15, ["name"] = "default:silver_sandstone_block"}, {["x"] = 12, ["y"] = 16, ["param1"] = 30, ["z"] = 15, ["name"] = "default:silver_sandstone_block"}, {["x"] = 12, ["y"] = 17, ["param1"] = 30, ["z"] = 15, ["name"] = "default:silver_sandstone_block"}, {["x"] = 12, ["y"] = 18, ["param1"] = 30, ["z"] = 15, ["name"] = "default:silver_sandstone_block"}, {["x"] = 12, ["y"] = 19, ["param1"] = 30, ["z"] = 15, ["name"] = "default:silver_sandstone_block"}, {["x"] = 12, ["y"] = 20, ["param1"] = 30, ["z"] = 15, ["name"] = "default:silver_sandstone_block"}, {["x"] = 12, ["y"] = 21, ["param1"] = 30, ["z"] = 15, ["name"] = "default:silver_sandstone_block"}, {["x"] = 12, ["y"] = 22, ["param1"] = 30, ["z"] = 15, ["name"] = "default:silver_sandstone_block"}, {["x"] = 12, ["y"] = 23, ["param1"] = 30, ["z"] = 15, ["name"] = "default:silver_sandstone_block"}, {["x"] = 12, ["y"] = 24, ["param1"] = 30, ["z"] = 3, ["name"] = "default:silver_sandstone_block"}, {["x"] = 12, ["y"] = 24, ["param1"] = 30, ["z"] = 14, ["name"] = "default:silver_sandstone_block"}, {["x"] = 12, ["y"] = 25, ["param1"] = 30, ["z"] = 4, ["name"] = "default:silver_sandstone_block"}, {["x"] = 12, ["y"] = 25, ["param1"] = 30, ["z"] = 13, ["name"] = "default:silver_sandstone_block"}, {["x"] = 12, ["y"] = 26, ["param1"] = 30, ["z"] = 5, ["name"] = "default:silver_sandstone_block"}, {["x"] = 12, ["y"] = 26, ["param1"] = 30, ["z"] = 12, ["name"] = "default:silver_sandstone_block"}, {["x"] = 12, ["y"] = 27, ["param1"] = 30, ["z"] = 6, ["name"] = "default:silver_sandstone_block"}, {["x"] = 12, ["y"] = 27, ["param1"] = 30, ["z"] = 7, ["name"] = "default:silver_sandstone_block"}, {["x"] = 12, ["y"] = 27, ["param1"] = 30, ["z"] = 8, ["name"] = "default:silver_sandstone_block"}, {["x"] = 12, ["y"] = 27, ["param1"] = 30, ["z"] = 9, ["name"] = "default:silver_sandstone_block"}, {["x"] = 12, ["y"] = 27, ["param1"] = 30, ["z"] = 10, ["name"] = "default:silver_sandstone_block"}, {["x"] = 12, ["y"] = 27, ["param1"] = 30, ["z"] = 11, ["name"] = "default:silver_sandstone_block"}, {["x"] = 12, ["y"] = 44, ["param1"] = 33, ["z"] = 3, ["name"] = "default:obsidian_block"}, {["x"] = 12, ["y"] = 44, ["param1"] = 33, ["z"] = 4, ["name"] = "default:obsidian_block"}, {["x"] = 12, ["y"] = 44, ["param1"] = 33, ["z"] = 5, ["name"] = "default:obsidian_block"}, {["x"] = 12, ["y"] = 44, ["param1"] = 33, ["z"] = 6, ["name"] = "default:obsidian_block"}, {["x"] = 12, ["y"] = 44, ["param1"] = 33, ["z"] = 7, ["name"] = "default:obsidian_block"}, {["x"] = 12, ["y"] = 44, ["param1"] = 33, ["z"] = 8, ["name"] = "default:obsidian_block"}, {["x"] = 12, ["y"] = 44, ["param1"] = 33, ["z"] = 9, ["name"] = "default:obsidian_block"}, {["x"] = 12, ["y"] = 44, ["param1"] = 33, ["z"] = 10, ["name"] = "default:obsidian_block"}, {["x"] = 12, ["y"] = 44, ["param1"] = 33, ["z"] = 11, ["name"] = "default:obsidian_block"}, {["x"] = 12, ["y"] = 44, ["param1"] = 33, ["z"] = 12, ["name"] = "default:obsidian_block"}, {["x"] = 12, ["y"] = 44, ["param1"] = 33, ["z"] = 13, ["name"] = "default:obsidian_block"}, {["x"] = 12, ["y"] = 44, ["param1"] = 33, ["z"] = 14, ["name"] = "default:obsidian_block"}, {["x"] = 12, ["y"] = 45, ["param1"] = 33, ["z"] = 3, ["name"] = "default:obsidian_block"}, {["x"] = 12, ["y"] = 45, ["param1"] = 33, ["z"] = 4, ["name"] = "default:obsidian_block"}, {["x"] = 12, ["y"] = 45, ["param1"] = 33, ["z"] = 5, ["name"] = "default:obsidian_block"},