5:return {{["z"] = 3, ["param1"] = 30, ["meta"] = {["inventory"] = {}, ["fields"] = {}}, ["name"] = "default:silver_sandstone_block", ["x"] = 0, ["y"] = 0}, {["z"] = 4, ["param1"] = 30, ["meta"] = {["inventory"] = {}, ["fields"] = {}}, ["name"] = "default:silver_sandstone_block", ["x"] = 0, ["y"] = 0}, {["z"] = 5, ["param1"] = 30, ["meta"] = {["inventory"] = {}, ["fields"] = {}}, ["name"] = "default:silver_sandstone_block", ["x"] = 0, ["y"] = 0}, {["z"] = 6, ["param1"] = 30, ["meta"] = {["inventory"] = {}, ["fields"] = {}}, ["name"] = "default:silver_sandstone_block", ["x"] = 0, ["y"] = 0}, {["z"] = 7, ["param1"] = 30, ["meta"] = {["inventory"] = {}, ["fields"] = {}}, ["name"] = "default:silver_sandstone_block", ["x"] = 0, ["y"] = 0}, {["z"] = 8, ["param1"] = 30, ["meta"] = {["inventory"] = {}, ["fields"] = {}}, ["name"] = "default:silver_sandstone_block", ["x"] = 0, ["y"] = 0}, {["z"] = 9, ["param1"] = 30, ["meta"] = {["inventory"] = {}, ["fields"] = {}}, ["name"] = "default:silver_sandstone_block", ["x"] = 0, ["y"] = 0}, {["z"] = 10, ["param1"] = 30, ["meta"] = {["inventory"] = {}, ["fields"] = {}}, ["name"] = "default:silver_sandstone_block", ["x"] = 0, ["y"] = 0}, {["z"] = 11, ["param1"] = 30, ["meta"] = {["inventory"] = {}, ["fields"] = {}}, ["name"] = "default:silver_sandstone_block", ["x"] = 0, ["y"] = 0}, {["z"] = 12, ["param1"] = 30, ["meta"] = {["inventory"] = {}, ["fields"] = {}}, ["name"] = "default:silver_sandstone_block", ["x"] = 0, ["y"] = 0}, {["z"] = 3, ["param1"] = 30, ["meta"] = {["inventory"] = {}, ["fields"] = {}}, ["name"] = "default:silver_sandstone_block", ["x"] = 0, ["y"] = 1}, {["z"] = 4, ["param1"] = 30, ["meta"] = {["inventory"] = {}, ["fields"] = {}}, ["name"] = "default:silver_sandstone_block", ["x"] = 0, ["y"] = 1}, {["z"] = 5, ["param1"] = 30, ["meta"] = {["inventory"] = {}, ["fields"] = {}}, ["name"] = "default:silver_sandstone_block", ["x"] = 0, ["y"] = 1}, {["z"] = 6, ["param1"] = 30, ["meta"] = {["inventory"] = {}, ["fields"] = {}}, ["name"] = "default:silver_sandstone_block", ["x"] = 0, ["y"] = 1}, {["z"] = 7, ["param1"] = 30, ["meta"] = {["inventory"] = {}, ["fields"] = {}}, ["name"] = "default:silver_sandstone_block", ["x"] = 0, ["y"] = 1}, {["z"] = 8, ["param1"] = 30, ["meta"] = {["inventory"] = {}, ["fields"] = {}}, ["name"] = "default:silver_sandstone_block", ["x"] = 0, ["y"] = 1}, {["z"] = 9, ["param1"] = 30, ["meta"] = {["inventory"] = {}, ["fields"] = {}}, ["name"] = "default:silver_sandstone_block", ["x"] = 0, ["y"] = 1}, {["z"] = 10, ["param1"] = 30, ["meta"] = {["inventory"] = {}, ["fields"] = {}}, ["name"] = "default:silver_sandstone_block", ["x"] = 0, ["y"] = 1}, {["z"] = 11, ["param1"] = 30, ["meta"] = {["inventory"] = {}, ["fields"] = {}}, ["name"] = "default:silver_sandstone_block", ["x"] = 0, ["y"] = 1}, {["z"] = 12, ["param1"] = 30, ["meta"] = {["inventory"] = {}, ["fields"] = {}}, ["name"] = "default:silver_sandstone_block", ["x"] = 0, ["y"] = 1}, {["z"] = 13, ["param1"] = 30, ["meta"] = {["inventory"] = {}, ["fields"] = {}}, ["name"] = "default:silver_sandstone_block", ["x"] = 0, ["y"] = 1}, {["z"] = 4, ["param1"] = 30, ["meta"] = {["inventory"] = {}, ["fields"] = {}}, ["name"] = "default:silver_sandstone_block", ["x"] = 0, ["y"] = 2}, {["z"] = 5, ["param1"] = 30, ["meta"] = {["inventory"] = {}, ["fields"] = {}}, ["name"] = "default:silver_sandstone_block", ["x"] = 0, ["y"] = 2}, {["z"] = 6, ["param1"] = 30, ["meta"] = {["inventory"] = {}, ["fields"] = {}}, ["name"] = "default:silver_sandstone_block", ["x"] = 0, ["y"] = 2}, {["z"] = 7, ["param1"] = 30, ["meta"] = {["inventory"] = {}, ["fields"] = {}}, ["name"] = "default:silver_sandstone_block", ["x"] = 0, ["y"] = 2}, {["z"] = 8, ["param1"] = 30, ["meta"] = {["inventory"] = {}, ["fields"] = {}}, ["name"] = "default:silver_sandstone_block", ["x"] = 0, ["y"] = 2}, {["z"] = 9, ["param1"] = 30, ["meta"] = {["inventory"] = {}, ["fields"] = {}}, ["name"] = "default:silver_sandstone_block", ["x"] = 0, ["y"] = 2}, {["z"] = 10, ["param1"] = 30, ["meta"] = {["inventory"] = {}, ["fields"] = {}}, ["name"] = "default:silver_sandstone_block", ["x"] = 0, ["y"] = 2}, {["z"] = 11, ["param1"] = 30, ["meta"] = {["inventory"] = {}, ["fields"] = {}}, ["name"] = "default:silver_sandstone_block", ["x"] = 0, ["y"] = 2}, {["z"] = 12, ["param1"] = 30, ["meta"] = {["inventory"] = {}, ["fields"] = {}}, ["name"] = "default:silver_sandstone_block", ["x"] = 0, ["y"] = 2}, {["z"] = 13, ["param1"] = 30, ["meta"] = {["inventory"] = {}, ["fields"] = {}}, ["name"] = "default:silver_sandstone_block", ["x"] = 0, ["y"] = 2}, {["z"] = 3, ["param1"] = 90, ["meta"] = {["inventory"] = {}, ["fields"] = {}}, ["name"] = "default:goldblock", ["x"] = 0, ["y"] = 3}, {["z"] = 4, ["param1"] = 90, ["meta"] = {["inventory"] = {}, ["fields"] = {}}, ["name"] = "default:goldblock", ["x"] = 0, ["y"] = 3}, {["z"] = 5, ["param1"] = 30, ["meta"] = {["inventory"] = {}, ["fields"] = {}}, ["name"] = "default:silver_sandstone_block", ["x"] = 0, ["y"] = 3}, {["z"] = 10, ["param1"] = 30, ["meta"] = {["inventory"] = {}, ["fields"] = {}}, ["name"] = "default:silver_sandstone_block", ["x"] = 0, ["y"] = 3}, {["z"] = 13, ["param1"] = 30, ["meta"] = {["inventory"] = {}, ["fields"] = {}}, ["name"] = "default:silver_sandstone_block", ["x"] = 0, ["y"] = 3}, {["z"] = 14, ["param1"] = 30, ["meta"] = {["inventory"] = {}, ["fields"] = {}}, ["name"] = "default:silver_sandstone_block", ["x"] = 0, ["y"] = 3}, {["z"] = 3, ["param1"] = 90, ["meta"] = {["inventory"] = {}, ["fields"] = {}}, ["name"] = "default:goldblock", ["x"] = 0, ["y"] = 4}, {["z"] = 4, ["param1"] = 90, ["meta"] = {["inventory"] = {}, ["fields"] = {}}, ["name"] = "default:goldblock", ["x"] = 0, ["y"] = 4}, {["z"] = 5, ["param1"] = 30, ["meta"] = {["inventory"] = {}, ["fields"] = {}}, ["name"] = "default:silver_sandstone_block", ["x"] = 0, ["y"] = 4}, {["z"] = 10, ["param1"] = 30, ["meta"] = {["inventory"] = {}, ["fields"] = {}}, ["name"] = "default:silver_sandstone_block", ["x"] = 0, ["y"] = 4}, {["z"] = 14, ["param1"] = 30, ["meta"] = {["inventory"] = {}, ["fields"] = {}}, ["name"] = "default:silver_sandstone_block", ["x"] = 0, ["y"] = 4}, {["z"] = 3, ["param1"] = 90, ["meta"] = {["inventory"] = {}, ["fields"] = {}}, ["name"] = "default:goldblock", ["x"] = 0, ["y"] = 5}, {["z"] = 4, ["param1"] = 90, ["meta"] = {["inventory"] = {}, ["fields"] = {}}, ["name"] = "default:goldblock", ["x"] = 0, ["y"] = 5}, {["z"] = 5, ["param1"] = 30, ["meta"] = {["inventory"] = {}, ["fields"] = {}}, ["name"] = "default:silver_sandstone_block", ["x"] = 0, ["y"] = 5}, {["z"] = 10, ["param1"] = 30, ["meta"] = {["inventory"] = {}, ["fields"] = {}}, ["name"] = "default:silver_sandstone_block", ["x"] = 0, ["y"] = 5}, {["z"] = 15, ["param1"] = 30, ["meta"] = {["inventory"] = {}, ["fields"] = {}}, ["name"] = "default:silver_sandstone_block", ["x"] = 0, ["y"] = 5}, {["z"] = 5, ["param1"] = 30, ["meta"] = {["inventory"] = {}, ["fields"] = {}}, ["name"] = "default:silver_sandstone_block", ["x"] = 0, ["y"] = 6}, {["z"] = 10, ["param1"] = 30, ["meta"] = {["inventory"] = {}, ["fields"] = {}}, ["name"] = "default:silver_sandstone_block", ["x"] = 0, ["y"] = 6}, {["z"] = 15, ["param1"] = 30, ["meta"] = {["inventory"] = {}, ["fields"] = {}}, ["name"] = "default:silver_sandstone_block", ["x"] = 0, ["y"] = 6}, {["z"] = 5, ["param1"] = 30, ["meta"] = {["inventory"] = {}, ["fields"] = {}}, ["name"] = "default:silver_sandstone_block", ["x"] = 0, ["y"] = 7}, {["z"] = 10, ["param1"] = 30, ["meta"] = {["inventory"] = {}, ["fields"] = {}}, ["name"] = "default:silver_sandstone_block", ["x"] = 0, ["y"] = 7}, {["z"] = 15, ["param1"] = 30, ["meta"] = {["inventory"] = {}, ["fields"] = {}}, ["name"] = "default:silver_sandstone_block", ["x"] = 0, ["y"] = 7}, {["z"] = 5, ["param1"] = 30, ["meta"] = {["inventory"] = {}, ["fields"] = {}}, ["name"] = "default:silver_sandstone_block", ["x"] = 0, ["y"] = 8}, {["z"] = 10, ["param1"] = 30, ["meta"] = {["inventory"] = {}, ["fields"] = {}}, ["name"] = "default:silver_sandstone_block", ["x"] = 0, ["y"] = 8}, {["z"] = 15, ["param1"] = 30, ["meta"] = {["inventory"] = {}, ["fields"] = {}}, ["name"] = "default:silver_sandstone_block", ["x"] = 0, ["y"] = 8}, {["z"] = 5, ["param1"] = 30, ["meta"] = {["inventory"] = {}, ["fields"] = {}}, ["name"] = "default:silver_sandstone_block", ["x"] = 0, ["y"] = 9}, {["z"] = 10, ["param1"] = 30, ["meta"] = {["inventory"] = {}, ["fields"] = {}}, ["name"] = "default:silver_sandstone_block", ["x"] = 0, ["y"] = 9}, {["z"] = 15, ["param1"] = 30, ["meta"] = {["inventory"] = {}, ["fields"] = {}}, ["name"] = "default:silver_sandstone_block", ["x"] = 0, ["y"] = 9}, {["z"] = 5, ["param1"] = 30, ["meta"] = {["inventory"] = {}, ["fields"] = {}}, ["name"] = "default:silver_sandstone_block", ["x"] = 0, ["y"] = 10}, {["z"] = 10, ["param1"] = 30, ["meta"] = {["inventory"] = {}, ["fields"] = {}}, ["name"] = "default:silver_sandstone_block", ["x"] = 0, ["y"] = 10}, {["z"] = 15, ["param1"] = 30, ["meta"] = {["inventory"] = {}, ["fields"] = {}}, ["name"] = "default:silver_sandstone_block", ["x"] = 0, ["y"] = 10}, {["z"] = 5, ["param1"] = 30, ["meta"] = {["inventory"] = {}, ["fields"] = {}}, ["name"] = "default:silver_sandstone_block", ["x"] = 0, ["y"] = 11}, {["z"] = 10, ["param1"] = 30, ["meta"] = {["inventory"] = {}, ["fields"] = {}}, ["name"] = "default:silver_sandstone_block", ["x"] = 0, ["y"] = 11}, {["z"] = 15, ["param1"] = 30, ["meta"] = {["inventory"] = {}, ["fields"] = {}}, ["name"] = "default:silver_sandstone_block", ["x"] = 0, ["y"] = 11}, {["z"] = 5, ["param1"] = 30, ["meta"] = {["inventory"] = {}, ["fields"] = {}}, ["name"] = "default:silver_sandstone_block", ["x"] = 0, ["y"] = 12}, {["z"] = 10, ["param1"] = 30, ["meta"] = {["inventory"] = {}, ["fields"] = {}}, ["name"] = "default:silver_sandstone_block", ["x"] = 0, ["y"] = 12}, {["z"] = 15, ["param1"] = 30, ["meta"] = {["inventory"] = {}, ["fields"] = {}}, ["name"] = "default:silver_sandstone_block", ["x"] = 0, ["y"] = 12}, {["z"] = 5, ["param1"] = 30, ["meta"] = {["inventory"] = {}, ["fields"] = {}}, ["name"] = "default:silver_sandstone_block", ["x"] = 0, ["y"] = 13}, {["z"] = 10, ["param1"] = 30, ["meta"] = {["inventory"] = {}, ["fields"] = {}}, ["name"] = "default:silver_sandstone_block", ["x"] = 0, ["y"] = 13}, {["z"] = 15, ["param1"] = 30, ["meta"] = {["inventory"] = {}, ["fields"] = {}}, ["name"] = "default:silver_sandstone_block", ["x"] = 0, ["y"] = 13}, {["z"] = 5, ["param1"] = 30, ["meta"] = {["inventory"] = {}, ["fields"] = {}}, ["name"] = "default:silver_sandstone_block", ["x"] = 0, ["y"] = 14}, {["z"] = 10, ["param1"] = 30, ["meta"] = {["inventory"] = {}, ["fields"] = {}}, ["name"] = "default:silver_sandstone_block", ["x"] = 0, ["y"] = 14}, {["z"] = 15, ["param1"] = 30, ["meta"] = {["inventory"] = {}, ["fields"] = {}}, ["name"] = "default:silver_sandstone_block", ["x"] = 0, ["y"] = 14}, {["z"] = 5, ["param1"] = 30, ["meta"] = {["inventory"] = {}, ["fields"] = {}}, ["name"] = "default:silver_sandstone_block", ["x"] = 0, ["y"] = 15}, {["z"] = 10, ["param1"] = 30, ["meta"] = {["inventory"] = {}, ["fields"] = {}}, ["name"] = "default:silver_sandstone_block", ["x"] = 0, ["y"] = 15}, {["z"] = 15, ["param1"] = 30, ["meta"] = {["inventory"] = {}, ["fields"] = {}}, ["name"] = "default:silver_sandstone_block", ["x"] = 0, ["y"] = 15}, {["z"] = 5, ["param1"] = 30, ["meta"] = {["inventory"] = {}, ["fields"] = {}}, ["name"] = "default:silver_sandstone_block", ["x"] = 0, ["y"] = 16}, {["z"] = 10, ["param1"] = 30, ["meta"] = {["inventory"] = {}, ["fields"] = {}}, ["name"] = "default:silver_sandstone_block", ["x"] = 0, ["y"] = 16}, {["z"] = 15, ["param1"] = 30, ["meta"] = {["inventory"] = {}, ["fields"] = {}}, ["name"] = "default:silver_sandstone_block", ["x"] = 0, ["y"] = 16}, {["z"] = 5, ["param1"] = 30, ["meta"] = {["inventory"] = {}, ["fields"] = {}}, ["name"] = "default:silver_sandstone_block", ["x"] = 0, ["y"] = 17}, {["z"] = 10, ["param1"] = 30, ["meta"] = {["inventory"] = {}, ["fields"] = {}}, ["name"] = "default:silver_sandstone_block", ["x"] = 0, ["y"] = 17}, {["z"] = 15, ["param1"] = 30, ["meta"] = {["inventory"] = {}, ["fields"] = {}}, ["name"] = "default:silver_sandstone_block", ["x"] = 0, ["y"] = 17}, {["z"] = 5, ["param1"] = 30, ["meta"] = {["inventory"] = {}, ["fields"] = {}}, ["name"] = "default:silver_sandstone_block", ["x"] = 0, ["y"] = 18}, {["z"] = 10, ["param1"] = 30, ["meta"] = {["inventory"] = {}, ["fields"] = {}}, ["name"] = "default:silver_sandstone_block", ["x"] = 0, ["y"] = 18}, {["z"] = 15, ["param1"] = 30, ["meta"] = {["inventory"] = {}, ["fields"] = {}}, ["name"] = "default:silver_sandstone_block", ["x"] = 0, ["y"] = 18}, {["z"] = 5, ["param1"] = 30, ["meta"] = {["inventory"] = {}, ["fields"] = {}}, ["name"] = "default:silver_sandstone_block", ["x"] = 0, ["y"] = 19}, {["z"] = 10, ["param1"] = 30, ["meta"] = {["inventory"] = {}, ["fields"] = {}}, ["name"] = "default:silver_sandstone_block", ["x"] = 0, ["y"] = 19}, {["z"] = 15, ["param1"] = 30, ["meta"] = {["inventory"] = {}, ["fields"] = {}}, ["name"] = "default:silver_sandstone_block", ["x"] = 0, ["y"] = 19}, {["z"] = 5, ["param1"] = 30, ["meta"] = {["inventory"] = {}, ["fields"] = {}}, ["name"] = "default:silver_sandstone_block", ["x"] = 0, ["y"] = 20}, {["z"] = 10, ["param1"] = 30, ["meta"] = {["inventory"] = {}, ["fields"] = {}}, ["name"] = "default:silver_sandstone_block", ["x"] = 0, ["y"] = 20}, {["z"] = 15, ["param1"] = 30, ["meta"] = {["inventory"] = {}, ["fields"] = {}}, ["name"] = "default:silver_sandstone_block", ["x"] = 0, ["y"] = 20}, {["z"] = 5, ["param1"] = 30, ["meta"] = {["inventory"] = {}, ["fields"] = {}}, ["name"] = "default:silver_sandstone_block", ["x"] = 0, ["y"] = 21}, {["z"] = 10, ["param1"] = 30, ["meta"] = {["inventory"] = {}, ["fields"] = {}}, ["name"] = "default:silver_sandstone_block", ["x"] = 0, ["y"] = 21}, {["z"] = 15, ["param1"] = 30, ["meta"] = {["inventory"] = {}, ["fields"] = {}}, ["name"] = "default:silver_sandstone_block", ["x"] = 0, ["y"] = 21}, {["z"] = 5, ["param1"] = 30, ["meta"] = {["inventory"] = {}, ["fields"] = {}}, ["name"] = "default:silver_sandstone_block", ["x"] = 0, ["y"] = 22}, {["z"] = 10, ["param1"] = 30, ["meta"] = {["inventory"] = {}, ["fields"] = {}}, ["name"] = "default:silver_sandstone_block", ["x"] = 0, ["y"] = 22}, {["z"] = 15, ["param1"] = 30, ["meta"] = {["inventory"] = {}, ["fields"] = {}}, ["name"] = "default:silver_sandstone_block", ["x"] = 0, ["y"] = 22}, {["z"] = 5, ["param1"] = 30, ["meta"] = {["inventory"] = {}, ["fields"] = {}}, ["name"] = "default:silver_sandstone_block", ["x"] = 0, ["y"] = 23}, {["z"] = 10, ["param1"] = 30, ["meta"] = {["inventory"] = {}, ["fields"] = {}}, ["name"] = "default:silver_sandstone_block", ["x"] = 0, ["y"] = 23}, {["z"] = 15, ["param1"] = 30, ["meta"] = {["inventory"] = {}, ["fields"] = {}}, ["name"] = "default:silver_sandstone_block", ["x"] = 0, ["y"] = 23}, {["z"] = 3, ["param1"] = 30, ["meta"] = {["inventory"] = {}, ["fields"] = {}}, ["name"] = "default:silver_sandstone_block", ["x"] = 0, ["y"] = 24}, {["z"] = 4, ["param1"] = 30, ["meta"] = {["inventory"] = {}, ["fields"] = {}}, ["name"] = "default:silver_sandstone_block", ["x"] = 0, ["y"] = 24}, {["z"] = 5, ["param1"] = 30, ["meta"] = {["inventory"] = {}, ["fields"] = {}}, ["name"] = "default:silver_sandstone_block", ["x"] = 0, ["y"] = 24}, {["z"] = 10, ["param1"] = 30, ["meta"] = {["inventory"] = {}, ["fields"] = {}}, ["name"] = "default:silver_sandstone_block", ["x"] = 0, ["y"] = 24}, {["z"] = 14, ["param1"] = 30, ["meta"] = {["inventory"] = {}, ["fields"] = {}}, ["name"] = "default:silver_sandstone_block", ["x"] = 0, ["y"] = 24}, {["z"] = 4, ["param1"] = 30, ["meta"] = {["inventory"] = {}, ["fields"] = {}}, ["name"] = "default:silver_sandstone_block", ["x"] = 0, ["y"] = 25}, {["z"] = 5, ["param1"] = 30, ["meta"] = {["inventory"] = {}, ["fields"] = {}}, ["name"] = "default:silver_sandstone_block", ["x"] = 0, ["y"] = 25}, {["z"] = 6, ["param1"] = 30, ["meta"] = {["inventory"] = {}, ["fields"] = {}}, ["name"] = "default:silver_sandstone_block", ["x"] = 0, ["y"] = 25}, {["z"] = 10, ["param1"] = 30, ["meta"] = {["inventory"] = {}, ["fields"] = {}}, ["name"] = "default:silver_sandstone_block", ["x"] = 0, ["y"] = 25}, {["z"] = 13, ["param1"] = 30, ["meta"] = {["inventory"] = {}, ["fields"] = {}}, ["name"] = "default:silver_sandstone_block", ["x"] = 0, ["y"] = 25}, {["z"] = 5, ["param1"] = 30, ["meta"] = {["inventory"] = {}, ["fields"] = {}}, ["name"] = "default:silver_sandstone_block", ["x"] = 0, ["y"] = 26}, {["z"] = 6, ["param1"] = 30, ["meta"] = {["inventory"] = {}, ["fields"] = {}}, ["name"] = "default:silver_sandstone_block", ["x"] = 0, ["y"] = 26}, {["z"] = 7, ["param1"] = 30, ["meta"] = {["inventory"] = {}, ["fields"] = {}}, ["name"] = "default:silver_sandstone_block", ["x"] = 0, ["y"] = 26}, {["z"] = 8, ["param1"] = 30, ["meta"] = {["inventory"] = {}, ["fields"] = {}}, ["name"] = "default:silver_sandstone_block", ["x"] = 0, ["y"] = 26}, {["z"] = 9, ["param1"] = 30, ["meta"] = {["inventory"] = {}, ["fields"] = {}}, ["name"] = "default:silver_sandstone_block", ["x"] = 0, ["y"] = 26}, {["z"] = 10, ["param1"] = 30, ["meta"] = {["inventory"] = {}, ["fields"] = {}}, ["name"] = "default:silver_sandstone_block", ["x"] = 0, ["y"] = 26}, {["z"] = 11, ["param1"] = 30, ["meta"] = {["inventory"] = {}, ["fields"] = {}}, ["name"] = "default:silver_sandstone_block", ["x"] = 0, ["y"] = 26}, {["z"] = 12, ["param1"] = 30, ["meta"] = {["inventory"] = {}, ["fields"] = {}}, ["name"] = "default:silver_sandstone_block", ["x"] = 0, ["y"] = 26}, {["z"] = 6, ["param1"] = 30, ["meta"] = {["inventory"] = {}, ["fields"] = {}}, ["name"] = "default:silver_sandstone_block", ["x"] = 0, ["y"] = 27}, {["z"] = 7, ["param1"] = 30, ["meta"] = {["inventory"] = {}, ["fields"] = {}}, ["name"] = "default:silver_sandstone_block", ["x"] = 0, ["y"] = 27}, {["z"] = 8, ["param1"] = 30, ["meta"] = {["inventory"] = {}, ["fields"] = {}}, ["name"] = "default:silver_sandstone_block", ["x"] = 0, ["y"] = 27}, {["z"] = 9, ["param1"] = 30, ["meta"] = {["inventory"] = {}, ["fields"] = {}}, ["name"] = "default:silver_sandstone_block", ["x"] = 0, ["y"] = 27}, {["z"] = 10, ["param1"] = 30, ["meta"] = {["inventory"] = {}, ["fields"] = {}}, ["name"] = "default:silver_sandstone_block", ["x"] = 0, ["y"] = 27}, {["z"] = 11, ["param1"] = 30, ["meta"] = {["inventory"] = {}, ["fields"] = {}}, ["name"] = "default:silver_sandstone_block", ["x"] = 0, ["y"] = 27}, {["z"] = 3, ["param1"] = 30, ["meta"] = {["inventory"] = {}, ["fields"] = {}}, ["name"] = "default:silver_sandstone_block", ["x"] = 1, ["y"] = 0}, {["z"] = 4, ["param1"] = 30, ["meta"] = {["inventory"] = {}, ["fields"] = {}}, ["name"] = "default:silver_sandstone_block", ["x"] = 1, ["y"] = 0}, {["z"] = 5, ["param1"] = 30, ["meta"] = {["inventory"] = {}, ["fields"] = {}}, ["name"] = "default:silver_sandstone_block", ["x"] = 1, ["y"] = 0}, {["z"] = 6, ["param1"] = 30, ["meta"] = {["inventory"] = {}, ["fields"] = {}}, ["name"] = "default:silver_sandstone_block", ["x"] = 1, ["y"] = 0}, {["z"] = 7, ["param1"] = 30, ["meta"] = {["inventory"] = {}, ["fields"] = {}}, ["name"] = "default:silver_sandstone_block", ["x"] = 1, ["y"] = 0}, {["z"] = 8, ["param1"] = 30, ["meta"] = {["inventory"] = {}, ["fields"] = {}}, ["name"] = "default:silver_sandstone_block", ["x"] = 1, ["y"] = 0}, {["z"] = 9, ["param1"] = 30, ["meta"] = {["inventory"] = {}, ["fields"] = {}}, ["name"] = "default:silver_sandstone_block", ["x"] = 1, ["y"] = 0}, {["z"] = 10, ["param1"] = 30, ["meta"] = {["inventory"] = {}, ["fields"] = {}}, ["name"] = "default:silver_sandstone_block", ["x"] = 1, ["y"] = 0}, {["z"] = 11, ["param1"] = 30, ["meta"] = {["inventory"] = {}, ["fields"] = {}}, ["name"] = "default:silver_sandstone_block", ["x"] = 1, ["y"] = 0}, {["z"] = 12, ["param1"] = 30, ["meta"] = {["inventory"] = {}, ["fields"] = {}}, ["name"] = "default:silver_sandstone_block", ["x"] = 1, ["y"] = 0}, {["z"] = 13, ["param1"] = 30, ["meta"] = {["inventory"] = {}, ["fields"] = {}}, ["name"] = "default:silver_sandstone_block", ["x"] = 1, ["y"] = 1}, {["z"] = 13, ["param1"] = 30, ["meta"] = {["inventory"] = {}, ["fields"] = {}}, ["name"] = "default:silver_sandstone_block", ["x"] = 1, ["y"] = 2}, {["z"] = 3, ["param1"] = 90, ["meta"] = {["inventory"] = {}, ["fields"] = {}}, ["name"] = "default:goldblock", ["x"] = 1, ["y"] = 3}, {["z"] = 14, ["param1"] = 30, ["meta"] = {["inventory"] = {}, ["fields"] = {}}, ["name"] = "default:silver_sandstone_block", ["x"] = 1, ["y"] = 3}, {["z"] = 3, ["param1"] = 90, ["meta"] = {["inventory"] = {}, ["fields"] = {}}, ["name"] = "default:goldblock", ["x"] = 1, ["y"] = 4}, {["z"] = 14, ["param1"] = 30, ["meta"] = {["inventory"] = {}, ["fields"] = {}}, ["name"] = "default:silver_sandstone_block", ["x"] = 1, ["y"] = 4}, {["z"] = 3, ["param1"] = 90, ["meta"] = {["inventory"] = {}, ["fields"] = {}}, ["name"] = "default:goldblock", ["x"] = 1, ["y"] = 5}, {["z"] = 15, ["param1"] = 30, ["meta"] = {["inventory"] = {}, ["fields"] = {}}, ["name"] = "default:silver_sandstone_block", ["x"] = 1, ["y"] = 5}, {["z"] = 15, ["param1"] = 30, ["meta"] = {["inventory"] = {}, ["fields"] = {}}, ["name"] = "default:silver_sandstone_block", ["x"] = 1, ["y"] = 6}, {["z"] = 15, ["param1"] = 30, ["meta"] = {["inventory"] = {}, ["fields"] = {}}, ["name"] = "default:silver_sandstone_block", ["x"] = 1, ["y"] = 7}, {["z"] = 15, ["param1"] = 30, ["meta"] = {["inventory"] = {}, ["fields"] = {}}, ["name"] = "default:silver_sandstone_block", ["x"] = 1, ["y"] = 8}, {["z"] = 15, ["param1"] = 30, ["meta"] = {["inventory"] = {}, ["fields"] = {}}, ["name"] = "default:silver_sandstone_block", ["x"] = 1, ["y"] = 9}, {["z"] = 15, ["param1"] = 30, ["meta"] = {["inventory"] = {}, ["fields"] = {}}, ["name"] = "default:silver_sandstone_block", ["x"] = 1, ["y"] = 10}, {["z"] = 15, ["param1"] = 30, ["meta"] = {["inventory"] = {}, ["fields"] = {}}, ["name"] = "default:silver_sandstone_block", ["x"] = 1, ["y"] = 11}, {["z"] = 15, ["param1"] = 30, ["meta"] = {["inventory"] = {}, ["fields"] = {}}, ["name"] = "default:silver_sandstone_block", ["x"] = 1, ["y"] = 12}, {["z"] = 15, ["param1"] = 30, ["meta"] = {["inventory"] = {}, ["fields"] = {}}, ["name"] = "default:silver_sandstone_block", ["x"] = 1, ["y"] = 13}, {["z"] = 15, ["param1"] = 30, ["meta"] = {["inventory"] = {}, ["fields"] = {}}, ["name"] = "default:silver_sandstone_block", ["x"] = 1, ["y"] = 14}, {["z"] = 15, ["param1"] = 30, ["meta"] = {["inventory"] = {}, ["fields"] = {}}, ["name"] = "default:silver_sandstone_block", ["x"] = 1, ["y"] = 15}, {["z"] = 15, ["param1"] = 30, ["meta"] = {["inventory"] = {}, ["fields"] = {}}, ["name"] = "default:silver_sandstone_block", ["x"] = 1, ["y"] = 16}, {["z"] = 15, ["param1"] = 30, ["meta"] = {["inventory"] = {}, ["fields"] = {}}, ["name"] = "default:silver_sandstone_block", ["x"] = 1, ["y"] = 17}, {["z"] = 15, ["param1"] = 30, ["meta"] = {["inventory"] = {}, ["fields"] = {}}, ["name"] = "default:silver_sandstone_block", ["x"] = 1, ["y"] = 18}, {["z"] = 15, ["param1"] = 30, ["meta"] = {["inventory"] = {}, ["fields"] = {}}, ["name"] = "default:silver_sandstone_block", ["x"] = 1, ["y"] = 19}, {["z"] = 15, ["param1"] = 30, ["meta"] = {["inventory"] = {}, ["fields"] = {}}, ["name"] = "default:silver_sandstone_block", ["x"] = 1, ["y"] = 20}, {["z"] = 15, ["param1"] = 30, ["meta"] = {["inventory"] = {}, ["fields"] = {}}, ["name"] = "default:silver_sandstone_block", ["x"] = 1, ["y"] = 21}, {["z"] = 15, ["param1"] = 30, ["meta"] = {["inventory"] = {}, ["fields"] = {}}, ["name"] = "default:silver_sandstone_block", ["x"] = 1, ["y"] = 22}, {["z"] = 15, ["param1"] = 30, ["meta"] = {["inventory"] = {}, ["fields"] = {}}, ["name"] = "default:silver_sandstone_block", ["x"] = 1, ["y"] = 23}, {["z"] = 3, ["param1"] = 30, ["meta"] = {["inventory"] = {}, ["fields"] = {}}, ["name"] = "default:silver_sandstone_block", ["x"] = 1, ["y"] = 24}, {["z"] = 14, ["param1"] = 30, ["meta"] = {["inventory"] = {}, ["fields"] = {}}, ["name"] = "default:silver_sandstone_block", ["x"] = 1, ["y"] = 24}, {["z"] = 4, ["param1"] = 30, ["meta"] = {["inventory"] = {}, ["fields"] = {}}, ["name"] = "default:silver_sandstone_block", ["x"] = 1, ["y"] = 25}, {["z"] = 13, ["param1"] = 30, ["meta"] = {["inventory"] = {}, ["fields"] = {}}, ["name"] = "default:silver_sandstone_block", ["x"] = 1, ["y"] = 25}, {["z"] = 5, ["param1"] = 30, ["meta"] = {["inventory"] = {}, ["fields"] = {}}, ["name"] = "default:silver_sandstone_block", ["x"] = 1, ["y"] = 26}, {["z"] = 12, ["param1"] = 30, ["meta"] = {["inventory"] = {}, ["fields"] = {}}, ["name"] = "default:silver_sandstone_block", ["x"] = 1, ["y"] = 26}, {["z"] = 6, ["param1"] = 30, ["meta"] = {["inventory"] = {}, ["fields"] = {}}, ["name"] = "default:silver_sandstone_block", ["x"] = 1, ["y"] = 27}, {["z"] = 7, ["param1"] = 30, ["meta"] = {["inventory"] = {}, ["fields"] = {}}, ["name"] = "default:silver_sandstone_block", ["x"] = 1, ["y"] = 27}, {["z"] = 8, ["param1"] = 30, ["meta"] = {["inventory"] = {}, ["fields"] = {}}, ["name"] = "default:silver_sandstone_block", ["x"] = 1, ["y"] = 27}, {["z"] = 9, ["param1"] = 30, ["meta"] = {["inventory"] = {}, ["fields"] = {}}, ["name"] = "default:silver_sandstone_block", ["x"] = 1, ["y"] = 27}, {["z"] = 10, ["param1"] = 30, ["meta"] = {["inventory"] = {}, ["fields"] = {}}, ["name"] = "default:silver_sandstone_block", ["x"] = 1, ["y"] = 27}, {["z"] = 11, ["param1"] = 30, ["meta"] = {["inventory"] = {}, ["fields"] = {}}, ["name"] = "default:silver_sandstone_block", ["x"] = 1, ["y"] = 27}, {["z"] = 3, ["param1"] = 30, ["meta"] = {["inventory"] = {}, ["fields"] = {}}, ["name"] = "default:silver_sandstone_block", ["x"] = 2, ["y"] = 0}, {["z"] = 4, ["param1"] = 30, ["meta"] = {["inventory"] = {}, ["fields"] = {}}, ["name"] = "default:silver_sandstone_block", ["x"] = 2, ["y"] = 0}, {["z"] = 5, ["param1"] = 30, ["meta"] = {["inventory"] = {}, ["fields"] = {}}, ["name"] = "default:silver_sandstone_block", ["x"] = 2, ["y"] = 0}, {["z"] = 6, ["param1"] = 30, ["meta"] = {["inventory"] = {}, ["fields"] = {}}, ["name"] = "default:silver_sandstone_block", ["x"] = 2, ["y"] = 0}, {["z"] = 7, ["param1"] = 30, ["meta"] = {["inventory"] = {}, ["fields"] = {}}, ["name"] = "default:silver_sandstone_block", ["x"] = 2, ["y"] = 0}, {["z"] = 8, ["param1"] = 30, ["meta"] = {["inventory"] = {}, ["fields"] = {}}, ["name"] = "default:silver_sandstone_block", ["x"] = 2, ["y"] = 0}, {["z"] = 9, ["param1"] = 30, ["meta"] = {["inventory"] = {}, ["fields"] = {}}, ["name"] = "default:silver_sandstone_block", ["x"] = 2, ["y"] = 0}, {["z"] = 10, ["param1"] = 30, ["meta"] = {["inventory"] = {}, ["fields"] = {}}, ["name"] = "default:silver_sandstone_block", ["x"] = 2, ["y"] = 0}, {["z"] = 11, ["param1"] = 30, ["meta"] = {["inventory"] = {}, ["fields"] = {}}, ["name"] = "default:silver_sandstone_block", ["x"] = 2, ["y"] = 0}, {["z"] = 12, ["param1"] = 30, ["meta"] = {["inventory"] = {}, ["fields"] = {}}, ["name"] = "default:silver_sandstone_block", ["x"] = 2, ["y"] = 0}, {["z"] = 13, ["param1"] = 30, ["meta"] = {["inventory"] = {}, ["fields"] = {}}, ["name"] = "default:silver_sandstone_block", ["x"] = 2, ["y"] = 1}, {["z"] = 13, ["param1"] = 30, ["meta"] = {["inventory"] = {}, ["fields"] = {}}, ["name"] = "default:silver_sandstone_block", ["x"] = 2, ["y"] = 2}, {["z"] = 3, ["param1"] = 90, ["meta"] = {["inventory"] = {}, ["fields"] = {}}, ["name"] = "default:goldblock", ["x"] = 2, ["y"] = 3}, {["z"] = 14, ["param1"] = 30, ["meta"] = {["inventory"] = {}, ["fields"] = {}}, ["name"] = "default:silver_sandstone_block", ["x"] = 2, ["y"] = 3}, {["z"] = 3, ["param1"] = 90, ["meta"] = {["inventory"] = {}, ["fields"] = {}}, ["name"] = "default:goldblock", ["x"] = 2, ["y"] = 4}, {["z"] = 14, ["param1"] = 30, ["meta"] = {["inventory"] = {}, ["fields"] = {}}, ["name"] = "default:silver_sandstone_block", ["x"] = 2, ["y"] = 4}, {["z"] = 3, ["param1"] = 90, ["meta"] = {["inventory"] = {}, ["fields"] = {}}, ["name"] = "default:goldblock", ["x"] = 2, ["y"] = 5}, {["z"] = 15, ["param1"] = 30, ["meta"] = {["inventory"] = {}, ["fields"] = {}}, ["name"] = "default:silver_sandstone_block", ["x"] = 2, ["y"] = 5}, {["z"] = 15, ["param1"] = 30, ["meta"] = {["inventory"] = {}, ["fields"] = {}}, ["name"] = "default:silver_sandstone_block", ["x"] = 2, ["y"] = 6}, {["z"] = 15, ["param1"] = 30, ["meta"] = {["inventory"] = {}, ["fields"] = {}}, ["name"] = "default:silver_sandstone_block", ["x"] = 2, ["y"] = 7}, {["z"] = 15, ["param1"] = 30, ["meta"] = {["inventory"] = {}, ["fields"] = {}}, ["name"] = "default:silver_sandstone_block", ["x"] = 2, ["y"] = 8}, {["z"] = 15, ["param1"] = 30, ["meta"] = {["inventory"] = {}, ["fields"] = {}}, ["name"] = "default:silver_sandstone_block", ["x"] = 2, ["y"] = 9}, {["z"] = 15, ["param1"] = 30, ["meta"] = {["inventory"] = {}, ["fields"] = {}}, ["name"] = "default:silver_sandstone_block", ["x"] = 2, ["y"] = 10}, {["z"] = 15, ["param1"] = 30, ["meta"] = {["inventory"] = {}, ["fields"] = {}}, ["name"] = "default:silver_sandstone_block", ["x"] = 2, ["y"] = 11}, {["z"] = 15, ["param1"] = 30, ["meta"] = {["inventory"] = {}, ["fields"] = {}}, ["name"] = "default:silver_sandstone_block", ["x"] = 2, ["y"] = 12}, {["z"] = 15, ["param1"] = 30, ["meta"] = {["inventory"] = {}, ["fields"] = {}}, ["name"] = "default:silver_sandstone_block", ["x"] = 2, ["y"] = 13}, {["z"] = 15, ["param1"] = 30, ["meta"] = {["inventory"] = {}, ["fields"] = {}}, ["name"] = "default:silver_sandstone_block", ["x"] = 2, ["y"] = 14}, {["z"] = 15, ["param1"] = 30, ["meta"] = {["inventory"] = {}, ["fields"] = {}}, ["name"] = "default:silver_sandstone_block", ["x"] = 2, ["y"] = 15}, {["z"] = 15, ["param1"] = 30, ["meta"] = {["inventory"] = {}, ["fields"] = {}}, ["name"] = "default:silver_sandstone_block", ["x"] = 2, ["y"] = 16}, {["z"] = 15, ["param1"] = 30, ["meta"] = {["inventory"] = {}, ["fields"] = {}}, ["name"] = "default:silver_sandstone_block", ["x"] = 2, ["y"] = 17}, {["z"] = 15, ["param1"] = 30, ["meta"] = {["inventory"] = {}, ["fields"] = {}}, ["name"] = "default:silver_sandstone_block", ["x"] = 2, ["y"] = 18}, {["z"] = 15, ["param1"] = 30, ["meta"] = {["inventory"] = {}, ["fields"] = {}}, ["name"] = "default:silver_sandstone_block", ["x"] = 2, ["y"] = 19}, {["z"] = 15, ["param1"] = 30, ["meta"] = {["inventory"] = {}, ["fields"] = {}}, ["name"] = "default:silver_sandstone_block", ["x"] = 2, ["y"] = 20}, {["z"] = 15, ["param1"] = 30, ["meta"] = {["inventory"] = {}, ["fields"] = {}}, ["name"] = "default:silver_sandstone_block", ["x"] = 2, ["y"] = 21}, {["z"] = 15, ["param1"] = 30, ["meta"] = {["inventory"] = {}, ["fields"] = {}}, ["name"] = "default:silver_sandstone_block", ["x"] = 2, ["y"] = 22}, {["z"] = 15, ["param1"] = 30, ["meta"] = {["inventory"] = {}, ["fields"] = {}}, ["name"] = "default:silver_sandstone_block", ["x"] = 2, ["y"] = 23}, {["z"] = 3, ["param1"] = 30, ["meta"] = {["inventory"] = {}, ["fields"] = {}}, ["name"] = "default:silver_sandstone_block", ["x"] = 2, ["y"] = 24}, {["z"] = 14, ["param1"] = 30, ["meta"] = {["inventory"] = {}, ["fields"] = {}}, ["name"] = "default:silver_sandstone_block", ["x"] = 2, ["y"] = 24}, {["z"] = 4, ["param1"] = 30, ["meta"] = {["inventory"] = {}, ["fields"] = {}}, ["name"] = "default:silver_sandstone_block", ["x"] = 2, ["y"] = 25}, {["z"] = 13, ["param1"] = 30, ["meta"] = {["inventory"] = {}, ["fields"] = {}}, ["name"] = "default:silver_sandstone_block", ["x"] = 2, ["y"] = 25}, {["z"] = 5, ["param1"] = 30, ["meta"] = {["inventory"] = {}, ["fields"] = {}}, ["name"] = "default:silver_sandstone_block", ["x"] = 2, ["y"] = 26}, {["z"] = 12, ["param1"] = 30, ["meta"] = {["inventory"] = {}, ["fields"] = {}}, ["name"] = "default:silver_sandstone_block", ["x"] = 2, ["y"] = 26}, {["z"] = 6, ["param1"] = 30, ["meta"] = {["inventory"] = {}, ["fields"] = {}}, ["name"] = "default:silver_sandstone_block", ["x"] = 2, ["y"] = 27}, {["z"] = 7, ["param1"] = 30, ["meta"] = {["inventory"] = {}, ["fields"] = {}}, ["name"] = "default:silver_sandstone_block", ["x"] = 2, ["y"] = 27}, {["z"] = 8, ["param1"] = 30, ["meta"] = {["inventory"] = {}, ["fields"] = {}}, ["name"] = "default:silver_sandstone_block", ["x"] = 2, ["y"] = 27}, {["z"] = 9, ["param1"] = 30, ["meta"] = {["inventory"] = {}, ["fields"] = {}}, ["name"] = "default:silver_sandstone_block", ["x"] = 2, ["y"] = 27}, {["z"] = 10, ["param1"] = 30, ["meta"] = {["inventory"] = {}, ["fields"] = {}}, ["name"] = "default:silver_sandstone_block", ["x"] = 2, ["y"] = 27}, {["z"] = 11, ["param1"] = 30, ["meta"] = {["inventory"] = {}, ["fields"] = {}}, ["name"] = "default:silver_sandstone_block", ["x"] = 2, ["y"] = 27}, {["z"] = 3, ["param1"] = 30, ["meta"] = {["inventory"] = {}, ["fields"] = {}}, ["name"] = "default:silver_sandstone_block", ["x"] = 3, ["y"] = 0}, {["z"] = 4, ["param1"] = 30, ["meta"] = {["inventory"] = {}, ["fields"] = {}}, ["name"] = "default:silver_sandstone_block", ["x"] = 3, ["y"] = 0}, {["z"] = 5, ["param1"] = 30, ["meta"] = {["inventory"] = {}, ["fields"] = {}}, ["name"] = "default:silver_sandstone_block", ["x"] = 3, ["y"] = 0}, {["z"] = 6, ["param1"] = 30, ["meta"] = {["inventory"] = {}, ["fields"] = {}}, ["name"] = "default:silver_sandstone_block", ["x"] = 3, ["y"] = 0}, {["z"] = 7, ["param1"] = 30, ["meta"] = {["inventory"] = {}, ["fields"] = {}}, ["name"] = "default:silver_sandstone_block", ["x"] = 3, ["y"] = 0}, {["z"] = 8, ["param1"] = 30, ["meta"] = {["inventory"] = {}, ["fields"] = {}}, ["name"] = "default:silver_sandstone_block", ["x"] = 3, ["y"] = 0}, {["z"] = 9, ["param1"] = 30, ["meta"] = {["inventory"] = {}, ["fields"] = {}}, ["name"] = "default:silver_sandstone_block", ["x"] = 3, ["y"] = 0}, {["z"] = 10, ["param1"] = 30, ["meta"] = {["inventory"] = {}, ["fields"] = {}}, ["name"] = "default:silver_sandstone_block", ["x"] = 3, ["y"] = 0}, {["z"] = 11, ["param1"] = 30, ["meta"] = {["inventory"] = {}, ["fields"] = {}}, ["name"] = "default:silver_sandstone_block", ["x"] = 3, ["y"] = 0}, {["z"] = 12, ["param1"] = 30, ["meta"] = {["inventory"] = {}, ["fields"] = {}}, ["name"] = "default:silver_sandstone_block", ["x"] = 3, ["y"] = 0}, {["z"] = 13, ["param1"] = 30, ["meta"] = {["inventory"] = {}, ["fields"] = {}}, ["name"] = "default:silver_sandstone_block", ["x"] = 3, ["y"] = 1}, {["z"] = 13, ["param1"] = 30, ["meta"] = {["inventory"] = {}, ["fields"] = {}}, ["name"] = "default:silver_sandstone_block", ["x"] = 3, ["y"] = 2}, {["z"] = 3, ["param1"] = 90, ["meta"] = {["inventory"] = {}, ["fields"] = {}}, ["name"] = "default:goldblock", ["x"] = 3, ["y"] = 3}, {["z"] = 14, ["param1"] = 30, ["meta"] = {["inventory"] = {}, ["fields"] = {}}, ["name"] = "default:silver_sandstone_block", ["x"] = 3, ["y"] = 3}, {["z"] = 3, ["param1"] = 90, ["meta"] = {["inventory"] = {}, ["fields"] = {}}, ["name"] = "default:goldblock", ["x"] = 3, ["y"] = 4}, {["z"] = 14, ["param1"] = 30, ["meta"] = {["inventory"] = {}, ["fields"] = {}}, ["name"] = "default:silver_sandstone_block", ["x"] = 3, ["y"] = 4}, {["z"] = 3, ["param1"] = 90, ["meta"] = {["inventory"] = {}, ["fields"] = {}}, ["name"] = "default:goldblock", ["x"] = 3, ["y"] = 5}, {["z"] = 15, ["param1"] = 30, ["meta"] = {["inventory"] = {}, ["fields"] = {}}, ["name"] = "default:silver_sandstone_block", ["x"] = 3, ["y"] = 5}, {["z"] = 15, ["param1"] = 30, ["meta"] = {["inventory"] = {}, ["fields"] = {}}, ["name"] = "default:silver_sandstone_block", ["x"] = 3, ["y"] = 6}, {["z"] = 15, ["param1"] = 30, ["meta"] = {["inventory"] = {}, ["fields"] = {}}, ["name"] = "default:silver_sandstone_block", ["x"] = 3, ["y"] = 7}, {["z"] = 15, ["param1"] = 30, ["meta"] = {["inventory"] = {}, ["fields"] = {}}, ["name"] = "default:silver_sandstone_block", ["x"] = 3, ["y"] = 8}, {["z"] = 15, ["param1"] = 30, ["meta"] = {["inventory"] = {}, ["fields"] = {}}, ["name"] = "default:silver_sandstone_block", ["x"] = 3, ["y"] = 9}, {["z"] = 15, ["param1"] = 30, ["meta"] = {["inventory"] = {}, ["fields"] = {}}, ["name"] = "default:silver_sandstone_block", ["x"] = 3, ["y"] = 10}, {["z"] = 15, ["param1"] = 30, ["meta"] = {["inventory"] = {}, ["fields"] = {}}, ["name"] = "default:silver_sandstone_block", ["x"] = 3, ["y"] = 11}, {["z"] = 15, ["param1"] = 30, ["meta"] = {["inventory"] = {}, ["fields"] = {}}, ["name"] = "default:silver_sandstone_block", ["x"] = 3, ["y"] = 12}, {["z"] = 15, ["param1"] = 30, ["meta"] = {["inventory"] = {}, ["fields"] = {}}, ["name"] = "default:silver_sandstone_block", ["x"] = 3, ["y"] = 13}, {["z"] = 15, ["param1"] = 30, ["meta"] = {["inventory"] = {}, ["fields"] = {}}, ["name"] = "default:silver_sandstone_block", ["x"] = 3, ["y"] = 14}, {["z"] = 15, ["param1"] = 30, ["meta"] = {["inventory"] = {}, ["fields"] = {}}, ["name"] = "default:silver_sandstone_block", ["x"] = 3, ["y"] = 15}, {["z"] = 15, ["param1"] = 30, ["meta"] = {["inventory"] = {}, ["fields"] = {}}, ["name"] = "default:silver_sandstone_block", ["x"] = 3, ["y"] = 16}, {["z"] = 15, ["param1"] = 30, ["meta"] = {["inventory"] = {}, ["fields"] = {}}, ["name"] = "default:silver_sandstone_block", ["x"] = 3, ["y"] = 17}, {["z"] = 15, ["param1"] = 30, ["meta"] = {["inventory"] = {}, ["fields"] = {}}, ["name"] = "default:silver_sandstone_block", ["x"] = 3, ["y"] = 18}, {["z"] = 15, ["param1"] = 30, ["meta"] = {["inventory"] = {}, ["fields"] = {}}, ["name"] = "default:silver_sandstone_block", ["x"] = 3, ["y"] = 19}, {["z"] = 15, ["param1"] = 30, ["meta"] = {["inventory"] = {}, ["fields"] = {}}, ["name"] = "default:silver_sandstone_block", ["x"] = 3, ["y"] = 20}, {["z"] = 15, ["param1"] = 30, ["meta"] = {["inventory"] = {}, ["fields"] = {}}, ["name"] = "default:silver_sandstone_block", ["x"] = 3, ["y"] = 21}, {["z"] = 15, ["param1"] = 30, ["meta"] = {["inventory"] = {}, ["fields"] = {}}, ["name"] = "default:silver_sandstone_block", ["x"] = 3, ["y"] = 22}, {["z"] = 15, ["param1"] = 30, ["meta"] = {["inventory"] = {}, ["fields"] = {}}, ["name"] = "default:silver_sandstone_block", ["x"] = 3, ["y"] = 23}, {["z"] = 3, ["param1"] = 30, ["meta"] = {["inventory"] = {}, ["fields"] = {}}, ["name"] = "default:silver_sandstone_block", ["x"] = 3, ["y"] = 24}, {["z"] = 14, ["param1"] = 30, ["meta"] = {["inventory"] = {}, ["fields"] = {}}, ["name"] = "default:silver_sandstone_block", ["x"] = 3, ["y"] = 24}, {["z"] = 4, ["param1"] = 30, ["meta"] = {["inventory"] = {}, ["fields"] = {}}, ["name"] = "default:silver_sandstone_block", ["x"] = 3, ["y"] = 25}, {["z"] = 13, ["param1"] = 30, ["meta"] = {["inventory"] = {}, ["fields"] = {}}, ["name"] = "default:silver_sandstone_block", ["x"] = 3, ["y"] = 25}, {["z"] = 5, ["param1"] = 30, ["meta"] = {["inventory"] = {}, ["fields"] = {}}, ["name"] = "default:silver_sandstone_block", ["x"] = 3, ["y"] = 26}, {["z"] = 12, ["param1"] = 30, ["meta"] = {["inventory"] = {}, ["fields"] = {}}, ["name"] = "default:silver_sandstone_block", ["x"] = 3, ["y"] = 26}, {["z"] = 6, ["param1"] = 30, ["meta"] = {["inventory"] = {}, ["fields"] = {}}, ["name"] = "default:silver_sandstone_block", ["x"] = 3, ["y"] = 27}, {["z"] = 7, ["param1"] = 30, ["meta"] = {["inventory"] = {}, ["fields"] = {}}, ["name"] = "default:silver_sandstone_block", ["x"] = 3, ["y"] = 27}, {["z"] = 8, ["param1"] = 30, ["meta"] = {["inventory"] = {}, ["fields"] = {}}, ["name"] = "default:silver_sandstone_block", ["x"] = 3, ["y"] = 27}, {["z"] = 9, ["param1"] = 30, ["meta"] = {["inventory"] = {}, ["fields"] = {}}, ["name"] = "default:silver_sandstone_block", ["x"] = 3, ["y"] = 27}, {["z"] = 10, ["param1"] = 30, ["meta"] = {["inventory"] = {}, ["fields"] = {}}, ["name"] = "default:silver_sandstone_block", ["x"] = 3, ["y"] = 27}, {["z"] = 11, ["param1"] = 30, ["meta"] = {["inventory"] = {}, ["fields"] = {}}, ["name"] = "default:silver_sandstone_block", ["x"] = 3, ["y"] = 27}, {["z"] = 8, ["meta"] = {["inventory"] = {}, ["fields"] = {}}, ["name"] = "default:silver_sandstone_block", ["x"] = 3, ["y"] = 39}, {["z"] = 9, ["meta"] = {["inventory"] = {}, ["fields"] = {}}, ["name"] = "default:silver_sandstone_block", ["x"] = 3, ["y"] = 39}, {["z"] = 8, ["meta"] = {["inventory"] = {}, ["fields"] = {}}, ["name"] = "default:silver_sandstone_block", ["x"] = 3, ["y"] = 40}, {["z"] = 9, ["meta"] = {["inventory"] = {}, ["fields"] = {}}, ["name"] = "default:silver_sandstone_block", ["x"] = 3, ["y"] = 40}, {["z"] = 8, ["meta"] = {["inventory"] = {}, ["fields"] = {}}, ["name"] = "default:silver_sandstone_block", ["x"] = 3, ["y"] = 41}, {["z"] = 9, ["meta"] = {["inventory"] = {}, ["fields"] = {}}, ["name"] = "default:silver_sandstone_block", ["x"] = 3, ["y"] = 41}, {["z"] = 8, ["meta"] = {["inventory"] = {}, ["fields"] = {}}, ["name"] = "default:silver_sandstone_block", ["x"] = 3, ["y"] = 42}, {["z"] = 9, ["meta"] = {["inventory"] = {}, ["fields"] = {}}, ["name"] = "default:silver_sandstone_block", ["x"] = 3, ["y"] = 42}, {["z"] = 3, ["param1"] = 30, ["meta"] = {["inventory"] = {}, ["fields"] = {}}, ["name"] = "default:silver_sandstone_block", ["x"] = 4, ["y"] = 0}, {["z"] = 4, ["param1"] = 30, ["meta"] = {["inventory"] = {}, ["fields"] = {}}, ["name"] = "default:silver_sandstone_block", ["x"] = 4, ["y"] = 0}, {["z"] = 5, ["param1"] = 30, ["meta"] = {["inventory"] = {}, ["fields"] = {}}, ["name"] = "default:silver_sandstone_block", ["x"] = 4, ["y"] = 0}, {["z"] = 6, ["param1"] = 30, ["meta"] = {["inventory"] = {}, ["fields"] = {}}, ["name"] = "default:silver_sandstone_block", ["x"] = 4, ["y"] = 0}, {["z"] = 7, ["param1"] = 30, ["meta"] = {["inventory"] = {}, ["fields"] = {}}, ["name"] = "default:silver_sandstone_block", ["x"] = 4, ["y"] = 0}, {["z"] = 8, ["param1"] = 30, ["meta"] = {["inventory"] = {}, ["fields"] = {}}, ["name"] = "default:silver_sandstone_block", ["x"] = 4, ["y"] = 0}, {["z"] = 9, ["param1"] = 30, ["meta"] = {["inventory"] = {}, ["fields"] = {}}, ["name"] = "default:silver_sandstone_block", ["x"] = 4, ["y"] = 0}, {["z"] = 10, ["param1"] = 30, ["meta"] = {["inventory"] = {}, ["fields"] = {}}, ["name"] = "default:silver_sandstone_block", ["x"] = 4, ["y"] = 0}, {["z"] = 11, ["param1"] = 30, ["meta"] = {["inventory"] = {}, ["fields"] = {}}, ["name"] = "default:silver_sandstone_block", ["x"] = 4, ["y"] = 0}, {["z"] = 12, ["param1"] = 30, ["meta"] = {["inventory"] = {}, ["fields"] = {}}, ["name"] = "default:silver_sandstone_block", ["x"] = 4, ["y"] = 0}, {["z"] = 13, ["param1"] = 30, ["meta"] = {["inventory"] = {}, ["fields"] = {}}, ["name"] = "default:silver_sandstone_block", ["x"] = 4, ["y"] = 1}, {["z"] = 13, ["param1"] = 30, ["meta"] = {["inventory"] = {}, ["fields"] = {}}, ["name"] = "default:silver_sandstone_block", ["x"] = 4, ["y"] = 2}, {["z"] = 3, ["param1"] = 90, ["meta"] = {["inventory"] = {}, ["fields"] = {}}, ["name"] = "default:goldblock", ["x"] = 4, ["y"] = 3}, {["z"] = 14, ["param1"] = 30, ["meta"] = {["inventory"] = {}, ["fields"] = {}}, ["name"] = "default:silver_sandstone_block", ["x"] = 4, ["y"] = 3}, {["z"] = 3, ["param1"] = 90, ["meta"] = {["inventory"] = {}, ["fields"] = {}}, ["name"] = "default:goldblock", ["x"] = 4, ["y"] = 4}, {["z"] = 14, ["param1"] = 30, ["meta"] = {["inventory"] = {}, ["fields"] = {}}, ["name"] = "default:silver_sandstone_block", ["x"] = 4, ["y"] = 4}, {["z"] = 3, ["param1"] = 90, ["meta"] = {["inventory"] = {}, ["fields"] = {}}, ["name"] = "default:goldblock", ["x"] = 4, ["y"] = 5}, {["z"] = 15, ["param1"] = 30, ["meta"] = {["inventory"] = {}, ["fields"] = {}}, ["name"] = "default:silver_sandstone_block", ["x"] = 4, ["y"] = 5}, {["z"] = 15, ["param1"] = 30, ["meta"] = {["inventory"] = {}, ["fields"] = {}}, ["name"] = "default:silver_sandstone_block", ["x"] = 4, ["y"] = 6}, {["z"] = 15, ["param1"] = 30, ["meta"] = {["inventory"] = {}, ["fields"] = {}}, ["name"] = "default:silver_sandstone_block", ["x"] = 4, ["y"] = 7}, {["z"] = 15, ["param1"] = 30, ["meta"] = {["inventory"] = {}, ["fields"] = {}}, ["name"] = "default:silver_sandstone_block", ["x"] = 4, ["y"] = 8}, {["z"] = 15, ["param1"] = 30, ["meta"] = {["inventory"] = {}, ["fields"] = {}}, ["name"] = "default:silver_sandstone_block", ["x"] = 4, ["y"] = 9}, {["z"] = 15, ["param1"] = 30, ["meta"] = {["inventory"] = {}, ["fields"] = {}}, ["name"] = "default:silver_sandstone_block", ["x"] = 4, ["y"] = 10}, {["z"] = 15, ["param1"] = 30, ["meta"] = {["inventory"] = {}, ["fields"] = {}}, ["name"] = "default:silver_sandstone_block", ["x"] = 4, ["y"] = 11}, {["z"] = 15, ["param1"] = 30, ["meta"] = {["inventory"] = {}, ["fields"] = {}}, ["name"] = "default:silver_sandstone_block", ["x"] = 4, ["y"] = 12}, {["z"] = 15, ["param1"] = 30, ["meta"] = {["inventory"] = {}, ["fields"] = {}}, ["name"] = "default:silver_sandstone_block", ["x"] = 4, ["y"] = 13}, {["z"] = 15, ["param1"] = 30, ["meta"] = {["inventory"] = {}, ["fields"] = {}}, ["name"] = "default:silver_sandstone_block", ["x"] = 4, ["y"] = 14}, {["z"] = 15, ["param1"] = 30, ["meta"] = {["inventory"] = {}, ["fields"] = {}}, ["name"] = "default:silver_sandstone_block", ["x"] = 4, ["y"] = 15}, {["z"] = 15, ["param1"] = 30, ["meta"] = {["inventory"] = {}, ["fields"] = {}}, ["name"] = "default:silver_sandstone_block", ["x"] = 4, ["y"] = 16}, {["z"] = 15, ["param1"] = 30, ["meta"] = {["inventory"] = {}, ["fields"] = {}}, ["name"] = "default:silver_sandstone_block", ["x"] = 4, ["y"] = 17}, {["z"] = 15, ["param1"] = 30, ["meta"] = {["inventory"] = {}, ["fields"] = {}}, ["name"] = "default:silver_sandstone_block", ["x"] = 4, ["y"] = 18}, {["z"] = 15, ["param1"] = 30, ["meta"] = {["inventory"] = {}, ["fields"] = {}}, ["name"] = "default:silver_sandstone_block", ["x"] = 4, ["y"] = 19}, {["z"] = 15, ["param1"] = 30, ["meta"] = {["inventory"] = {}, ["fields"] = {}}, ["name"] = "default:silver_sandstone_block", ["x"] = 4, ["y"] = 20}, {["z"] = 15, ["param1"] = 30, ["meta"] = {["inventory"] = {}, ["fields"] = {}}, ["name"] = "default:silver_sandstone_block", ["x"] = 4, ["y"] = 21}, {["z"] = 15, ["param1"] = 30, ["meta"] = {["inventory"] = {}, ["fields"] = {}}, ["name"] = "default:silver_sandstone_block", ["x"] = 4, ["y"] = 22}, {["z"] = 15, ["param1"] = 30, ["meta"] = {["inventory"] = {}, ["fields"] = {}}, ["name"] = "default:silver_sandstone_block", ["x"] = 4, ["y"] = 23}, {["z"] = 3, ["param1"] = 30, ["meta"] = {["inventory"] = {}, ["fields"] = {}}, ["name"] = "default:silver_sandstone_block", ["x"] = 4, ["y"] = 24}, {["z"] = 14, ["param1"] = 30, ["meta"] = {["inventory"] = {}, ["fields"] = {}}, ["name"] = "default:silver_sandstone_block", ["x"] = 4, ["y"] = 24}, {["z"] = 4, ["param1"] = 30, ["meta"] = {["inventory"] = {}, ["fields"] = {}}, ["name"] = "default:silver_sandstone_block", ["x"] = 4, ["y"] = 25}, {["z"] = 13, ["param1"] = 30, ["meta"] = {["inventory"] = {}, ["fields"] = {}}, ["name"] = "default:silver_sandstone_block", ["x"] = 4, ["y"] = 25}, {["z"] = 5, ["param1"] = 30, ["meta"] = {["inventory"] = {}, ["fields"] = {}}, ["name"] = "default:silver_sandstone_block", ["x"] = 4, ["y"] = 26}, {["z"] = 12, ["param1"] = 30, ["meta"] = {["inventory"] = {}, ["fields"] = {}}, ["name"] = "default:silver_sandstone_block", ["x"] = 4, ["y"] = 26}, {["z"] = 6, ["param1"] = 30, ["meta"] = {["inventory"] = {}, ["fields"] = {}}, ["name"] = "default:silver_sandstone_block", ["x"] = 4, ["y"] = 27}, {["z"] = 7, ["param1"] = 30, ["meta"] = {["inventory"] = {}, ["fields"] = {}}, ["name"] = "default:silver_sandstone_block", ["x"] = 4, ["y"] = 27}, {["z"] = 8, ["param1"] = 30, ["meta"] = {["inventory"] = {}, ["fields"] = {}}, ["name"] = "default:silver_sandstone_block", ["x"] = 4, ["y"] = 27}, {["z"] = 9, ["param1"] = 30, ["meta"] = {["inventory"] = {}, ["fields"] = {}}, ["name"] = "default:silver_sandstone_block", ["x"] = 4, ["y"] = 27}, {["z"] = 10, ["param1"] = 30, ["meta"] = {["inventory"] = {}, ["fields"] = {}}, ["name"] = "default:silver_sandstone_block", ["x"] = 4, ["y"] = 27}, {["z"] = 11, ["param1"] = 30, ["meta"] = {["inventory"] = {}, ["fields"] = {}}, ["name"] = "default:silver_sandstone_block", ["x"] = 4, ["y"] = 27}, {["z"] = 8, ["meta"] = {["inventory"] = {}, ["fields"] = {}}, ["name"] = "default:silver_sandstone_block", ["x"] = 4, ["y"] = 36}, {["z"] = 9, ["meta"] = {["inventory"] = {}, ["fields"] = {}}, ["name"] = "default:silver_sandstone_block", ["x"] = 4, ["y"] = 36}, {["z"] = 8, ["meta"] = {["inventory"] = {}, ["fields"] = {}}, ["name"] = "default:silver_sandstone_block", ["x"] = 4, ["y"] = 37}, {["z"] = 9, ["meta"] = {["inventory"] = {}, ["fields"] = {}}, ["name"] = "default:silver_sandstone_block", ["x"] = 4, ["y"] = 37}, {["z"] = 8, ["meta"] = {["inventory"] = {}, ["fields"] = {}}, ["name"] = "default:silver_sandstone_block", ["x"] = 4, ["y"] = 38}, {["z"] = 9, ["meta"] = {["inventory"] = {}, ["fields"] = {}}, ["name"] = "default:silver_sandstone_block", ["x"] = 4, ["y"] = 38}, {["z"] = 8, ["meta"] = {["inventory"] = {}, ["fields"] = {}}, ["name"] = "default:silver_sandstone_block", ["x"] = 4, ["y"] = 39}, {["z"] = 9, ["meta"] = {["inventory"] = {}, ["fields"] = {}}, ["name"] = "default:silver_sandstone_block", ["x"] = 4, ["y"] = 39}, {["z"] = 8, ["param1"] = 31, ["meta"] = {["inventory"] = {}, ["fields"] = {}}, ["name"] = "default:silver_sandstone_block", ["x"] = 4, ["y"] = 40}, {["z"] = 9, ["param1"] = 31, ["meta"] = {["inventory"] = {}, ["fields"] = {}}, ["name"] = "default:silver_sandstone_block", ["x"] = 4, ["y"] = 40}, {["z"] = 8, ["param1"] = 31, ["meta"] = {["inventory"] = {}, ["fields"] = {}}, ["name"] = "default:silver_sandstone_block", ["x"] = 4, ["y"] = 41}, {["z"] = 9, ["param1"] = 31, ["meta"] = {["inventory"] = {}, ["fields"] = {}}, ["name"] = "default:silver_sandstone_block", ["x"] = 4, ["y"] = 41}, {["z"] = 8, ["param1"] = 31, ["meta"] = {["inventory"] = {}, ["fields"] = {}}, ["name"] = "default:silver_sandstone_block", ["x"] = 4, ["y"] = 42}, {["z"] = 9, ["param1"] = 31, ["meta"] = {["inventory"] = {}, ["fields"] = {}}, ["name"] = "default:silver_sandstone_block", ["x"] = 4, ["y"] = 42}, {["z"] = 8, ["param1"] = 31, ["meta"] = {["inventory"] = {}, ["fields"] = {}}, ["name"] = "default:silver_sandstone_block", ["x"] = 4, ["y"] = 43}, {["z"] = 9, ["param1"] = 31, ["meta"] = {["inventory"] = {}, ["fields"] = {}}, ["name"] = "default:silver_sandstone_block", ["x"] = 4, ["y"] = 43}, {["z"] = 8, ["param1"] = 31, ["meta"] = {["inventory"] = {}, ["fields"] = {}}, ["name"] = "default:silver_sandstone_block", ["x"] = 4, ["y"] = 44}, {["z"] = 9, ["param1"] = 31, ["meta"] = {["inventory"] = {}, ["fields"] = {}}, ["name"] = "default:silver_sandstone_block", ["x"] = 4, ["y"] = 44}, {["z"] = 8, ["param1"] = 31, ["meta"] = {["inventory"] = {}, ["fields"] = {}}, ["name"] = "default:silver_sandstone_block", ["x"] = 4, ["y"] = 45}, {["z"] = 9, ["param1"] = 31, ["meta"] = {["inventory"] = {}, ["fields"] = {}}, ["name"] = "default:silver_sandstone_block", ["x"] = 4, ["y"] = 45}, {["z"] = 3, ["param1"] = 30, ["meta"] = {["inventory"] = {}, ["fields"] = {}}, ["name"] = "default:silver_sandstone_block", ["x"] = 5, ["y"] = 0}, {["z"] = 4, ["param1"] = 30, ["meta"] = {["inventory"] = {}, ["fields"] = {}}, ["name"] = "default:silver_sandstone_block", ["x"] = 5, ["y"] = 0}, {["z"] = 5, ["param1"] = 30, ["meta"] = {["inventory"] = {}, ["fields"] = {}}, ["name"] = "default:silver_sandstone_block", ["x"] = 5, ["y"] = 0}, {["z"] = 6, ["param1"] = 30, ["meta"] = {["inventory"] = {}, ["fields"] = {}}, ["name"] = "default:silver_sandstone_block", ["x"] = 5, ["y"] = 0}, {["z"] = 7, ["param1"] = 30, ["meta"] = {["inventory"] = {}, ["fields"] = {}}, ["name"] = "default:silver_sandstone_block", ["x"] = 5, ["y"] = 0}, {["z"] = 8, ["param1"] = 30, ["meta"] = {["inventory"] = {}, ["fields"] = {}}, ["name"] = "default:silver_sandstone_block", ["x"] = 5, ["y"] = 0}, {["z"] = 9, ["param1"] = 30, ["meta"] = {["inventory"] = {}, ["fields"] = {}}, ["name"] = "default:silver_sandstone_block", ["x"] = 5, ["y"] = 0}, {["z"] = 10, ["param1"] = 30, ["meta"] = {["inventory"] = {}, ["fields"] = {}}, ["name"] = "default:silver_sandstone_block", ["x"] = 5, ["y"] = 0}, {["z"] = 11, ["param1"] = 30, ["meta"] = {["inventory"] = {}, ["fields"] = {}}, ["name"] = "default:silver_sandstone_block", ["x"] = 5, ["y"] = 0}, {["z"] = 12, ["param1"] = 30, ["meta"] = {["inventory"] = {}, ["fields"] = {}}, ["name"] = "default:silver_sandstone_block", ["x"] = 5, ["y"] = 0}, {["z"] = 13, ["param1"] = 30, ["meta"] = {["inventory"] = {}, ["fields"] = {}}, ["name"] = "default:silver_sandstone_block", ["x"] = 5, ["y"] = 1}, {["z"] = 13, ["param1"] = 30, ["meta"] = {["inventory"] = {}, ["fields"] = {}}, ["name"] = "default:silver_sandstone_block", ["x"] = 5, ["y"] = 2}, {["z"] = 3, ["param1"] = 90, ["meta"] = {["inventory"] = {}, ["fields"] = {}}, ["name"] = "default:goldblock", ["x"] = 5, ["y"] = 3}, {["z"] = 14, ["param1"] = 30, ["meta"] = {["inventory"] = {}, ["fields"] = {}}, ["name"] = "default:silver_sandstone_block", ["x"] = 5, ["y"] = 3}, {["z"] = 3, ["param1"] = 90, ["meta"] = {["inventory"] = {}, ["fields"] = {}}, ["name"] = "default:goldblock", ["x"] = 5, ["y"] = 4}, {["z"] = 14, ["param1"] = 30, ["meta"] = {["inventory"] = {}, ["fields"] = {}}, ["name"] = "default:silver_sandstone_block", ["x"] = 5, ["y"] = 4}, {["z"] = 3, ["param1"] = 90, ["meta"] = {["inventory"] = {}, ["fields"] = {}}, ["name"] = "default:goldblock", ["x"] = 5, ["y"] = 5}, {["z"] = 15, ["param1"] = 30, ["meta"] = {["inventory"] = {}, ["fields"] = {}}, ["name"] = "default:silver_sandstone_block", ["x"] = 5, ["y"] = 5}, {["z"] = 15, ["param1"] = 30, ["meta"] = {["inventory"] = {}, ["fields"] = {}}, ["name"] = "default:silver_sandstone_block", ["x"] = 5, ["y"] = 6}, {["z"] = 15, ["param1"] = 30, ["meta"] = {["inventory"] = {}, ["fields"] = {}}, ["name"] = "default:silver_sandstone_block", ["x"] = 5, ["y"] = 7}, {["z"] = 15, ["param1"] = 30, ["meta"] = {["inventory"] = {}, ["fields"] = {}}, ["name"] = "default:silver_sandstone_block", ["x"] = 5, ["y"] = 8}, {["z"] = 15, ["param1"] = 30, ["meta"] = {["inventory"] = {}, ["fields"] = {}}, ["name"] = "default:silver_sandstone_block", ["x"] = 5, ["y"] = 9}, {["z"] = 15, ["param1"] = 30, ["meta"] = {["inventory"] = {}, ["fields"] = {}}, ["name"] = "default:silver_sandstone_block", ["x"] = 5, ["y"] = 10}, {["z"] = 15, ["param1"] = 30, ["meta"] = {["inventory"] = {}, ["fields"] = {}}, ["name"] = "default:silver_sandstone_block", ["x"] = 5, ["y"] = 11}, {["z"] = 15, ["param1"] = 30, ["meta"] = {["inventory"] = {}, ["fields"] = {}}, ["name"] = "default:silver_sandstone_block", ["x"] = 5, ["y"] = 12}, {["z"] = 15, ["param1"] = 30, ["meta"] = {["inventory"] = {}, ["fields"] = {}}, ["name"] = "default:silver_sandstone_block", ["x"] = 5, ["y"] = 13}, {["z"] = 15, ["param1"] = 30, ["meta"] = {["inventory"] = {}, ["fields"] = {}}, ["name"] = "default:silver_sandstone_block", ["x"] = 5, ["y"] = 14}, {["z"] = 15, ["param1"] = 30, ["meta"] = {["inventory"] = {}, ["fields"] = {}}, ["name"] = "default:silver_sandstone_block", ["x"] = 5, ["y"] = 15}, {["z"] = 15, ["param1"] = 30, ["meta"] = {["inventory"] = {}, ["fields"] = {}}, ["name"] = "default:silver_sandstone_block", ["x"] = 5, ["y"] = 16}, {["z"] = 15, ["param1"] = 30, ["meta"] = {["inventory"] = {}, ["fields"] = {}}, ["name"] = "default:silver_sandstone_block", ["x"] = 5, ["y"] = 17}, {["z"] = 15, ["param1"] = 30, ["meta"] = {["inventory"] = {}, ["fields"] = {}}, ["name"] = "default:silver_sandstone_block", ["x"] = 5, ["y"] = 18}, {["z"] = 15, ["param1"] = 30, ["meta"] = {["inventory"] = {}, ["fields"] = {}}, ["name"] = "default:silver_sandstone_block", ["x"] = 5, ["y"] = 19}, {["z"] = 15, ["param1"] = 30, ["meta"] = {["inventory"] = {}, ["fields"] = {}}, ["name"] = "default:silver_sandstone_block", ["x"] = 5, ["y"] = 20}, {["z"] = 15, ["param1"] = 30, ["meta"] = {["inventory"] = {}, ["fields"] = {}}, ["name"] = "default:silver_sandstone_block", ["x"] = 5, ["y"] = 21}, {["z"] = 15, ["param1"] = 30, ["meta"] = {["inventory"] = {}, ["fields"] = {}}, ["name"] = "default:silver_sandstone_block", ["x"] = 5, ["y"] = 22}, {["z"] = 15, ["param1"] = 30, ["meta"] = {["inventory"] = {}, ["fields"] = {}}, ["name"] = "default:silver_sandstone_block", ["x"] = 5, ["y"] = 23}, {["z"] = 3, ["param1"] = 30, ["meta"] = {["inventory"] = {}, ["fields"] = {}}, ["name"] = "default:silver_sandstone_block", ["x"] = 5, ["y"] = 24}, {["z"] = 14, ["param1"] = 30, ["meta"] = {["inventory"] = {}, ["fields"] = {}}, ["name"] = "default:silver_sandstone_block", ["x"] = 5, ["y"] = 24}, {["z"] = 4, ["param1"] = 30, ["meta"] = {["inventory"] = {}, ["fields"] = {}}, ["name"] = "default:silver_sandstone_block", ["x"] = 5, ["y"] = 25}, {["z"] = 13, ["param1"] = 30, ["meta"] = {["inventory"] = {}, ["fields"] = {}}, ["name"] = "default:silver_sandstone_block", ["x"] = 5, ["y"] = 25}, {["z"] = 5, ["param1"] = 30, ["meta"] = {["inventory"] = {}, ["fields"] = {}}, ["name"] = "default:silver_sandstone_block", ["x"] = 5, ["y"] = 26}, {["z"] = 12, ["param1"] = 30, ["meta"] = {["inventory"] = {}, ["fields"] = {}}, ["name"] = "default:silver_sandstone_block", ["x"] = 5, ["y"] = 26}, {["z"] = 6, ["param1"] = 30, ["meta"] = {["inventory"] = {}, ["fields"] = {}}, ["name"] = "default:silver_sandstone_block", ["x"] = 5, ["y"] = 27}, {["z"] = 7, ["param1"] = 30, ["meta"] = {["inventory"] = {}, ["fields"] = {}}, ["name"] = "default:silver_sandstone_block", ["x"] = 5, ["y"] = 27}, {["z"] = 8, ["param1"] = 30, ["meta"] = {["inventory"] = {}, ["fields"] = {}}, ["name"] = "default:silver_sandstone_block", ["x"] = 5, ["y"] = 27}, {["z"] = 9, ["param1"] = 30, ["meta"] = {["inventory"] = {}, ["fields"] = {}}, ["name"] = "default:silver_sandstone_block", ["x"] = 5, ["y"] = 27}, {["z"] = 10, ["param1"] = 30, ["meta"] = {["inventory"] = {}, ["fields"] = {}}, ["name"] = "default:silver_sandstone_block", ["x"] = 5, ["y"] = 27}, {["z"] = 11, ["param1"] = 30, ["meta"] = {["inventory"] = {}, ["fields"] = {}}, ["name"] = "default:silver_sandstone_block", ["x"] = 5, ["y"] = 27}, {["z"] = 8, ["meta"] = {["inventory"] = {}, ["fields"] = {}}, ["name"] = "default:silver_sandstone_block", ["x"] = 5, ["y"] = 34}, {["z"] = 9, ["meta"] = {["inventory"] = {}, ["fields"] = {}}, ["name"] = "default:silver_sandstone_block", ["x"] = 5, ["y"] = 34}, {["z"] = 8, ["meta"] = {["inventory"] = {}, ["fields"] = {}}, ["name"] = "default:silver_sandstone_block", ["x"] = 5, ["y"] = 35}, {["z"] = 9, ["meta"] = {["inventory"] = {}, ["fields"] = {}}, ["name"] = "default:silver_sandstone_block", ["x"] = 5, ["y"] = 35}, {["z"] = 8, ["meta"] = {["inventory"] = {}, ["fields"] = {}}, ["name"] = "default:silver_sandstone_block", ["x"] = 5, ["y"] = 36}, {["z"] = 9, ["meta"] = {["inventory"] = {}, ["fields"] = {}}, ["name"] = "default:silver_sandstone_block", ["x"] = 5, ["y"] = 36}, {["z"] = 8, ["meta"] = {["inventory"] = {}, ["fields"] = {}}, ["name"] = "default:silver_sandstone_block", ["x"] = 5, ["y"] = 37}, {["z"] = 9, ["meta"] = {["inventory"] = {}, ["fields"] = {}}, ["name"] = "default:silver_sandstone_block", ["x"] = 5, ["y"] = 37}, {["z"] = 8, ["meta"] = {["inventory"] = {}, ["fields"] = {}}, ["name"] = "default:silver_sandstone_block", ["x"] = 5, ["y"] = 38}, {["z"] = 9, ["meta"] = {["inventory"] = {}, ["fields"] = {}}, ["name"] = "default:silver_sandstone_block", ["x"] = 5, ["y"] = 38}, {["z"] = 4, ["param1"] = 88, ["meta"] = {["inventory"] = {}, ["fields"] = {}}, ["name"] = "wool:dark_grey", ["x"] = 5, ["y"] = 43}, {["z"] = 8, ["param1"] = 31, ["meta"] = {["inventory"] = {}, ["fields"] = {}}, ["name"] = "default:silver_sandstone_block", ["x"] = 5, ["y"] = 43}, {["z"] = 9, ["param1"] = 31, ["meta"] = {["inventory"] = {}, ["fields"] = {}}, ["name"] = "default:silver_sandstone_block", ["x"] = 5, ["y"] = 43}, {["z"] = 13, ["param1"] = 88, ["meta"] = {["inventory"] = {}, ["fields"] = {}}, ["name"] = "wool:dark_grey", ["x"] = 5, ["y"] = 43}, {["z"] = 3, ["param1"] = 88, ["meta"] = {["inventory"] = {}, ["fields"] = {}}, ["name"] = "wool:dark_grey", ["x"] = 5, ["y"] = 44}, {["z"] = 4, ["param1"] = 88, ["meta"] = {["inventory"] = {}, ["fields"] = {}}, ["name"] = "wool:dark_grey", ["x"] = 5, ["y"] = 44}, {["z"] = 5, ["param1"] = 88, ["meta"] = {["inventory"] = {}, ["fields"] = {}}, ["name"] = "wool:dark_grey", ["x"] = 5, ["y"] = 44}, {["z"] = 8, ["param1"] = 31, ["meta"] = {["inventory"] = {}, ["fields"] = {}}, ["name"] = "default:silver_sandstone_block", ["x"] = 5, ["y"] = 44}, {["z"] = 9, ["param1"] = 31, ["meta"] = {["inventory"] = {}, ["fields"] = {}}, ["name"] = "default:silver_sandstone_block", ["x"] = 5, ["y"] = 44}, {["z"] = 12, ["param1"] = 88, ["meta"] = {["inventory"] = {}, ["fields"] = {}}, ["name"] = "wool:dark_grey", ["x"] = 5, ["y"] = 44}, {["z"] = 13, ["param1"] = 88, ["meta"] = {["inventory"] = {}, ["fields"] = {}}, ["name"] = "wool:dark_grey", ["x"] = 5, ["y"] = 44}, {["z"] = 14, ["param1"] = 88, ["meta"] = {["inventory"] = {}, ["fields"] = {}}, ["name"] = "wool:dark_grey", ["x"] = 5, ["y"] = 44}, {["z"] = 2, ["param1"] = 88, ["meta"] = {["inventory"] = {}, ["fields"] = {}}, ["name"] = "wool:dark_grey", ["x"] = 5, ["y"] = 45}, {["z"] = 3, ["param1"] = 88, ["meta"] = {["inventory"] = {}, ["fields"] = {}}, ["name"] = "wool:dark_grey", ["x"] = 5, ["y"] = 45}, {["z"] = 4, ["param1"] = 91, ["meta"] = {["inventory"] = {}, ["fields"] = {}}, ["name"] = "default:goldblock", ["x"] = 5, ["y"] = 45}, {["z"] = 5, ["param1"] = 88, ["meta"] = {["inventory"] = {}, ["fields"] = {}}, ["name"] = "wool:dark_grey", ["x"] = 5, ["y"] = 45}, {["z"] = 6, ["param1"] = 88, ["meta"] = {["inventory"] = {}, ["fields"] = {}}, ["name"] = "wool:dark_grey", ["x"] = 5, ["y"] = 45}, {["z"] = 8, ["param1"] = 31, ["meta"] = {["inventory"] = {}, ["fields"] = {}}, ["name"] = "default:silver_sandstone_block", ["x"] = 5, ["y"] = 45}, {["z"] = 9, ["param1"] = 31, ["meta"] = {["inventory"] = {}, ["fields"] = {}}, ["name"] = "default:silver_sandstone_block", ["x"] = 5, ["y"] = 45}, {["z"] = 11, ["param1"] = 88, ["meta"] = {["inventory"] = {}, ["fields"] = {}}, ["name"] = "wool:dark_grey", ["x"] = 5, ["y"] = 45}, {["z"] = 12, ["param1"] = 88, ["meta"] = {["inventory"] = {}, ["fields"] = {}}, ["name"] = "wool:dark_grey", ["x"] = 5, ["y"] = 45}, {["z"] = 13, ["param1"] = 91, ["meta"] = {["inventory"] = {}, ["fields"] = {}}, ["name"] = "default:goldblock", ["x"] = 5, ["y"] = 45}, {["z"] = 14, ["param1"] = 88, ["meta"] = {["inventory"] = {}, ["fields"] = {}}, ["name"] = "wool:dark_grey", ["x"] = 5, ["y"] = 45}, {["z"] = 15, ["param1"] = 88, ["meta"] = {["inventory"] = {}, ["fields"] = {}}, ["name"] = "wool:dark_grey", ["x"] = 5, ["y"] = 45}, {["z"] = 4, ["param1"] = 88, ["meta"] = {["inventory"] = {}, ["fields"] = {}}, ["name"] = "wool:dark_grey", ["x"] = 5, ["y"] = 46}, {["z"] = 5, ["param1"] = 88, ["meta"] = {["inventory"] = {}, ["fields"] = {}}, ["name"] = "wool:dark_grey", ["x"] = 5, ["y"] = 46}, {["z"] = 6, ["param1"] = 88, ["meta"] = {["inventory"] = {}, ["fields"] = {}}, ["name"] = "wool:dark_grey", ["x"] = 5, ["y"] = 46}, {["z"] = 13, ["param1"] = 88, ["meta"] = {["inventory"] = {}, ["fields"] = {}}, ["name"] = "wool:dark_grey", ["x"] = 5, ["y"] = 46}, {["z"] = 14, ["param1"] = 88, ["meta"] = {["inventory"] = {}, ["fields"] = {}}, ["name"] = "wool:dark_grey", ["x"] = 5, ["y"] = 46}, {["z"] = 15, ["param1"] = 88, ["meta"] = {["inventory"] = {}, ["fields"] = {}}, ["name"] = "wool:dark_grey", ["x"] = 5, ["y"] = 46}, {["z"] = 5, ["param1"] = 88, ["meta"] = {["inventory"] = {}, ["fields"] = {}}, ["name"] = "wool:dark_grey", ["x"] = 5, ["y"] = 47}, {["z"] = 14, ["param1"] = 88, ["meta"] = {["inventory"] = {}, ["fields"] = {}}, ["name"] = "wool:dark_grey", ["x"] = 5, ["y"] = 47}, {["z"] = 3, ["param1"] = 30, ["meta"] = {["inventory"] = {}, ["fields"] = {}}, ["name"] = "default:silver_sandstone_block", ["x"] = 6, ["y"] = 0}, {["z"] = 4, ["param1"] = 30, ["meta"] = {["inventory"] = {}, ["fields"] = {}}, ["name"] = "default:silver_sandstone_block", ["x"] = 6, ["y"] = 0}, {["z"] = 5, ["param1"] = 30, ["meta"] = {["inventory"] = {}, ["fields"] = {}}, ["name"] = "default:silver_sandstone_block", ["x"] = 6, ["y"] = 0}, {["z"] = 6, ["param1"] = 30, ["meta"] = {["inventory"] = {}, ["fields"] = {}}, ["name"] = "default:silver_sandstone_block", ["x"] = 6, ["y"] = 0}, {["z"] = 7, ["param1"] = 30, ["meta"] = {["inventory"] = {}, ["fields"] = {}}, ["name"] = "default:silver_sandstone_block", ["x"] = 6, ["y"] = 0}, {["z"] = 8, ["param1"] = 30, ["meta"] = {["inventory"] = {}, ["fields"] = {}}, ["name"] = "default:silver_sandstone_block", ["x"] = 6, ["y"] = 0}, {["z"] = 9, ["param1"] = 30, ["meta"] = {["inventory"] = {}, ["fields"] = {}}, ["name"] = "default:silver_sandstone_block", ["x"] = 6, ["y"] = 0}, {["z"] = 10, ["param1"] = 30, ["meta"] = {["inventory"] = {}, ["fields"] = {}}, ["name"] = "default:silver_sandstone_block", ["x"] = 6, ["y"] = 0}, {["z"] = 11, ["param1"] = 30, ["meta"] = {["inventory"] = {}, ["fields"] = {}}, ["name"] = "default:silver_sandstone_block", ["x"] = 6, ["y"] = 0}, {["z"] = 12, ["param1"] = 30, ["meta"] = {["inventory"] = {}, ["fields"] = {}}, ["name"] = "default:silver_sandstone_block", ["x"] = 6, ["y"] = 0}, {["z"] = 13, ["param1"] = 30, ["meta"] = {["inventory"] = {}, ["fields"] = {}}, ["name"] = "default:silver_sandstone_block", ["x"] = 6, ["y"] = 1}, {["z"] = 13, ["param1"] = 30, ["meta"] = {["inventory"] = {}, ["fields"] = {}}, ["name"] = "default:silver_sandstone_block", ["x"] = 6, ["y"] = 2}, {["z"] = 3, ["param1"] = 90, ["meta"] = {["inventory"] = {}, ["fields"] = {}}, ["name"] = "default:goldblock", ["x"] = 6, ["y"] = 3}, {["z"] = 14, ["param1"] = 30, ["meta"] = {["inventory"] = {}, ["fields"] = {}}, ["name"] = "default:silver_sandstone_block", ["x"] = 6, ["y"] = 3}, {["z"] = 3, ["param1"] = 90, ["meta"] = {["inventory"] = {}, ["fields"] = {}}, ["name"] = "default:goldblock", ["x"] = 6, ["y"] = 4}, {["z"] = 14, ["param1"] = 30, ["meta"] = {["inventory"] = {}, ["fields"] = {}}, ["name"] = "default:silver_sandstone_block", ["x"] = 6, ["y"] = 4}, {["z"] = 3, ["param1"] = 90, ["meta"] = {["inventory"] = {}, ["fields"] = {}}, ["name"] = "default:goldblock", ["x"] = 6, ["y"] = 5}, {["z"] = 15, ["param1"] = 30, ["meta"] = {["inventory"] = {}, ["fields"] = {}}, ["name"] = "default:silver_sandstone_block", ["x"] = 6, ["y"] = 5}, {["z"] = 15, ["param1"] = 30, ["meta"] = {["inventory"] = {}, ["fields"] = {}}, ["name"] = "default:silver_sandstone_block", ["x"] = 6, ["y"] = 6}, {["z"] = 15, ["param1"] = 30, ["meta"] = {["inventory"] = {}, ["fields"] = {}}, ["name"] = "default:silver_sandstone_block", ["x"] = 6, ["y"] = 7}, {["z"] = 15, ["param1"] = 30, ["meta"] = {["inventory"] = {}, ["fields"] = {}}, ["name"] = "default:silver_sandstone_block", ["x"] = 6, ["y"] = 8}, {["z"] = 15, ["param1"] = 30, ["meta"] = {["inventory"] = {}, ["fields"] = {}}, ["name"] = "default:silver_sandstone_block", ["x"] = 6, ["y"] = 9}, {["z"] = 15, ["param1"] = 30, ["meta"] = {["inventory"] = {}, ["fields"] = {}}, ["name"] = "default:silver_sandstone_block", ["x"] = 6, ["y"] = 10}, {["z"] = 15, ["param1"] = 30, ["meta"] = {["inventory"] = {}, ["fields"] = {}}, ["name"] = "default:silver_sandstone_block", ["x"] = 6, ["y"] = 11}, {["z"] = 15, ["param1"] = 30, ["meta"] = {["inventory"] = {}, ["fields"] = {}}, ["name"] = "default:silver_sandstone_block", ["x"] = 6, ["y"] = 12}, {["z"] = 15, ["param1"] = 30, ["meta"] = {["inventory"] = {}, ["fields"] = {}}, ["name"] = "default:silver_sandstone_block", ["x"] = 6, ["y"] = 13}, {["z"] = 15, ["param1"] = 30, ["meta"] = {["inventory"] = {}, ["fields"] = {}}, ["name"] = "default:silver_sandstone_block", ["x"] = 6, ["y"] = 14}, {["z"] = 15, ["param1"] = 30, ["meta"] = {["inventory"] = {}, ["fields"] = {}}, ["name"] = "default:silver_sandstone_block", ["x"] = 6, ["y"] = 15}, {["z"] = 15, ["param1"] = 30, ["meta"] = {["inventory"] = {}, ["fields"] = {}}, ["name"] = "default:silver_sandstone_block", ["x"] = 6, ["y"] = 16}, {["z"] = 15, ["param1"] = 30, ["meta"] = {["inventory"] = {}, ["fields"] = {}}, ["name"] = "default:silver_sandstone_block", ["x"] = 6, ["y"] = 17}, {["z"] = 15, ["param1"] = 30, ["meta"] = {["inventory"] = {}, ["fields"] = {}}, ["name"] = "default:silver_sandstone_block", ["x"] = 6, ["y"] = 18}, {["z"] = 15, ["param1"] = 30, ["meta"] = {["inventory"] = {}, ["fields"] = {}}, ["name"] = "default:silver_sandstone_block", ["x"] = 6, ["y"] = 19}, {["z"] = 15, ["param1"] = 30, ["meta"] = {["inventory"] = {}, ["fields"] = {}}, ["name"] = "default:silver_sandstone_block", ["x"] = 6, ["y"] = 20}, {["z"] = 15, ["param1"] = 30, ["meta"] = {["inventory"] = {}, ["fields"] = {}}, ["name"] = "default:silver_sandstone_block", ["x"] = 6, ["y"] = 21}, {["z"] = 15, ["param1"] = 30, ["meta"] = {["inventory"] = {}, ["fields"] = {}}, ["name"] = "default:silver_sandstone_block", ["x"] = 6, ["y"] = 22}, {["z"] = 15, ["param1"] = 30, ["meta"] = {["inventory"] = {}, ["fields"] = {}}, ["name"] = "default:silver_sandstone_block", ["x"] = 6, ["y"] = 23}, {["z"] = 3, ["param1"] = 30, ["meta"] = {["inventory"] = {}, ["fields"] = {}}, ["name"] = "default:silver_sandstone_block", ["x"] = 6, ["y"] = 24}, {["z"] = 14, ["param1"] = 30, ["meta"] = {["inventory"] = {}, ["fields"] = {}}, ["name"] = "default:silver_sandstone_block", ["x"] = 6, ["y"] = 24}, {["z"] = 4, ["param1"] = 30, ["meta"] = {["inventory"] = {}, ["fields"] = {}}, ["name"] = "default:silver_sandstone_block", ["x"] = 6, ["y"] = 25}, {["z"] = 13, ["param1"] = 30, ["meta"] = {["inventory"] = {}, ["fields"] = {}}, ["name"] = "default:silver_sandstone_block", ["x"] = 6, ["y"] = 25}, {["z"] = 5, ["param1"] = 30, ["meta"] = {["inventory"] = {}, ["fields"] = {}}, ["name"] = "default:silver_sandstone_block", ["x"] = 6, ["y"] = 26}, {["z"] = 12, ["param1"] = 30, ["meta"] = {["inventory"] = {}, ["fields"] = {}}, ["name"] = "default:silver_sandstone_block", ["x"] = 6, ["y"] = 26}, {["z"] = 6, ["param1"] = 30, ["meta"] = {["inventory"] = {}, ["fields"] = {}}, ["name"] = "default:silver_sandstone_block", ["x"] = 6, ["y"] = 27}, {["z"] = 7, ["param1"] = 30, ["meta"] = {["inventory"] = {}, ["fields"] = {}}, ["name"] = "default:silver_sandstone_block", ["x"] = 6, ["y"] = 27}, {["z"] = 8, ["param1"] = 30, ["meta"] = {["inventory"] = {}, ["fields"] = {}}, ["name"] = "default:silver_sandstone_block", ["x"] = 6, ["y"] = 27}, {["z"] = 9, ["param1"] = 30, ["meta"] = {["inventory"] = {}, ["fields"] = {}}, ["name"] = "default:silver_sandstone_block", ["x"] = 6, ["y"] = 27}, {["z"] = 10, ["param1"] = 30, ["meta"] = {["inventory"] = {}, ["fields"] = {}}, ["name"] = "default:silver_sandstone_block", ["x"] = 6, ["y"] = 27}, {["z"] = 11, ["param1"] = 30, ["meta"] = {["inventory"] = {}, ["fields"] = {}}, ["name"] = "default:silver_sandstone_block", ["x"] = 6, ["y"] = 27}, {["z"] = 7, ["param1"] = 30, ["meta"] = {["inventory"] = {}, ["fields"] = {}}, ["name"] = "default:silver_sandstone_block", ["x"] = 6, ["y"] = 28}, {["z"] = 8, ["param1"] = 30, ["meta"] = {["inventory"] = {}, ["fields"] = {}}, ["name"] = "default:silver_sandstone_block", ["x"] = 6, ["y"] = 28}, {["z"] = 9, ["param1"] = 30, ["meta"] = {["inventory"] = {}, ["fields"] = {}}, ["name"] = "default:silver_sandstone_block", ["x"] = 6, ["y"] = 28}, {["z"] = 10, ["param1"] = 30, ["meta"] = {["inventory"] = {}, ["fields"] = {}}, ["name"] = "default:silver_sandstone_block", ["x"] = 6, ["y"] = 28}, {["z"] = 8, ["meta"] = {["inventory"] = {}, ["fields"] = {}}, ["name"] = "default:silver_sandstone_block", ["x"] = 6, ["y"] = 32}, {["z"] = 9, ["meta"] = {["inventory"] = {}, ["fields"] = {}}, ["name"] = "default:silver_sandstone_block", ["x"] = 6, ["y"] = 32}, {["z"] = 8, ["meta"] = {["inventory"] = {}, ["fields"] = {}}, ["name"] = "default:silver_sandstone_block", ["x"] = 6, ["y"] = 33}, {["z"] = 9, ["meta"] = {["inventory"] = {}, ["fields"] = {}}, ["name"] = "default:silver_sandstone_block", ["x"] = 6, ["y"] = 33}, {["z"] = 8, ["meta"] = {["inventory"] = {}, ["fields"] = {}}, ["name"] = "default:silver_sandstone_block", ["x"] = 6, ["y"] = 34}, {["z"] = 9, ["meta"] = {["inventory"] = {}, ["fields"] = {}}, ["name"] = "default:silver_sandstone_block", ["x"] = 6, ["y"] = 34}, {["z"] = 8, ["meta"] = {["inventory"] = {}, ["fields"] = {}}, ["name"] = "default:silver_sandstone_block", ["x"] = 6, ["y"] = 35}, {["z"] = 9, ["meta"] = {["inventory"] = {}, ["fields"] = {}}, ["name"] = "default:silver_sandstone_block", ["x"] = 6, ["y"] = 35}, {["z"] = 3, ["param1"] = 34, ["meta"] = {["inventory"] = {}, ["fields"] = {}}, ["name"] = "default:obsidian_block", ["x"] = 6, ["y"] = 44}, {["z"] = 4, ["param1"] = 34, ["meta"] = {["inventory"] = {}, ["fields"] = {}}, ["name"] = "default:obsidian_block", ["x"] = 6, ["y"] = 44}, {["z"] = 5, ["param1"] = 34, ["meta"] = {["inventory"] = {}, ["fields"] = {}}, ["name"] = "default:obsidian_block", ["x"] = 6, ["y"] = 44}, {["z"] = 6, ["param1"] = 34, ["meta"] = {["inventory"] = {}, ["fields"] = {}}, ["name"] = "default:obsidian_block", ["x"] = 6, ["y"] = 44}, {["z"] = 7, ["param1"] = 34, ["meta"] = {["inventory"] = {}, ["fields"] = {}}, ["name"] = "default:obsidian_block", ["x"] = 6, ["y"] = 44}, {["z"] = 8, ["param1"] = 34, ["meta"] = {["inventory"] = {}, ["fields"] = {}}, ["name"] = "default:obsidian_block", ["x"] = 6, ["y"] = 44}, {["z"] = 9, ["param1"] = 34, ["meta"] = {["inventory"] = {}, ["fields"] = {}}, ["name"] = "default:obsidian_block", ["x"] = 6, ["y"] = 44}, {["z"] = 10, ["param1"] = 34, ["meta"] = {["inventory"] = {}, ["fields"] = {}}, ["name"] = "default:obsidian_block", ["x"] = 6, ["y"] = 44}, {["z"] = 11, ["param1"] = 34, ["meta"] = {["inventory"] = {}, ["fields"] = {}}, ["name"] = "default:obsidian_block", ["x"] = 6, ["y"] = 44}, {["z"] = 12, ["param1"] = 34, ["meta"] = {["inventory"] = {}, ["fields"] = {}}, ["name"] = "default:obsidian_block", ["x"] = 6, ["y"] = 44}, {["z"] = 13, ["param1"] = 34, ["meta"] = {["inventory"] = {}, ["fields"] = {}}, ["name"] = "default:obsidian_block", ["x"] = 6, ["y"] = 44}, {["z"] = 14, ["param1"] = 34, ["meta"] = {["inventory"] = {}, ["fields"] = {}}, ["name"] = "default:obsidian_block", ["x"] = 6, ["y"] = 44}, {["z"] = 3, ["param1"] = 34, ["meta"] = {["inventory"] = {}, ["fields"] = {}}, ["name"] = "default:obsidian_block", ["x"] = 6, ["y"] = 45}, {["z"] = 4, ["param1"] = 34, ["meta"] = {["inventory"] = {}, ["fields"] = {}}, ["name"] = "default:obsidian_block", ["x"] = 6, ["y"] = 45}, {["z"] = 5, ["param1"] = 34, ["meta"] = {["inventory"] = {}, ["fields"] = {}}, ["name"] = "default:obsidian_block", ["x"] = 6, ["y"] = 45}, {["z"] = 6, ["param1"] = 34, ["meta"] = {["inventory"] = {}, ["fields"] = {}}, ["name"] = "default:obsidian_block", ["x"] = 6, ["y"] = 45}, {["z"] = 7, ["param1"] = 34, ["meta"] = {["inventory"] = {}, ["fields"] = {}}, ["name"] = "default:obsidian_block", ["x"] = 6, ["y"] = 45}, {["z"] = 8, ["param1"] = 34, ["meta"] = {["inventory"] = {}, ["fields"] = {}}, ["name"] = "default:obsidian_block", ["x"] = 6, ["y"] = 45}, {["z"] = 9, ["param1"] = 34, ["meta"] = {["inventory"] = {}, ["fields"] = {}}, ["name"] = "default:obsidian_block", ["x"] = 6, ["y"] = 45}, {["z"] = 10, ["param1"] = 34, ["meta"] = {["inventory"] = {}, ["fields"] = {}}, ["name"] = "default:obsidian_block", ["x"] = 6, ["y"] = 45}, {["z"] = 11, ["param1"] = 34, ["meta"] = {["inventory"] = {}, ["fields"] = {}}, ["name"] = "default:obsidian_block", ["x"] = 6, ["y"] = 45}, {["z"] = 12, ["param1"] = 34, ["meta"] = {["inventory"] = {}, ["fields"] = {}}, ["name"] = "default:obsidian_block", ["x"] = 6, ["y"] = 45}, {["z"] = 13, ["param1"] = 34, ["meta"] = {["inventory"] = {}, ["fields"] = {}}, ["name"] = "default:obsidian_block", ["x"] = 6, ["y"] = 45}, {["z"] = 14, ["param1"] = 34, ["meta"] = {["inventory"] = {}, ["fields"] = {}}, ["name"] = "default:obsidian_block", ["x"] = 6, ["y"] = 45}, {["z"] = 4, ["param1"] = 34, ["meta"] = {["inventory"] = {}, ["fields"] = {}}, ["name"] = "default:obsidian_block", ["x"] = 6, ["y"] = 46}, {["z"] = 5, ["param1"] = 34, ["meta"] = {["inventory"] = {}, ["fields"] = {}}, ["name"] = "default:obsidian_block", ["x"] = 6, ["y"] = 46}, {["z"] = 6, ["param1"] = 34, ["meta"] = {["inventory"] = {}, ["fields"] = {}}, ["name"] = "default:obsidian_block", ["x"] = 6, ["y"] = 46}, {["z"] = 7, ["param1"] = 34, ["meta"] = {["inventory"] = {}, ["fields"] = {}}, ["name"] = "default:obsidian_block", ["x"] = 6, ["y"] = 46}, {["z"] = 8, ["param1"] = 34, ["meta"] = {["inventory"] = {}, ["fields"] = {}}, ["name"] = "default:obsidian_block", ["x"] = 6, ["y"] = 46}, {["z"] = 9, ["param1"] = 34, ["meta"] = {["inventory"] = {}, ["fields"] = {}}, ["name"] = "default:obsidian_block", ["x"] = 6, ["y"] = 46}, {["z"] = 10, ["param1"] = 34, ["meta"] = {["inventory"] = {}, ["fields"] = {}}, ["name"] = "default:obsidian_block", ["x"] = 6, ["y"] = 46}, {["z"] = 11, ["param1"] = 34, ["meta"] = {["inventory"] = {}, ["fields"] = {}}, ["name"] = "default:obsidian_block", ["x"] = 6, ["y"] = 46}, {["z"] = 12, ["param1"] = 34, ["meta"] = {["inventory"] = {}, ["fields"] = {}}, ["name"] = "default:obsidian_block", ["x"] = 6, ["y"] = 46}, {["z"] = 13, ["param1"] = 34, ["meta"] = {["inventory"] = {}, ["fields"] = {}}, ["name"] = "default:obsidian_block", ["x"] = 6, ["y"] = 46}, {["z"] = 14, ["param1"] = 34, ["meta"] = {["inventory"] = {}, ["fields"] = {}}, ["name"] = "default:obsidian_block", ["x"] = 6, ["y"] = 46}, {["z"] = 15, ["param1"] = 34, ["meta"] = {["inventory"] = {}, ["fields"] = {}}, ["name"] = "default:obsidian_block", ["x"] = 6, ["y"] = 46}, {["z"] = 3, ["param1"] = 30, ["meta"] = {["inventory"] = {}, ["fields"] = {}}, ["name"] = "default:silver_sandstone_block", ["x"] = 7, ["y"] = 0}, {["z"] = 4, ["param1"] = 30, ["meta"] = {["inventory"] = {}, ["fields"] = {}}, ["name"] = "default:silver_sandstone_block", ["x"] = 7, ["y"] = 0}, {["z"] = 5, ["param1"] = 30, ["meta"] = {["inventory"] = {}, ["fields"] = {}}, ["name"] = "default:silver_sandstone_block", ["x"] = 7, ["y"] = 0}, {["z"] = 6, ["param1"] = 30, ["meta"] = {["inventory"] = {}, ["fields"] = {}}, ["name"] = "default:silver_sandstone_block", ["x"] = 7, ["y"] = 0}, {["z"] = 7, ["param1"] = 30, ["meta"] = {["inventory"] = {}, ["fields"] = {}}, ["name"] = "default:silver_sandstone_block", ["x"] = 7, ["y"] = 0}, {["z"] = 8, ["param1"] = 30, ["meta"] = {["inventory"] = {}, ["fields"] = {}}, ["name"] = "default:silver_sandstone_block", ["x"] = 7, ["y"] = 0}, {["z"] = 9, ["param1"] = 30, ["meta"] = {["inventory"] = {}, ["fields"] = {}}, ["name"] = "default:silver_sandstone_block", ["x"] = 7, ["y"] = 0}, {["z"] = 10, ["param1"] = 30, ["meta"] = {["inventory"] = {}, ["fields"] = {}}, ["name"] = "default:silver_sandstone_block", ["x"] = 7, ["y"] = 0}, {["z"] = 11, ["param1"] = 30, ["meta"] = {["inventory"] = {}, ["fields"] = {}}, ["name"] = "default:silver_sandstone_block", ["x"] = 7, ["y"] = 0}, {["z"] = 12, ["param1"] = 30, ["meta"] = {["inventory"] = {}, ["fields"] = {}}, ["name"] = "default:silver_sandstone_block", ["x"] = 7, ["y"] = 0}, {["z"] = 13, ["param1"] = 30, ["meta"] = {["inventory"] = {}, ["fields"] = {}}, ["name"] = "default:silver_sandstone_block", ["x"] = 7, ["y"] = 1}, {["z"] = 13, ["param1"] = 30, ["meta"] = {["inventory"] = {}, ["fields"] = {}}, ["name"] = "default:silver_sandstone_block", ["x"] = 7, ["y"] = 2}, {["z"] = 3, ["param1"] = 90, ["meta"] = {["inventory"] = {}, ["fields"] = {}}, ["name"] = "default:goldblock", ["x"] = 7, ["y"] = 3}, {["z"] = 14, ["param1"] = 30, ["meta"] = {["inventory"] = {}, ["fields"] = {}}, ["name"] = "default:silver_sandstone_block", ["x"] = 7, ["y"] = 3}, {["z"] = 3, ["param1"] = 90, ["meta"] = {["inventory"] = {}, ["fields"] = {}}, ["name"] = "default:goldblock", ["x"] = 7, ["y"] = 4}, {["z"] = 14, ["param1"] = 30, ["meta"] = {["inventory"] = {}, ["fields"] = {}}, ["name"] = "default:silver_sandstone_block", ["x"] = 7, ["y"] = 4}, {["z"] = 3, ["param1"] = 90, ["meta"] = {["inventory"] = {}, ["fields"] = {}}, ["name"] = "default:goldblock", ["x"] = 7, ["y"] = 5}, {["z"] = 15, ["param1"] = 30, ["meta"] = {["inventory"] = {}, ["fields"] = {}}, ["name"] = "default:silver_sandstone_block", ["x"] = 7, ["y"] = 5}, {["z"] = 15, ["param1"] = 30, ["meta"] = {["inventory"] = {}, ["fields"] = {}}, ["name"] = "default:silver_sandstone_block", ["x"] = 7, ["y"] = 6}, {["z"] = 15, ["param1"] = 30, ["meta"] = {["inventory"] = {}, ["fields"] = {}}, ["name"] = "default:silver_sandstone_block", ["x"] = 7, ["y"] = 7}, {["z"] = 15, ["param1"] = 30, ["meta"] = {["inventory"] = {}, ["fields"] = {}}, ["name"] = "default:silver_sandstone_block", ["x"] = 7, ["y"] = 8}, {["z"] = 15, ["param1"] = 30, ["meta"] = {["inventory"] = {}, ["fields"] = {}}, ["name"] = "default:silver_sandstone_block", ["x"] = 7, ["y"] = 9}, {["z"] = 15, ["param1"] = 30, ["meta"] = {["inventory"] = {}, ["fields"] = {}}, ["name"] = "default:silver_sandstone_block", ["x"] = 7, ["y"] = 10}, {["z"] = 15, ["param1"] = 30, ["meta"] = {["inventory"] = {}, ["fields"] = {}}, ["name"] = "default:silver_sandstone_block", ["x"] = 7, ["y"] = 11}, {["z"] = 15, ["param1"] = 30, ["meta"] = {["inventory"] = {}, ["fields"] = {}}, ["name"] = "default:silver_sandstone_block", ["x"] = 7, ["y"] = 12}, {["z"] = 15, ["param1"] = 30, ["meta"] = {["inventory"] = {}, ["fields"] = {}}, ["name"] = "default:silver_sandstone_block", ["x"] = 7, ["y"] = 13}, {["z"] = 15, ["param1"] = 30, ["meta"] = {["inventory"] = {}, ["fields"] = {}}, ["name"] = "default:silver_sandstone_block", ["x"] = 7, ["y"] = 14}, {["z"] = 15, ["param1"] = 30, ["meta"] = {["inventory"] = {}, ["fields"] = {}}, ["name"] = "default:silver_sandstone_block", ["x"] = 7, ["y"] = 15}, {["z"] = 15, ["param1"] = 30, ["meta"] = {["inventory"] = {}, ["fields"] = {}}, ["name"] = "default:silver_sandstone_block", ["x"] = 7, ["y"] = 16}, {["z"] = 15, ["param1"] = 30, ["meta"] = {["inventory"] = {}, ["fields"] = {}}, ["name"] = "default:silver_sandstone_block", ["x"] = 7, ["y"] = 17}, {["z"] = 15, ["param1"] = 30, ["meta"] = {["inventory"] = {}, ["fields"] = {}}, ["name"] = "default:silver_sandstone_block", ["x"] = 7, ["y"] = 18}, {["z"] = 15, ["param1"] = 30, ["meta"] = {["inventory"] = {}, ["fields"] = {}}, ["name"] = "default:silver_sandstone_block", ["x"] = 7, ["y"] = 19}, {["z"] = 15, ["param1"] = 30, ["meta"] = {["inventory"] = {}, ["fields"] = {}}, ["name"] = "default:silver_sandstone_block", ["x"] = 7, ["y"] = 20}, {["z"] = 15, ["param1"] = 30, ["meta"] = {["inventory"] = {}, ["fields"] = {}}, ["name"] = "default:silver_sandstone_block", ["x"] = 7, ["y"] = 21}, {["z"] = 15, ["param1"] = 30, ["meta"] = {["inventory"] = {}, ["fields"] = {}}, ["name"] = "default:silver_sandstone_block", ["x"] = 7, ["y"] = 22}, {["z"] = 15, ["param1"] = 30, ["meta"] = {["inventory"] = {}, ["fields"] = {}}, ["name"] = "default:silver_sandstone_block", ["x"] = 7, ["y"] = 23}, {["z"] = 3, ["param1"] = 30, ["meta"] = {["inventory"] = {}, ["fields"] = {}}, ["name"] = "default:silver_sandstone_block", ["x"] = 7, ["y"] = 24}, {["z"] = 14, ["param1"] = 30, ["meta"] = {["inventory"] = {}, ["fields"] = {}}, ["name"] = "default:silver_sandstone_block", ["x"] = 7, ["y"] = 24}, {["z"] = 4, ["param1"] = 30, ["meta"] = {["inventory"] = {}, ["fields"] = {}}, ["name"] = "default:silver_sandstone_block", ["x"] = 7, ["y"] = 25}, {["z"] = 13, ["param1"] = 30, ["meta"] = {["inventory"] = {}, ["fields"] = {}}, ["name"] = "default:silver_sandstone_block", ["x"] = 7, ["y"] = 25}, {["z"] = 5, ["param1"] = 30, ["meta"] = {["inventory"] = {}, ["fields"] = {}}, ["name"] = "default:silver_sandstone_block", ["x"] = 7, ["y"] = 26}, {["z"] = 12, ["param1"] = 30, ["meta"] = {["inventory"] = {}, ["fields"] = {}}, ["name"] = "default:silver_sandstone_block", ["x"] = 7, ["y"] = 26}, {["z"] = 6, ["param1"] = 30, ["meta"] = {["inventory"] = {}, ["fields"] = {}}, ["name"] = "default:silver_sandstone_block", ["x"] = 7, ["y"] = 27}, {["z"] = 7, ["param1"] = 30, ["meta"] = {["inventory"] = {}, ["fields"] = {}}, ["name"] = "default:silver_sandstone_block", ["x"] = 7, ["y"] = 27}, {["z"] = 8, ["param1"] = 30, ["meta"] = {["inventory"] = {}, ["fields"] = {}}, ["name"] = "default:silver_sandstone_block", ["x"] = 7, ["y"] = 27}, {["z"] = 9, ["param1"] = 30, ["meta"] = {["inventory"] = {}, ["fields"] = {}}, ["name"] = "default:silver_sandstone_block", ["x"] = 7, ["y"] = 27}, {["z"] = 10, ["param1"] = 30, ["meta"] = {["inventory"] = {}, ["fields"] = {}}, ["name"] = "default:silver_sandstone_block", ["x"] = 7, ["y"] = 27}, {["z"] = 11, ["param1"] = 30, ["meta"] = {["inventory"] = {}, ["fields"] = {}}, ["name"] = "default:silver_sandstone_block", ["x"] = 7, ["y"] = 27}, {["z"] = 7, ["param1"] = 30, ["meta"] = {["inventory"] = {}, ["fields"] = {}}, ["name"] = "default:silver_sandstone_block", ["x"] = 7, ["y"] = 28}, {["z"] = 8, ["param1"] = 30, ["meta"] = {["inventory"] = {}, ["fields"] = {}}, ["name"] = "default:silver_sandstone_block", ["x"] = 7, ["y"] = 28}, {["z"] = 9, ["param1"] = 30, ["meta"] = {["inventory"] = {}, ["fields"] = {}}, ["name"] = "default:silver_sandstone_block", ["x"] = 7, ["y"] = 28}, {["z"] = 10, ["param1"] = 30, ["meta"] = {["inventory"] = {}, ["fields"] = {}}, ["name"] = "default:silver_sandstone_block", ["x"] = 7, ["y"] = 28}, {["z"] = 8, ["param1"] = 30, ["meta"] = {["inventory"] = {}, ["fields"] = {}}, ["name"] = "default:silver_sandstone_block", ["x"] = 7, ["y"] = 29}, {["z"] = 9, ["param1"] = 30, ["meta"] = {["inventory"] = {}, ["fields"] = {}}, ["name"] = "default:silver_sandstone_block", ["x"] = 7, ["y"] = 29}, {["z"] = 8, ["param1"] = 30, ["meta"] = {["inventory"] = {}, ["fields"] = {}}, ["name"] = "default:silver_sandstone_block", ["x"] = 7, ["y"] = 30}, {["z"] = 9, ["param1"] = 30, ["meta"] = {["inventory"] = {}, ["fields"] = {}}, ["name"] = "default:silver_sandstone_block", ["x"] = 7, ["y"] = 30}, {["z"] = 8, ["param1"] = 30, ["meta"] = {["inventory"] = {}, ["fields"] = {}}, ["name"] = "default:silver_sandstone_block", ["x"] = 7, ["y"] = 31}, {["z"] = 9, ["param1"] = 30, ["meta"] = {["inventory"] = {}, ["fields"] = {}}, ["name"] = "default:silver_sandstone_block", ["x"] = 7, ["y"] = 31}, {["z"] = 8, ["meta"] = {["inventory"] = {}, ["fields"] = {}}, ["name"] = "default:silver_sandstone_block", ["x"] = 7, ["y"] = 32}, {["z"] = 9, ["meta"] = {["inventory"] = {}, ["fields"] = {}}, ["name"] = "default:silver_sandstone_block", ["x"] = 7, ["y"] = 32}, {["z"] = 8, ["meta"] = {["inventory"] = {}, ["fields"] = {}}, ["name"] = "default:silver_sandstone_block", ["x"] = 7, ["y"] = 33}, {["z"] = 9, ["meta"] = {["inventory"] = {}, ["fields"] = {}}, ["name"] = "default:silver_sandstone_block", ["x"] = 7, ["y"] = 33}, {["z"] = 4, ["param1"] = 34, ["meta"] = {["inventory"] = {}, ["fields"] = {}}, ["name"] = "default:obsidian_block", ["x"] = 7, ["y"] = 46}, {["z"] = 5, ["param1"] = 34, ["meta"] = {["inventory"] = {}, ["fields"] = {}}, ["name"] = "default:obsidian_block", ["x"] = 7, ["y"] = 46}, {["z"] = 6, ["param1"] = 34, ["meta"] = {["inventory"] = {}, ["fields"] = {}}, ["name"] = "default:obsidian_block", ["x"] = 7, ["y"] = 46}, {["z"] = 7, ["param1"] = 34, ["meta"] = {["inventory"] = {}, ["fields"] = {}}, ["name"] = "default:obsidian_block", ["x"] = 7, ["y"] = 46}, {["z"] = 8, ["param1"] = 34, ["meta"] = {["inventory"] = {}, ["fields"] = {}}, ["name"] = "default:obsidian_block", ["x"] = 7, ["y"] = 46}, {["z"] = 9, ["param1"] = 34, ["meta"] = {["inventory"] = {}, ["fields"] = {}}, ["name"] = "default:obsidian_block", ["x"] = 7, ["y"] = 46}, {["z"] = 10, ["param1"] = 34, ["meta"] = {["inventory"] = {}, ["fields"] = {}}, ["name"] = "default:obsidian_block", ["x"] = 7, ["y"] = 46}, {["z"] = 11, ["param1"] = 34, ["meta"] = {["inventory"] = {}, ["fields"] = {}}, ["name"] = "default:obsidian_block", ["x"] = 7, ["y"] = 46}, {["z"] = 12, ["param1"] = 34, ["meta"] = {["inventory"] = {}, ["fields"] = {}}, ["name"] = "default:obsidian_block", ["x"] = 7, ["y"] = 46}, {["z"] = 13, ["param1"] = 34, ["meta"] = {["inventory"] = {}, ["fields"] = {}}, ["name"] = "default:obsidian_block", ["x"] = 7, ["y"] = 46}, {["z"] = 14, ["param1"] = 34, ["meta"] = {["inventory"] = {}, ["fields"] = {}}, ["name"] = "default:obsidian_block", ["x"] = 7, ["y"] = 46}, {["z"] = 15, ["param1"] = 34, ["meta"] = {["inventory"] = {}, ["fields"] = {}}, ["name"] = "default:obsidian_block", ["x"] = 7, ["y"] = 46}, {["z"] = 3, ["param1"] = 30, ["meta"] = {["inventory"] = {}, ["fields"] = {}}, ["name"] = "default:silver_sandstone_block", ["x"] = 8, ["y"] = 0}, {["z"] = 4, ["param1"] = 30, ["meta"] = {["inventory"] = {}, ["fields"] = {}}, ["name"] = "default:silver_sandstone_block", ["x"] = 8, ["y"] = 0}, {["z"] = 5, ["param1"] = 30, ["meta"] = {["inventory"] = {}, ["fields"] = {}}, ["name"] = "default:silver_sandstone_block", ["x"] = 8, ["y"] = 0}, {["z"] = 6, ["param1"] = 30, ["meta"] = {["inventory"] = {}, ["fields"] = {}}, ["name"] = "default:silver_sandstone_block", ["x"] = 8, ["y"] = 0}, {["z"] = 7, ["param1"] = 30, ["meta"] = {["inventory"] = {}, ["fields"] = {}}, ["name"] = "default:silver_sandstone_block", ["x"] = 8, ["y"] = 0}, {["z"] = 8, ["param1"] = 30, ["meta"] = {["inventory"] = {}, ["fields"] = {}}, ["name"] = "default:silver_sandstone_block", ["x"] = 8, ["y"] = 0}, {["z"] = 9, ["param1"] = 30, ["meta"] = {["inventory"] = {}, ["fields"] = {}}, ["name"] = "default:silver_sandstone_block", ["x"] = 8, ["y"] = 0}, {["z"] = 10, ["param1"] = 30, ["meta"] = {["inventory"] = {}, ["fields"] = {}}, ["name"] = "default:silver_sandstone_block", ["x"] = 8, ["y"] = 0}, {["z"] = 11, ["param1"] = 30, ["meta"] = {["inventory"] = {}, ["fields"] = {}}, ["name"] = "default:silver_sandstone_block", ["x"] = 8, ["y"] = 0}, {["z"] = 12, ["param1"] = 30, ["meta"] = {["inventory"] = {}, ["fields"] = {}}, ["name"] = "default:silver_sandstone_block", ["x"] = 8, ["y"] = 0}, {["z"] = 13, ["param1"] = 30, ["meta"] = {["inventory"] = {}, ["fields"] = {}}, ["name"] = "default:silver_sandstone_block", ["x"] = 8, ["y"] = 1}, {["z"] = 13, ["param1"] = 30, ["meta"] = {["inventory"] = {}, ["fields"] = {}}, ["name"] = "default:silver_sandstone_block", ["x"] = 8, ["y"] = 2}, {["z"] = 3, ["param1"] = 90, ["meta"] = {["inventory"] = {}, ["fields"] = {}}, ["name"] = "default:goldblock", ["x"] = 8, ["y"] = 3}, {["z"] = 14, ["param1"] = 30, ["meta"] = {["inventory"] = {}, ["fields"] = {}}, ["name"] = "default:silver_sandstone_block", ["x"] = 8, ["y"] = 3}, {["z"] = 3, ["param1"] = 90, ["meta"] = {["inventory"] = {}, ["fields"] = {}}, ["name"] = "default:goldblock", ["x"] = 8, ["y"] = 4}, {["z"] = 14, ["param1"] = 30, ["meta"] = {["inventory"] = {}, ["fields"] = {}}, ["name"] = "default:silver_sandstone_block", ["x"] = 8, ["y"] = 4}, {["z"] = 3, ["param1"] = 90, ["meta"] = {["inventory"] = {}, ["fields"] = {}}, ["name"] = "default:goldblock", ["x"] = 8, ["y"] = 5}, {["z"] = 15, ["param1"] = 30, ["meta"] = {["inventory"] = {}, ["fields"] = {}}, ["name"] = "default:silver_sandstone_block", ["x"] = 8, ["y"] = 5}, {["z"] = 15, ["param1"] = 30, ["meta"] = {["inventory"] = {}, ["fields"] = {}}, ["name"] = "default:silver_sandstone_block", ["x"] = 8, ["y"] = 6}, {["z"] = 15, ["param1"] = 30, ["meta"] = {["inventory"] = {}, ["fields"] = {}}, ["name"] = "default:silver_sandstone_block", ["x"] = 8, ["y"] = 7}, {["z"] = 15, ["param1"] = 30, ["meta"] = {["inventory"] = {}, ["fields"] = {}}, ["name"] = "default:silver_sandstone_block", ["x"] = 8, ["y"] = 8}, {["z"] = 15, ["param1"] = 30, ["meta"] = {["inventory"] = {}, ["fields"] = {}}, ["name"] = "default:silver_sandstone_block", ["x"] = 8, ["y"] = 9}, {["z"] = 15, ["param1"] = 30, ["meta"] = {["inventory"] = {}, ["fields"] = {}}, ["name"] = "default:silver_sandstone_block", ["x"] = 8, ["y"] = 10}, {["z"] = 15, ["param1"] = 30, ["meta"] = {["inventory"] = {}, ["fields"] = {}}, ["name"] = "default:silver_sandstone_block", ["x"] = 8, ["y"] = 11}, {["z"] = 15, ["param1"] = 30, ["meta"] = {["inventory"] = {}, ["fields"] = {}}, ["name"] = "default:silver_sandstone_block", ["x"] = 8, ["y"] = 12}, {["z"] = 15, ["param1"] = 30, ["meta"] = {["inventory"] = {}, ["fields"] = {}}, ["name"] = "default:silver_sandstone_block", ["x"] = 8, ["y"] = 13}, {["z"] = 15, ["param1"] = 30, ["meta"] = {["inventory"] = {}, ["fields"] = {}}, ["name"] = "default:silver_sandstone_block", ["x"] = 8, ["y"] = 14}, {["z"] = 15, ["param1"] = 30, ["meta"] = {["inventory"] = {}, ["fields"] = {}}, ["name"] = "default:silver_sandstone_block", ["x"] = 8, ["y"] = 15}, {["z"] = 15, ["param1"] = 30, ["meta"] = {["inventory"] = {}, ["fields"] = {}}, ["name"] = "default:silver_sandstone_block", ["x"] = 8, ["y"] = 16}, {["z"] = 15, ["param1"] = 30, ["meta"] = {["inventory"] = {}, ["fields"] = {}}, ["name"] = "default:silver_sandstone_block", ["x"] = 8, ["y"] = 17}, {["z"] = 15, ["param1"] = 30, ["meta"] = {["inventory"] = {}, ["fields"] = {}}, ["name"] = "default:silver_sandstone_block", ["x"] = 8, ["y"] = 18}, {["z"] = 15, ["param1"] = 30, ["meta"] = {["inventory"] = {}, ["fields"] = {}}, ["name"] = "default:silver_sandstone_block", ["x"] = 8, ["y"] = 19}, {["z"] = 15, ["param1"] = 30, ["meta"] = {["inventory"] = {}, ["fields"] = {}}, ["name"] = "default:silver_sandstone_block", ["x"] = 8, ["y"] = 20}, {["z"] = 15, ["param1"] = 30, ["meta"] = {["inventory"] = {}, ["fields"] = {}}, ["name"] = "default:silver_sandstone_block", ["x"] = 8, ["y"] = 21}, {["z"] = 15, ["param1"] = 30, ["meta"] = {["inventory"] = {}, ["fields"] = {}}, ["name"] = "default:silver_sandstone_block", ["x"] = 8, ["y"] = 22}, {["z"] = 15, ["param1"] = 30, ["meta"] = {["inventory"] = {}, ["fields"] = {}}, ["name"] = "default:silver_sandstone_block", ["x"] = 8, ["y"] = 23}, {["z"] = 3, ["param1"] = 30, ["meta"] = {["inventory"] = {}, ["fields"] = {}}, ["name"] = "default:silver_sandstone_block", ["x"] = 8, ["y"] = 24}, {["z"] = 14, ["param1"] = 30, ["meta"] = {["inventory"] = {}, ["fields"] = {}}, ["name"] = "default:silver_sandstone_block", ["x"] = 8, ["y"] = 24}, {["z"] = 4, ["param1"] = 30, ["meta"] = {["inventory"] = {}, ["fields"] = {}}, ["name"] = "default:silver_sandstone_block", ["x"] = 8, ["y"] = 25}, {["z"] = 13, ["param1"] = 30, ["meta"] = {["inventory"] = {}, ["fields"] = {}}, ["name"] = "default:silver_sandstone_block", ["x"] = 8, ["y"] = 25}, {["z"] = 5, ["param1"] = 30, ["meta"] = {["inventory"] = {}, ["fields"] = {}}, ["name"] = "default:silver_sandstone_block", ["x"] = 8, ["y"] = 26}, {["z"] = 12, ["param1"] = 30, ["meta"] = {["inventory"] = {}, ["fields"] = {}}, ["name"] = "default:silver_sandstone_block", ["x"] = 8, ["y"] = 26}, {["z"] = 6, ["param1"] = 30, ["meta"] = {["inventory"] = {}, ["fields"] = {}}, ["name"] = "default:silver_sandstone_block", ["x"] = 8, ["y"] = 27}, {["z"] = 7, ["param1"] = 30, ["meta"] = {["inventory"] = {}, ["fields"] = {}}, ["name"] = "default:silver_sandstone_block", ["x"] = 8, ["y"] = 27}, {["z"] = 8, ["param1"] = 30, ["meta"] = {["inventory"] = {}, ["fields"] = {}}, ["name"] = "default:silver_sandstone_block", ["x"] = 8, ["y"] = 27}, {["z"] = 9, ["param1"] = 30, ["meta"] = {["inventory"] = {}, ["fields"] = {}}, ["name"] = "default:silver_sandstone_block", ["x"] = 8, ["y"] = 27}, {["z"] = 10, ["param1"] = 30, ["meta"] = {["inventory"] = {}, ["fields"] = {}}, ["name"] = "default:silver_sandstone_block", ["x"] = 8, ["y"] = 27}, {["z"] = 11, ["param1"] = 30, ["meta"] = {["inventory"] = {}, ["fields"] = {}}, ["name"] = "default:silver_sandstone_block", ["x"] = 8, ["y"] = 27}, {["z"] = 7, ["param1"] = 30, ["meta"] = {["inventory"] = {}, ["fields"] = {}}, ["name"] = "default:silver_sandstone_block", ["x"] = 8, ["y"] = 28}, {["z"] = 8, ["param1"] = 30, ["meta"] = {["inventory"] = {}, ["fields"] = {}}, ["name"] = "default:silver_sandstone_block", ["x"] = 8, ["y"] = 28}, {["z"] = 9, ["param1"] = 30, ["meta"] = {["inventory"] = {}, ["fields"] = {}}, ["name"] = "default:silver_sandstone_block", ["x"] = 8, ["y"] = 28}, {["z"] = 10, ["param1"] = 30, ["meta"] = {["inventory"] = {}, ["fields"] = {}}, ["name"] = "default:silver_sandstone_block", ["x"] = 8, ["y"] = 28}, {["z"] = 8, ["param1"] = 30, ["meta"] = {["inventory"] = {}, ["fields"] = {}}, ["name"] = "default:silver_sandstone_block", ["x"] = 8, ["y"] = 29}, {["z"] = 9, ["param1"] = 30, ["meta"] = {["inventory"] = {}, ["fields"] = {}}, ["name"] = "default:silver_sandstone_block", ["x"] = 8, ["y"] = 29}, {["z"] = 8, ["param1"] = 30, ["meta"] = {["inventory"] = {}, ["fields"] = {}}, ["name"] = "default:silver_sandstone_block", ["x"] = 8, ["y"] = 30}, {["z"] = 9, ["param1"] = 30, ["meta"] = {["inventory"] = {}, ["fields"] = {}}, ["name"] = "default:silver_sandstone_block", ["x"] = 8, ["y"] = 30}, {["z"] = 8, ["param1"] = 30, ["meta"] = {["inventory"] = {}, ["fields"] = {}}, ["name"] = "default:silver_sandstone_block", ["x"] = 8, ["y"] = 31}, {["z"] = 9, ["param1"] = 30, ["meta"] = {["inventory"] = {}, ["fields"] = {}}, ["name"] = "default:silver_sandstone_block", ["x"] = 8, ["y"] = 31}, {["z"] = 4, ["param1"] = 34, ["meta"] = {["inventory"] = {}, ["fields"] = {}}, ["name"] = "default:obsidian_block", ["x"] = 8, ["y"] = 46}, {["z"] = 5, ["param1"] = 34, ["meta"] = {["inventory"] = {}, ["fields"] = {}}, ["name"] = "default:obsidian_block", ["x"] = 8, ["y"] = 46}, {["z"] = 6, ["param1"] = 34, ["meta"] = {["inventory"] = {}, ["fields"] = {}}, ["name"] = "default:obsidian_block", ["x"] = 8, ["y"] = 46}, {["z"] = 7, ["param1"] = 34, ["meta"] = {["inventory"] = {}, ["fields"] = {}}, ["name"] = "default:obsidian_block", ["x"] = 8, ["y"] = 46}, {["z"] = 8, ["param1"] = 34, ["meta"] = {["inventory"] = {}, ["fields"] = {}}, ["name"] = "default:obsidian_block", ["x"] = 8, ["y"] = 46}, {["z"] = 9, ["param1"] = 34, ["meta"] = {["inventory"] = {}, ["fields"] = {}}, ["name"] = "default:obsidian_block", ["x"] = 8, ["y"] = 46}, {["z"] = 10, ["param1"] = 34, ["meta"] = {["inventory"] = {}, ["fields"] = {}}, ["name"] = "default:obsidian_block", ["x"] = 8, ["y"] = 46}, {["z"] = 11, ["param1"] = 34, ["meta"] = {["inventory"] = {}, ["fields"] = {}}, ["name"] = "default:obsidian_block", ["x"] = 8, ["y"] = 46}, {["z"] = 12, ["param1"] = 34, ["meta"] = {["inventory"] = {}, ["fields"] = {}}, ["name"] = "default:obsidian_block", ["x"] = 8, ["y"] = 46}, {["z"] = 13, ["param1"] = 34, ["meta"] = {["inventory"] = {}, ["fields"] = {}}, ["name"] = "default:obsidian_block", ["x"] = 8, ["y"] = 46}, {["z"] = 14, ["param1"] = 34, ["meta"] = {["inventory"] = {}, ["fields"] = {}}, ["name"] = "default:obsidian_block", ["x"] = 8, ["y"] = 46}, {["z"] = 15, ["param1"] = 34, ["meta"] = {["inventory"] = {}, ["fields"] = {}}, ["name"] = "default:obsidian_block", ["x"] = 8, ["y"] = 46}, {["z"] = 3, ["param1"] = 30, ["meta"] = {["inventory"] = {}, ["fields"] = {}}, ["name"] = "default:silver_sandstone_block", ["x"] = 9, ["y"] = 0}, {["z"] = 4, ["param1"] = 30, ["meta"] = {["inventory"] = {}, ["fields"] = {}}, ["name"] = "default:silver_sandstone_block", ["x"] = 9, ["y"] = 0}, {["z"] = 5, ["param1"] = 30, ["meta"] = {["inventory"] = {}, ["fields"] = {}}, ["name"] = "default:silver_sandstone_block", ["x"] = 9, ["y"] = 0}, {["z"] = 6, ["param1"] = 30, ["meta"] = {["inventory"] = {}, ["fields"] = {}}, ["name"] = "default:silver_sandstone_block", ["x"] = 9, ["y"] = 0}, {["z"] = 7, ["param1"] = 30, ["meta"] = {["inventory"] = {}, ["fields"] = {}}, ["name"] = "default:silver_sandstone_block", ["x"] = 9, ["y"] = 0}, {["z"] = 8, ["param1"] = 30, ["meta"] = {["inventory"] = {}, ["fields"] = {}}, ["name"] = "default:silver_sandstone_block", ["x"] = 9, ["y"] = 0}, {["z"] = 9, ["param1"] = 30, ["meta"] = {["inventory"] = {}, ["fields"] = {}}, ["name"] = "default:silver_sandstone_block", ["x"] = 9, ["y"] = 0}, {["z"] = 10, ["param1"] = 30, ["meta"] = {["inventory"] = {}, ["fields"] = {}}, ["name"] = "default:silver_sandstone_block", ["x"] = 9, ["y"] = 0}, {["z"] = 11, ["param1"] = 30, ["meta"] = {["inventory"] = {}, ["fields"] = {}}, ["name"] = "default:silver_sandstone_block", ["x"] = 9, ["y"] = 0}, {["z"] = 12, ["param1"] = 30, ["meta"] = {["inventory"] = {}, ["fields"] = {}}, ["name"] = "default:silver_sandstone_block", ["x"] = 9, ["y"] = 0}, {["z"] = 13, ["param1"] = 30, ["meta"] = {["inventory"] = {}, ["fields"] = {}}, ["name"] = "default:silver_sandstone_block", ["x"] = 9, ["y"] = 1}, {["z"] = 13, ["param1"] = 30, ["meta"] = {["inventory"] = {}, ["fields"] = {}}, ["name"] = "default:silver_sandstone_block", ["x"] = 9, ["y"] = 2}, {["z"] = 3, ["param1"] = 90, ["meta"] = {["inventory"] = {}, ["fields"] = {}},